Workbook
Name Appendix_1_Range: 'APPENDIX 1'!$B$3:$R$52
Name Appendix_10_Range: 'APPENDIX 10'!$B$3:$Q$36
Name Appendix_11_Range: 'APPENDIX 11'!$B$3:$Q$36
Name Appendix_12_Range: 'APPENDIX 12'!$B$3:$Q$36
Name Appendix_13_Range: 'APPENDIX 13'!$B$3:$Q$36
Name Appendix_14_Range: 'APPENDIX 14'!$B$3:$Q$36
Name Appendix_15_Range: 'APPENDIX 15'!$B$3:$Q$36
Name Appendix_16_Range: 'APPENDIX 16'!$B$3:$Q$36
Name Appendix_17_Range: 'APPENDIX 17'!$B$3:$Q$35
Name Appendix_18_Range: 'APPENDIX 18'!$B$3:$R$51
Name Appendix_19_Range: 'APPENDIX 19'!$B$3:$Q$51
Name Appendix_2_Range: 'APPENDIX 2'!$B$3:$R$37
Name Appendix_20_Range: 'APPENDIX 20'!$B$3:$Q$51
Name Appendix_21_Range: 'APPENDIX 21'!$B$3:$Q$51
Name Appendix_22_Range: 'APPENDIX 22'!$B$3:$Q$51
Name Appendix_23_Range: 'APPENDIX 23'!$B$3:$Q$51
Name Appendix_24_Range: 'APPENDIX 25'!$B$3:$L$35
Name Appendix_25_Range: 'APPENDIX 24'!$B$3:$Q$13
Name Appendix_3_Range: 'APPENDIX 3'!$B$3:$R$13
Name Appendix_4i_Range: 'APPENDIX 4 i'!$B$4:$K$44
Name Appendix_4ii_Range: 'APPENDIX 4 ii'!$B$3:$K$44
Name Appendix_4iii_Range: 'APPENDIX 4 iii'!$B$3:$L$44
Name Appendix_5i_Range: 'APPENDIX 5 i'!$B$4:$L$42
Name Appendix_5ii_Range: 'APPENDIX 5 ii'!$B$3:$L$42
Name Appendix_5iii_Range: 'APPENDIX 5 iii'!$B$3:$M$42
Name Appendix_5iv_Range: 'APPENDIX 5 iv'!$B$3:$N$42
Name Appendix_6i_Range: 'APPENDIX 6'!$B$4:$I$42
Name Appendix_7_Range: 'APPENDIX 7'!$B$3:$L$36
Name Appendix_8_Range: 'APPENDIX 8'!$B$3:$K$36
Name Appendix_9_Range: 'APPENDIX 9'!$B$3:$Q$36
Name Details_Range: Details!$C$2:$J$21
Name Reliances_and_Limitations: 'Reliance & Limitations'!$A$2:$G$8
Name Table_of_Contents: 'Table of Contents'!$A$1:$D$37

Sheet Details
E6: INSURANCE REGULATORY AUTHORITY
E11: TYPE OF INDUSTRY STATISTICS | F11: Quarterly (Unaudited)
E13: QUARTER | F13: 4
E15: YEAR | F15: 2025
E18: PERIOD ENDED | F18: 31.12.2025

Sheet Reliance & Limitations
B3: RELIANCE AND LIMITATIONS
B4: The insurance information contained in this workbook has been extracted from the quarterly unaudited returns submitted to the Authority in line with Section 54 of the Insurance Act. No adjustments have been made to the returns’ data except where necessary in consultation with the affected insurer(s) or reinsurer(s). The publication of any summary of the returns in this report does not necessarily mean that the returns so summarized have satisfied all the requirements of the Insurance Act, or that the Commissioner of Insurance approves the accuracy or the contents of the returns Where necessary, figures have been adjusted to eliminate errors in totals due to rounding off, and are given in thousands Kenya Shillings (‘000’ KES) except where otherwise stated. The report incorporates data from all insurers and reinsurers except for, KUSCCO Mutual Assurance Limited, The Monarch Insurance Company Limited-Life, Corporate Insurance Company- General, The Monarch Insurance Company Limited-General and Trident Insurance Company Limited due to non-compliance with the submission requirements

Sheet Table of Contents
B3: INSURANCE REGULATORY AUTHORITY
B5: =Details!F15&" QUARTER"&" "&Details!F13&" "&"STATISTICS" -> 2025 QUARTER 4 STATISTICS
B6: TABLE OF CONTENTS
B7: Link | C7: Description
B8: APPENDIX 1 | C8: =_xlfn.CONCAT("SUMMARY OF GENERAL INSURANCE BUSINESS PROFIT & LOSS ACCOUNTS FOR THE PERIOD ENDED"," ",Details!F18) -> SUMMARY OF GENERAL INSURANCE BUSINESS PROFIT & LOSS ACCOUNTS FOR THE PERIOD ENDED 31.12.2025
B9: APPENDIX 2 | C9: =_xlfn.CONCAT("SUMMARY OF LONG TERM INSURANCE BUSINESS PROFIT & LOSS ACCOUNTS FOR THE PERIOD ENDED"," ",Details!$F$18) -> SUMMARY OF LONG TERM INSURANCE BUSINESS PROFIT & LOSS ACCOUNTS FOR THE PERIOD ENDED 31.12.2025
B10: APPENDIX 3 | C10: =_xlfn.CONCAT("SUMMARY OF MICRO INSURANCE BUSINESS PROFIT & LOSS ACCOUNTS FOR THE PERIOD ENDED"," ",Details!$F$18) -> SUMMARY OF MICRO INSURANCE BUSINESS PROFIT & LOSS ACCOUNTS FOR THE PERIOD ENDED 31.12.2025
B11: APPENDIX 4 i | C11: =_xlfn.CONCAT("SUMMARY OF LONG TERM INSURANCE BUSINESS BALANCE SHEETS AS AT"," ",Details!F18) -> SUMMARY OF LONG TERM INSURANCE BUSINESS BALANCE SHEETS AS AT 31.12.2025
B12: APPENDIX 4 ii | C12: =_xlfn.CONCAT("SUMMARY OF LONG TERM INSURANCE BUSINESS BALANCE SHEETS AS AT"," ",Details!F18) -> SUMMARY OF LONG TERM INSURANCE BUSINESS BALANCE SHEETS AS AT 31.12.2025
B13: APPENDIX 4 iii | C13: =_xlfn.CONCAT("SUMMARY OF LONG TERM INSURANCE BUSINESS BALANCE SHEETS AS AT"," ",Details!F18) -> SUMMARY OF LONG TERM INSURANCE BUSINESS BALANCE SHEETS AS AT 31.12.2025
B14: APPENDIX 5 i | C14: =_xlfn.CONCAT("SUMMARY OF GENERAL INSURANCE BUSINESS BALANCE SHEETS AS AT"," ",Details!F18) -> SUMMARY OF GENERAL INSURANCE BUSINESS BALANCE SHEETS AS AT 31.12.2025
B15: APPENDIX 5 ii | C15: =_xlfn.CONCAT("SUMMARY OF GENERAL INSURANCE BUSINESS BALANCE SHEETS AS AT"," ",Details!F18) -> SUMMARY OF GENERAL INSURANCE BUSINESS BALANCE SHEETS AS AT 31.12.2025
B16: APPENDIX 5 iii | C16: =_xlfn.CONCAT("SUMMARY OF GENERAL INSURANCE BUSINESS BALANCE SHEETS AS AT"," ",Details!F18) -> SUMMARY OF GENERAL INSURANCE BUSINESS BALANCE SHEETS AS AT 31.12.2025
B17: APPENDIX 5 iv | C17: =_xlfn.CONCAT("SUMMARY OF GENERAL INSURANCE BUSINESS BALANCE SHEETS AS AT"," ",Details!F18) -> SUMMARY OF GENERAL INSURANCE BUSINESS BALANCE SHEETS AS AT 31.12.2025
B18: APPENDIX 6 | C18: =_xlfn.CONCAT("SUMMARY OF MICRO INSURANCE BUSINESS BALANCE SHEETS AS AT"," ",Details!F18) -> SUMMARY OF MICRO INSURANCE BUSINESS BALANCE SHEETS AS AT 31.12.2025
B19: APPENDIX 7 | C19: =_xlfn.CONCAT("SUMMARY OF LONG TERM INSURANCE BUSINESS GROSS PREMIUM INCOME FOR THE PERIOD ENDED"," ",Details!F18) -> SUMMARY OF LONG TERM INSURANCE BUSINESS GROSS PREMIUM INCOME FOR THE PERIOD ENDED 31.12.2025
B20: APPENDIX 8 | C20: =_xlfn.CONCAT("SUMMARY OF LONG TERM INSURANCE BUSINESS MARKET SHARE PER CLASS FOR THE PERIOD ENDED"," ",Details!F18) -> SUMMARY OF LONG TERM INSURANCE BUSINESS MARKET SHARE PER CLASS FOR THE PERIOD ENDED 31.12.2025
B21: APPENDIX 9 | C21: =_xlfn.CONCAT("SUMMARY OF LIFE ASSURANCE BUSINESS REVENUE ACCOUNTS FOR THE PERIOD ENDED"," ",Details!F18) -> SUMMARY OF LIFE ASSURANCE BUSINESS REVENUE ACCOUNTS FOR THE PERIOD ENDED 31.12.2025
B22: APPENDIX 10 | C22: =_xlfn.CONCAT("SUMMARY OF ANNUITIES BUSINESS REVENUE ACCOUNTS FOR THE PERIOD ENDED"," ",Details!F18) -> SUMMARY OF ANNUITIES BUSINESS REVENUE ACCOUNTS FOR THE PERIOD ENDED 31.12.2025
B23: APPENDIX 11 | C23: =_xlfn.CONCAT("SUMMARY OF GROUP LIFE BUSINESS REVENUE ACCOUNTS FOR THE PERIOD ENDED"," ",Details!F18) -> SUMMARY OF GROUP LIFE BUSINESS REVENUE ACCOUNTS FOR THE PERIOD ENDED 31.12.2025
B24: APPENDIX 12 | C24: =_xlfn.CONCAT("SUMMARY OF GROUP CREDIT BUSINESS REVENUE ACCOUNTS FOR THE PERIOD ENDED"," ",Details!F18) -> SUMMARY OF GROUP CREDIT BUSINESS REVENUE ACCOUNTS FOR THE PERIOD ENDED 31.12.2025
B25: APPENDIX 13 | C25: =_xlfn.CONCAT("SUMMARY OF INVESTMENTS BUSINESS REVENUE ACCOUNTS FOR THE PERIOD ENDED"," ",Details!F18) -> SUMMARY OF INVESTMENTS BUSINESS REVENUE ACCOUNTS FOR THE PERIOD ENDED 31.12.2025
B26: APPENDIX 14 | C26: =_xlfn.CONCAT("SUMMARY OF PERMANENT HEALTH BUSINESS REVENUE ACCOUNTS FOR THE PERIOD ENDED"," ",Details!F18) -> SUMMARY OF PERMANENT HEALTH BUSINESS REVENUE ACCOUNTS FOR THE PERIOD ENDED 31.12.2025
B27: APPENDIX 15 | C27: =_xlfn.CONCAT("SUMMARY OF PERSONAL PENSIONS BUSINESS REVENUE ACCOUNTS FOR THE PERIOD ENDED"," ",Details!F18) -> SUMMARY OF PERSONAL PENSIONS BUSINESS REVENUE ACCOUNTS FOR THE PERIOD ENDED 31.12.2025
B28: APPENDIX 16 | C28: =_xlfn.CONCAT("SUMMARY OF DEPOSIT ADMINISTRATION BUSINESS REVENUE ACCOUNTS FOR THE PERIOD ENDED"," ",Details!F18) -> SUMMARY OF DEPOSIT ADMINISTRATION BUSINESS REVENUE ACCOUNTS FOR THE PERIOD ENDED 31.12.2025
B29: APPENDIX 17 | C29: =_xlfn.CONCAT("SUMMARY OF COMBINED LONG TERM BUSINESS REVENUE ACCOUNTS FOR THE PERIOD ENDED"," ",Details!F18) -> SUMMARY OF COMBINED LONG TERM BUSINESS REVENUE ACCOUNTS FOR THE PERIOD ENDED 31.12.2025
B30: APPENDIX 18 | C30: =_xlfn.CONCAT("SUMMARY OF GROSS PREMIUM INCOME UNDER GENERAL INSURANCE BUSINESS FOR THE PERIOD ENDED"," ",Details!$F$18) -> SUMMARY OF GROSS PREMIUM INCOME UNDER GENERAL INSURANCE BUSINESS FOR THE PERIOD ENDED 31.12.2025
B31: APPENDIX 19 | C31: =_xlfn.CONCAT("SUMMARY OF GENERAL INSURANCE BUSINESS MARKET SHARE PER CLASS FOR THE PERIOD ENDED"," ",Details!$F$18) -> SUMMARY OF GENERAL INSURANCE BUSINESS MARKET SHARE PER CLASS FOR THE PERIOD ENDED 31.12.2025
B32: APPENDIX 20 | C32: =_xlfn.CONCAT("SUMMARY OF CLAIMS PAID UNDER GENERAL INSURANCE BUSINESS FOR THE PERIOD ENDED"," ",Details!$F$18) -> SUMMARY OF CLAIMS PAID UNDER GENERAL INSURANCE BUSINESS FOR THE PERIOD ENDED 31.12.2025
B33: APPENDIX 21 | C33: =_xlfn.CONCAT("SUMMARY OF CLAIMS INCURRED UNDER GENERAL INSURANCE BUSINESS FOR THE PERIOD ENDED"," ",Details!$F$18) -> SUMMARY OF CLAIMS INCURRED UNDER GENERAL INSURANCE BUSINESS FOR THE PERIOD ENDED 31.12.2025
B34: APPENDIX 22 | C34: =_xlfn.CONCAT("SUMMARY OF INCURRED CLAIMS RATIOS UNDER GENERAL INSURANCE BUSINESS FOR THE PERIOD ENDED"," ",Details!$F$18) -> SUMMARY OF INCURRED CLAIMS RATIOS UNDER GENERAL INSURANCE BUSINESS FOR THE PERIOD ENDED 31.12.2025
B35: APPENDIX 23 | C35: =_xlfn.CONCAT("SUMMARY OF GENERAL INSURANCE BUSINESS REVENUE ACCOUNTS FOR THE PERIOD ENDED"," ",Details!$F$18) -> SUMMARY OF GENERAL INSURANCE BUSINESS REVENUE ACCOUNTS FOR THE PERIOD ENDED 31.12.2025
B36: APPENDIX 24 | C36: =_xlfn.CONCAT("SUMMARY OF MICROINSURANCE BUSINESS REVENUE ACCOUNTS FOR THE PERIOD ENDED"," ",Details!$F$18) -> SUMMARY OF MICROINSURANCE BUSINESS REVENUE ACCOUNTS FOR THE PERIOD ENDED 31.12.2025
B37: APPENDIX 25 | C37: =_xlfn.CONCAT("SUMMARY OF BUSINESS RESULTS UNDER MICRO INSURANCE BUSINESS FOR THE PERIOD ENDED"," ",Details!$F$18) -> SUMMARY OF BUSINESS RESULTS UNDER MICRO INSURANCE BUSINESS FOR THE PERIOD ENDED 31.12.2025

Sheet APPENDIX 1
B3: =_xlfn.CONCAT('Table of Contents'!B8,": ",'Table of Contents'!C8) -> APPENDIX 1: SUMMARY OF GENERAL INSURANCE BUSINESS PROFIT & LOSS ACCOUNTS FOR THE PERIOD ENDED 31.12.2025
B4: Company | C4: Insurance Revenue | D4: Insurance Service Expense | E4: Net expenses from reinsurance contracts held | F4: Insurance Service Result | G4: Net Investment Income | H4: Finance expenses from insurance contracts | I4: Finance income from reinsurance contracts | J4: Net Financial Result | K4: Asset management services revenue | L4: Other Income | M4: Other finance costs | N4: Other operating expenses | O4: Share of profit of associates and joint ventures accounted for using the equity method | P4: Profit before income tax | Q4: Income tax expense | R4: Profit for the year
B5: INSURERS
B6: AAR INSURANCE KENYA | C6: 12309693 | D6: 11767626 | E6: -32687.526 | F6: 574754.53 | G6: 738160.64 | H6: 0 | I6: 0 | J6: 738160.64 | K6: 0 | L6: 11818.483 | M6: 13476.897 | N6: 593240.67 | O6: 0 | P6: 718016.08 | Q6: 157747.4 | R6: 560268.68
B7: AFRICAN MERCHANT ASSURANCE | C7: 3764707.9 | D7: 2694540.6 | E7: 161575.88 | F7: 908591.4 | G7: 194549.02 | H7: 396376.16 | I7: 43488.455 | J7: -158338.69 | K7: 0 | L7: 0 | M7: 0 | N7: 487085.99 | O7: 0 | P7: 263166.72 | Q7: 37349.674 | R7: 225817.05
B8: APA INSURANCE LIMITED | C8: 19029084 | D8: 15588884 | E8: 2803547.4 | F8: 636652.89 | G8: 2056160.7 | H8: 1264285.1 | I8: 489592.52 | J8: 1281468.1 | K8: 0 | L8: 0 | M8: 22413.707 | N8: 459302.86 | O8: 0 | P8: 1436404.5 | Q8: -70485.353 | R8: 1506889.8
B9: BRITAM GENERAL INSURANCE | C9: 15255849 | D9: 11545994 | E9: 2779323.6 | F9: 930531.84 | G9: 1960381.6 | H9: 1205126.3 | I9: 511517.36 | J9: 1266772.7 | K9: 0 | L9: 35438.195 | M9: 33032.757 | N9: 398128.38 | O9: 0 | P9: 1801581.6 | Q9: 48.647 | R9: 1801532.9
B10: BUPA GLOBAL INSURANCE | C10: 2145748.9 | D10: 1981140.4 | E10: 453438.61 | F10: -288830.12 | G10: 81144.823 | H10: 0 | I10: 0 | J10: 81144.823 | K10: 0 | L10: 0 | M10: 0 | N10: 0 | O10: 0 | P10: -207685.29 | Q10: -16715.591 | R10: -190969.7
B11: CANNON GENERAL INSURANCE | C11: 2295386.6 | D11: 2487102.4 | E11: 120052.75 | F11: -311768.47 | G11: 498788.08 | H11: 120835.34 | I11: 71370.871 | J11: 449323.62 | K11: 0 | L11: 0 | M11: 0 | N11: 214762.87 | O11: 0 | P11: -77207.726 | Q11: 0 | R11: -77207.726
B12: CIC GENERAL INSURANCE COMPANY | C12: 18891677 | D12: 17351225 | E12: 1047035.5 | F12: 493415.81 | G12: 1301522.6 | H12: 455941.38 | I12: 110305.72 | J12: 955886.96 | K12: 0 | L12: 440375.68 | M12: 0 | N12: 460782.67 | O12: 0 | P12: 1428895.8 | Q12: 428668.74 | R12: 1000227
B13: CORPORATE INSURANCE COMPANY | C13: 0 | D13: 0 | E13: 0 | F13: 0 | G13: 0 | H13: 0 | I13: 0 | J13: 0 | K13: 0 | L13: 0 | M13: 0 | N13: 0 | O13: 0 | P13: 0 | Q13: 0 | R13: 0
B14: DEFINITE ASSURANCE COMPANY | C14: 711439.43 | D14: 515701.64 | E14: 1493.169 | F14: 194244.61 | G14: 0 | H14: 0 | I14: 0 | J14: 0 | K14: 0 | L14: 0 | M14: 0 | N14: 540741.68 | O14: 0 | P14: -346497.07 | Q14: 0 | R14: -346497.07
B15: DIRECTLINE ASSURANCE COMPANY | C15: 2891099.7 | D15: 3220443.1 | E15: 61924.504 | F15: -391267.92 | G15: 239822.88 | H15: 749755.13 | I15: 0 | J15: -509932.25 | K15: 0 | L15: 0 | M15: 0 | N15: 28625.34 | O15: 0 | P15: -929825.51 | Q15: 0 | R15: -929825.51
B16: EQUITY GENERAL INSURANCE LIMITED | C16: 1487881.8 | D16: 1238677.4 | E16: 64053.309 | F16: 185151.04 | G16: 140156.95 | H16: 0 | I16: 0 | J16: 140156.95 | K16: 0 | L16: 0 | M16: 0 | N16: 125167.14 | O16: 0 | P16: 200140.84 | Q16: 60042.253 | R16: 140098.59
B17: EQUITY HEALTH INSURANCE LIMITED | C17: 3734.7279 | D17: 7905.4547 | E17: -240.83358 | F17: -3929.8932 | G17: 53098.03 | H17: 0 | I17: 0 | J17: 53098.03 | K17: 0 | L17: 0 | M17: 0 | N17: 8960.9472 | O17: 0 | P17: 40207.19 | Q17: 12062.157 | R17: 28145.033
... B42: TRIDENT INSURANCE COMPANY | C42: 0 | D42: 0 | E42: 0 | F42: 0 | G42: 0 | H42: 0 | I42: 0 | J42: 0 | K42: 0 | L42: 0 | M42: 0 | N42: 0 | O42: 0 | P42: 0 | Q42: 0 | R42: 0
B43: TOTAL | C43: =SUM(C6:C42) -> 2.1941225e+08 | D43: =SUM(D6:D42) -> 1.8333493e+08 | E43: =SUM(E6:E42) -> 27360817 | F43: =SUM(F6:F42) -> 8716498.3 | G43: =SUM(G6:G42) -> 20518348 | H43: =SUM(H6:H42) -> 7600534.7 | I43: =SUM(I6:I42) -> 2149047 | J43: =SUM(J6:J42) -> 15066860 | ... R43: =SUM(R6:R42) -> 10706898
B44: REINSURERS
B45: CONTINENTAL REINSURANCE | C45: 5696642 | D45: 4668264.4 | E45: 526853.58 | F45: 501523.95 | G45: 240678.7 | H45: 642292.7 | I45: 266149.19 | J45: -135464.82 | K45: 0 | L45: 16912.396 | M45: 9683.745 | N45: 37924.267 | O45: 0 | P45: 335363.52 | Q45: 100609.05 | R45: 234754.46
B46: EAST AFRICA REINSURANCE | C46: 4478184.4 | D46: 3810500.9 | E46: 519512.66 | F46: 148170.85 | G46: 672574.01 | H46: 122909.46 | I46: 23325.911 | J46: 572990.46 | K46: 0 | L46: 0 | M46: 0 | N46: 91065.755 | O46: 0 | P46: 630095.55 | Q46: 157151.54 | R46: 472944.01
B47: GHANA REINSURANCE COMPANY | C47: 3800134.5 | D47: 3086636.3 | E47: 178539.36 | F47: 534958.82 | G47: 231792.13 | H47: 209159.29 | I47: 46888.859 | J47: 69521.698 | K47: 0 | L47: -36.91703 | M47: -29072.824 | N47: 150410.76 | O47: 0 | P47: 483105.66 | Q47: 144931.7 | R47: 338173.96
B48: KENYA REINSURANCE CORPORATION | C48: 11663307 | D48: 10660833 | E48: 1562451.2 | F48: -559977.73 | G48: 4101738.9 | H48: 413898.52 | I48: 53882.553 | J48: 3741723 | K48: 0 | L48: 315265.37 | M48: 102272.73 | N48: 1874687.2 | O48: 0 | P48: 1520050.6 | Q48: 455937.71 | R48: 1064112.9
B49: WAICA REINSURANCE KENYA LIMITED | C49: 5306780.5 | D49: 4030911.2 | E49: 34979.277 | F49: 1240890 | G49: 349963.1 | H49: 377865.48 | I49: 38057.66 | J49: 10155.282 | K49: 0 | L49: 4.545 | M49: 82988.744 | N49: 337861.47 | O49: 0 | P49: 830199.64 | Q49: 228560.83 | R49: 601638.81
B50: TOTAL | C50: =SUM(C45:C49) -> 30945048 | D50: =SUM(D45:D49) -> 26257146 | E50: =SUM(E45:E49) -> 2822336 | F50: =SUM(F45:F49) -> 1865565.9 | G50: =SUM(G45:G49) -> 5596746.9 | H50: =SUM(H45:H49) -> 1766125.5 | I50: =SUM(I45:I49) -> 428304.17 | J50: =SUM(J45:J49) -> 4258925.6 | ... R50: =SUM(R45:R49) -> 2711624.2
B51: GRAND TOTAL | C51: =C43+C50 -> 2.503573e+08 | D51: =D43+D50 -> 2.0959208e+08 | E51: =E43+E50 -> 30183153 | F51: =F43+F50 -> 10582064 | G51: =G43+G50 -> 26115095 | H51: =H43+H50 -> 9366660.2 | I51: =I43+I50 -> 2577351.2 | J51: =J43+J50 -> 19325786 | ... R51: =R43+R50 -> 13418523
B52: Amounts in Thousand Shillings

Sheet APPENDIX 2
B3: =_xlfn.CONCAT('Table of Contents'!B9,": ",'Table of Contents'!C9) -> APPENDIX 2: SUMMARY OF LONG TERM INSURANCE BUSINESS PROFIT & LOSS ACCOUNTS FOR THE PERIOD ENDED 31.12.2025
B4: Company | C4: Insurance Revenue | D4: Insurance Service Expense | E4: Net expenses from reinsurance contracts held | F4: Insurance Service Result | G4: Net Investment Income | H4: Finance expenses from insurance contracts | I4: Finance income from reinsurance contracts | J4: Net Financial Result | K4: Asset management services revenue | L4: Other Income | M4: Other finance costs | N4: Other operating expenses | O4: Share of profit of associates and joint ventures accounted for using the equity method | P4: Profit before income tax | Q4: Income tax expense | R4: Profit for the year
B5: INSURERS
B6: ABSA LIFE ASSURANCE | C6: 7999022.1 | D6: 7415893.1 | E6: 444977.49 | F6: 138151.51 | G6: 2358873.5 | H6: 3911424.2 | I6: 52486.125 | J6: -1500064.6 | K6: 0 | L6: 0 | M6: -32221.011 | N6: 194147.2 | O6: 0 | P6: -1523839.2 | Q6: -523609.27 | R6: -1000230
B7: APA LIFE ASSURANCE COMPANY | C7: 4495527.7 | D7: 3500961.7 | E7: 581574.79 | F7: 412991.21 | G7: 3050262 | H7: 2773464.7 | I7: 74054.436 | J7: 350851.74 | K7: 0 | L7: 0 | M7: 29770.145 | N7: 152360.42 | O7: 0 | P7: 581712.39 | Q7: 36154.957 | R7: 545557.43
B8: BRITAM LIFE ASSURANCE | C8: 14878232 | D8: 10799996 | E8: 1401923.4 | F8: 2676312.9 | G8: 27294855 | H8: 26425566 | I8: 146531.35 | J8: 1015820.2 | K8: 0 | L8: -2600.692 | M8: 42466.494 | N8: 698027.64 | O8: 727319.68 | P8: 3676358 | Q8: 1102907.4 | R8: 2573450.6
B9: CANNON LIFE ASSURANCE (K) LIMITED | C9: 481760.75 | D9: 487063.3 | E9: 88837.333 | F9: -94139.886 | G9: 139798.73 | H9: 71376.537 | I9: 2177.5877 | J9: 70599.781 | K9: 0 | L9: 15747.5 | M9: 0 | N9: 9819.1657 | O9: 0 | P9: -17611.77 | Q9: 9316.562 | R9: -26928.332
B10: CAPEX LIFE ASSURANCE COMPANY | C10: 1598705.5 | D10: 1461270.4 | E10: 63833.714 | F10: 73601.47 | G10: 36741.364 | H10: 15177.119 | I10: 3105.436 | J10: 24669.681 | K10: 0 | L10: -1319.752 | M10: 0 | N10: 19884.956 | O10: 0 | P10: 77066.443 | Q10: 19981.511 | R10: 57084.932
B11: CIC LIFE ASSURANCE COMPANY | C11: 7129652.9 | D11: 7126604.5 | E11: -76645.722 | F11: 79694.152 | G11: 2027539.1 | H11: 4024946.1 | I11: 65029.994 | J11: -1932377 | K11: 1965632 | L11: 388686.02 | M11: 0 | N11: 270315.73 | O11: 0 | P11: 231319.44 | Q11: 61751.348 | R11: 169568.09
B12: CORPORATE INSURANCE COMPANY | C12: 54932.119 | D12: 147081.05 | E12: 10265.994 | F12: -102414.93 | G12: 8082.879 | H12: 32132.494 | I12: 0 | J12: -24049.615 | K12: 0 | L12: 0 | M12: 0 | N12: 3446.0658 | O12: 0 | P12: -129910.61 | Q12: 0 | R12: -129910.61
B13: EQUITY LIFE ASSURANCE | C13: 2078131.1 | D13: 1604240.2 | E13: 97004.823 | F13: 376886 | G13: 4225723 | H13: 2676924.8 | I13: 39139.573 | J13: 1587937.7 | K13: 0 | L13: 144232.69 | M13: 0 | N13: 331848.28 | O13: 0 | P13: 1777208.1 | Q13: 533162.44 | R13: 1244045.7
B14: GA LIFE ASSURANCE COMPANY | C14: 85531.404 | D14: 52896.341 | E14: 9336.632 | F14: 23298.431 | G14: 7138437.2 | H14: 0 | I14: 0 | J14: 7138437.2 | K14: 0 | L14: 1082667.6 | M14: 771.453 | N14: 227854.6 | O14: 0 | P14: 8015777.2 | Q14: 84.755 | R14: 8015692.4
B15: GEMINIA LIFE INSURANCE COMPANY | C15: 398161.3 | D15: 168922.82 | E15: 10843.237 | F15: 218395.24 | G15: 6146.895 | H15: -13653.857 | I15: 0 | J15: 19800.752 | K15: 0 | L15: 0 | M15: 0 | N15: 97584.115 | O15: 0 | P15: 140611.88 | Q15: 0 | R15: 140611.88
B16: ICEA LION LIFE ASSURANCE | C16: 7845134.9 | D16: 5629572.9 | E16: 106287.18 | F16: 2109274.8 | G16: 28730284 | H16: 23630715 | I16: 0 | J16: 5099569 | K16: 0 | L16: 26819.761 | M16: 0 | N16: 683576.32 | O16: 0 | P16: 6552087.3 | Q16: 1965613 | R16: 4586474.3
B17: JUBILEE LIFE INSURANCE | C17: 4273477.1 | D17: 3901981 | E17: 325043.29 | F17: 46452.806 | G17: 26997518 | H17: 23281143 | I17: 0 | J17: 3716375 | K17: 0 | L17: 0 | M17: 0 | N17: 1297578 | O17: 28321.349 | P17: 2493571.2 | Q17: 419937.39 | R17: 2073633.8
... B29: THE MONARCH INSURANCE | C29: 0 | D29: 0 | E29: 0 | F29: 0 | G29: 0 | H29: 0 | I29: 0 | J29: 0 | K29: 0 | L29: 0 | M29: 0 | N29: 0 | O29: 0 | P29: 0 | Q29: 0 | R29: 0
B30: TOTAL | C30: =SUM(C6:C29) -> 74377062 | D30: =SUM(D6:D29) -> 64111089 | E30: =SUM(E6:E29) -> 3640408.3 | F30: =SUM(F6:F29) -> 6625565.3 | G30: =SUM(G6:G29) -> 1.31083e+08 | H30: =SUM(H6:H29) -> 1.1389757e+08 | I30: =SUM(I6:I29) -> 444302.57 | J30: =SUM(J6:J29) -> 17629730 | ... R30: =SUM(R6:R29) -> 19004432
B31: REINSURERS
B32: CONTINENTAL REINSURANCE | C32: 36272.799 | D32: 103392.75 | E32: -3476.847 | F32: -63643.105 | G32: 68066.016 | H32: 5608.024 | I32: 626.984 | J32: 63084.976 | K32: 0 | L32: 0.012 | M32: 2016.506 | N32: 940.401 | O32: 0 | P32: -3515.024 | Q32: 1054.507 | R32: -2460.517
B33: EAST AFRICA REINSURANCE | C33: 1334886.2 | D33: 1085660.3 | E33: 91040.993 | F33: 158184.87 | G33: 267767.59 | H33: 22343.517 | I33: 5362.2192 | J33: 250786.29 | K33: 0 | L33: 0 | M33: 0 | N33: 14366.242 | O33: 0 | P33: 394604.92 | Q33: -127899.56 | R33: 266705.37
B34: KENYA REINSURANCE CORPORATION | C34: 2918918.1 | D34: 3197289.1 | E34: -65951.856 | F34: -212419.16 | G34: 1020339.1 | H34: 109322.35 | I34: -1280.8807 | J34: 909735.91 | K34: 0 | L34: 0 | M34: -2.993 | N34: 102691.13 | O34: 0 | P34: 594628.61 | Q34: -178388.7 | R34: 416239.91
B35: TOTAL | C35: =SUM(C32:C34) -> 4290077.1 | D35: =SUM(D32:D34) -> 4386342.2 | E35: =SUM(E32:E34) -> 21612.29 | F35: =SUM(F32:F34) -> -117877.39 | G35: =SUM(G32:G34) -> 1356172.7 | H35: =SUM(H32:H34) -> 137273.89 | I35: =SUM(I32:I34) -> 4708.3225 | J35: =SUM(J32:J34) -> 1223607.2 | ... R35: =SUM(R32:R34) -> 680484.76
B36: GRAND TOTAL | C36: =C35+C30 -> 78667139 | D36: =D35+D30 -> 68497431 | E36: =E35+E30 -> 3662020.6 | F36: =F35+F30 -> 6507687.9 | G36: =G35+G30 -> 1.3243917e+08 | H36: =H35+H30 -> 1.1403484e+08 | I36: =I35+I30 -> 449010.89 | J36: =J35+J30 -> 18853337 | ... R36: =R35+R30 -> 19684916
B37: Amounts in Thousand Shillings

Sheet APPENDIX 3
B3: =_xlfn.CONCAT('Table of Contents'!B10,": ",'Table of Contents'!C10) -> APPENDIX 3: SUMMARY OF MICRO INSURANCE BUSINESS PROFIT & LOSS ACCOUNTS FOR THE PERIOD ENDED 31.12.2025
B4: Company | C4: Insurance Revenue | D4: Insurance Service Expense | E4: Net expenses from reinsurance contracts held | F4: Insurance Service Result | G4: Net Investment Income | H4: Finance expenses from insurance contracts | I4: Finance income from reinsurance contracts | J4: Net Financial Result | K4: Asset management services revenue | L4: Other Income | M4: Other finance costs | N4: Other operating expenses | O4: Share of profit of associates and joint ventures accounted for using the equity method | P4: Profit before income tax | Q4: Income tax expense | R4: Profit for the year
B5: INSURERS
B6: APA MICRO INSURANCE | C6: 0 | D6: 0 | E6: 0 | F6: 0 | G6: 0 | H6: 0 | I6: 0 | J6: 0 | K6: 0 | L6: 0 | M6: 0 | N6: 0 | O6: 0 | P6: 0 | Q6: 0 | R6: 0
B7: BIRDVIEW MICRO INSURANCE | C7: 5620.9536 | D7: 39396.988 | E7: 345.44319 | F7: -34121.477 | G7: 0 | H7: 0 | I7: 0 | J7: 0 | K7: 0 | L7: 0 | M7: 0 | N7: 0 | O7: 0 | P7: -34121.477 | Q7: 0 | R7: -34121.477
B8: BRITAM MICRO INSURANCE | C8: 1090229.5 | D8: 1010963.6 | E8: 39922.421 | F8: 39343.462 | G8: 47074.091 | H8: 43598.521 | I8: 92.07156 | J8: 3567.6414 | K8: 0 | L8: 7093.2743 | M8: 5284.9804 | N8: 67954.175 | O8: 0 | P8: -23234.778 | Q8: 0 | R8: -23234.778
B9: CIC MICRO INSURANCE | C9: 2447.5647 | D9: 12589.965 | E9: 118.14515 | F9: -10260.545 | G9: 2383.7418 | H9: 0 | I9: 0 | J9: 2383.7418 | K9: 0 | L9: 55.0619 | M9: 0 | N9: 9754.658 | O9: 0 | P9: -17576.4 | Q9: 0 | R9: -17576.4
B10: STAR DISCOVER MICRO INSURANCE
B11: TURACO MICRO INSURANCE | C11: 466714.82 | D11: 374676.64 | E11: 47250.138 | F11: 44788.047 | G11: 11045.685 | H11: 0 | I11: 0 | J11: 11045.685 | K11: 0 | L11: 0 | M11: 0 | N11: 0 | O11: 0 | P11: 55833.732 | Q11: 0 | R11: 55833.732
B12: TOTAL | C12: =SUM(C6:C11) -> 1565012.8 | D12: =SUM(D6:D11) -> 1437627.2 | E12: =SUM(E6:E11) -> 87636.147 | F12: =SUM(F6:F11) -> 39749.486 | G12: =SUM(G6:G11) -> 60503.518 | H12: =SUM(H6:H11) -> 43598.521 | I12: =SUM(I6:I11) -> 92.07156 | J12: =SUM(J6:J11) -> 16997.068 | ... R12: =SUM(R6:R11) -> -19098.923
B13: Amounts in Thousand Shillings

Sheet APPENDIX 4 i
B4: =_xlfn.CONCAT('Table of Contents'!B11,": ",'Table of Contents'!C11) -> APPENDIX 4 i: SUMMARY OF LONG TERM INSURANCE BUSINESS BALANCE SHEETS AS AT 31.12.2025
B5: Company | C5: ABSA LIFE ASSURANCE | D5: APA LIFE ASSURANCE COMPANY | E5: BRITAM LIFE ASSURANCE | F5: CANNON LIFE ASSURANCE (K) LIMITED | G5: CAPEX LIFE ASSURANCE COMPANY | H5: CIC LIFE ASSURANCE COMPANY | I5: CONTINENTAL REINSURANCE | J5: CORPORATE INSURANCE COMPANY | K5: EAST AFRICA REINSURANCE
B6: Share Capital | C6: 699000 | D6: 1100000 | E6: 1200000 | F6: 416725.77 | G6: 400000 | H6: 800000 | I6: 500000 | J6: 200000 | K6: 500000
B7: Share Premium_x000D_ | C7: 0 | D7: 0 | E7: 0 | F7: 491067.65 | G7: 0 | H7: 0 | I7: 0 | J7: 0 | K7: 0
B8: Revaluation Reserves | C8: 0 | D8: 0 | E8: 0 | F8: 2500 | G8: 2072.909 | H8: 0 | I8: 0 | J8: -8100 | K8: 0
B9: Statutory Reserves | C9: 778220.1 | D9: -113765.05 | E9: 16650414 | F9: 0 | G9: 1120.164 | H9: 2248532 | I9: 0 | J9: 0 | K9: 0
B10: Other Equity | C10: 1000000 | D10: 0 | E10: 0 | F10: 404206.58 | G10: 0 | H10: 588924.67 | I10: -0.001 | J10: 0 | K10: 0
B11: Retained Earnings | C11: -1000230.2 | D11: 790348.24 | E11: 75000 | F11: -1248907.1 | G11: 284659.29 | H11: 4.7946692e-05 | I11: -2461.1683 | J11: -295693.98 | K11: 1322979.5
B12: Other Reserves | C12: 0 | D12: 122330.97 | E12: 0 | F12: 518154.63 | G12: 0 | H12: 0 | I12: 0 | J12: -205203 | K12: 0
B13: Total Equity_x000D_ | C13: 1476989.9 | D13: 1898914.2 | E13: 17925414 | F13: 583747.49 | G13: 687852.36 | H13: 3637456.7 | I13: 497538.83 | J13: -308996.98 | K13: 1822979.5
B14: Investment Contract Liabilites | C14: 0 | D14: 290376.27 | E14: 0 | F14: 0 | G14: 17360.134 | H14: 98924.319 | I14: 0 | J14: 0 | K14: 0
B15: Insurance Contract Liabilites | C15: 19163545 | D15: 25685137 | E15: 1.7426825e+08 | F15: 804549.28 | G15: 1316385.2 | H15: 37157330 | I15: 83563.37 | J15: 947009.01 | K15: 750944.86
B16: Reinsurance Contract Liabilites | C16: 0 | D16: 0 | E16: 3217.346 | F16: 0 | G16: 60826.293 | H16: 0 | I16: 5985.719 | J16: 0 | K16: 99143.935
B17: Long-Term Liabilites | C17: 0 | D17: 0 | E17: 7135891.8 | F17: 0 | G17: 0 | H17: 1034704.6 | I17: 70315.084 | J17: 0 | K17: 566991.12
... B43: Total Assets | C43: 21422690 | D43: 28346986 | E43: 2.020984e+08 | F43: 1745432.2 | G43: 2149111.3 | H43: 43001821 | I43: 729779.93 | J43: 781095.72 | K43: 3247556.7
B44: Amounts in Thousand Shillings | J44: Continued next page

Sheet APPENDIX 4 ii
B3: Continued from previous page
B4: =_xlfn.CONCAT('Table of Contents'!B12,": ",'Table of Contents'!C12) -> APPENDIX 4 ii: SUMMARY OF LONG TERM INSURANCE BUSINESS BALANCE SHEETS AS AT 31.12.2025
B5: Company | C5: EQUITY LIFE ASSURANCE | D5: GA LIFE ASSURANCE COMPANY | E5: GEMINIA LIFE INSURANCE COMPANY | F5: ICEA LION LIFE ASSURANCE | G5: JUBILEE LIFE INSURANCE | H5: KENINDIA ASSURANCE COMPANY | I5: KENYA ORIENT LIFE ASSURANCE | J5: KENYA REINSURANCE CORPORATION | K5: KUSCCO MUTUAL ASSURANCE LIMITED
B6: Share Capital | C6: 420000 | D6: 400000 | E6: 458093.68 | F6: 1125000 | G6: 500000 | H6: 900000 | I6: 313000 | J6: 500000 | K6: 0
B7: Share Premium_x000D_ | C7: 180000 | D7: 0 | E7: 0 | F7: 1125000 | G7: 0 | H7: 1000000 | I7: 0 | J7: 0 | K7: 0
B8: Revaluation Reserves | C8: 0 | D8: 0 | E8: 0 | F8: 0 | G8: 0 | H8: -536.59 | I8: 0 | J8: 0 | K8: 0
B9: Statutory Reserves | C9: 0 | D9: 9749606.2 | E9: 316903 | F9: 18510139 | G9: 0 | H9: 0 | I9: 228861.75 | J9: 0 | K9: 0
B10: Other Equity | C10: 0 | D10: 0 | E10: 0 | F10: 1015000 | G10: 0 | H10: 0 | I10: 0 | J10: 0 | K10: 0
B11: Retained Earnings | C11: 3445095.5 | D11: 70798.782 | E11: 404024.89 | F11: 5232443.2 | G11: 8190483.3 | H11: 2450187.5 | I11: 87724.449 | J11: 10773758 | K11: 0
B12: Other Reserves | C12: 4020853.2 | D12: 0 | E12: 0 | F12: 0 | G12: 3067746.2 | H12: 2384092.7 | I12: 0 | J12: 0 | K12: 0
B13: Total Equity_x000D_ | C13: 8065948.7 | D13: 10220405 | E13: 1179021.6 | F13: 27007582 | G13: 11758229 | H13: 6733743.6 | I13: 629586.2 | J13: 11273758 | K13: 0
B14: Investment Contract Liabilites | C14: 0 | D14: 48577386 | E14: 1257322.5 | F14: 0 | G14: 0 | H14: 0 | I14: 2081460.1 | J14: 0 | K14: 0
B15: Insurance Contract Liabilites | C15: 25000416 | D15: 41755.416 | E15: 1546154.3 | F15: 1.820023e+08 | G15: 1.6624529e+08 | H15: 1.0779783e+08 | I15: 3098899.8 | J15: 2133750.8 | K15: 0
B16: Reinsurance Contract Liabilites | C16: 0 | D16: 0 | E16: 0 | F16: 0 | G16: 0 | H16: 23126.829 | I16: 0 | J16: 0 | K16: 0
B17: Long-Term Liabilites | C17: 1328750.4 | D17: 0 | E17: 58439.677 | F17: 5520156 | G17: 1378255 | H17: 1021648.4 | I17: 131859.1 | J17: 0 | K17: 0
... B43: Total Assets | C43: 35949764 | D43: 63409248 | E43: 4151589.1 | F43: 2.1593023e+08 | G43: 1.8131079e+08 | H43: 1.1621327e+08 | I43: 5964701.1 | J43: 13604371 | K43: 0
B44: Amounts in Thousand Shillings | J44: Continued next page

Sheet APPENDIX 4 iii
B3: Continued from previous page
B4: =_xlfn.CONCAT('Table of Contents'!B13,": ",'Table of Contents'!C13) -> APPENDIX 4 iii: SUMMARY OF LONG TERM INSURANCE BUSINESS BALANCE SHEETS AS AT 31.12.2025 | Q4: Industry
B5: Company | C5: LIBERTY LIFE ASSURANCE COMPANY | D5: MADISON INSURANCE COMPANY | E5: OLD MUTUAL LIFE ASSURANCE KENYA | F5: PIONEER ASSURANCE COMPANY | G5: PRUDENTIAL LIFE ASSURANCE | H5: SANLAM LIFE ASSURANCE | I5: STAR DISCOVER LIFE INSURANCE | J5: THE KENYAN ALLIANCE INSURANCE | K5: THE MONARCH INSURANCE | L5: TOTAL | N5: Insurers | O5: Reinsurers | Q5: Insurers | R5: Reinsurers | S5: Total
B6: Share Capital | C6: 742340 | D6: 450000 | E6: 2946667.4 | F6: 400000 | G6: 425698.08 | H6: 843138.54 | I6: 400000 | J6: 510000 | K6: 0 | L6: 17149663 | N6: =SUMIFS('APPENDIX 4 iii'!$B6:$L6,'APPENDIX 4 iii'!$B$5:$L$5,"*total*")-O6 -> 15649663 | O6: =SUMIFS('APPENDIX 4 i'!$B6:$K6,'APPENDIX 4 i'!$B$5:$K$5,"*reinsurance*")+ SUMIFS('APPENDIX 4 ii'!$B6:$K6,'APPENDIX 4 ii'!$B$5:$K$5,"*reinsurance*")+ SUMIFS('APPENDIX 4 iii'!$B6:$K6,'APPENDIX 4 iii'!$B$5:$K$5,"*reinsurance*") -> 1500000 | Q6: =N6+_xlfn.XLOOKUP($B6,'APPENDIX 5 iv'!$B:$B,'APPENDIX 5 iv'!P:P,0,0)+_xlfn.XLOOKUP($B6,'APPENDIX 6'!$B:$B,'APPENDIX 6'!I:I,0,0) -> 54329466 | R6: =O6+_xlfn.XLOOKUP($B6,'APPENDIX 5 iv'!$B:$B,'APPENDIX 5 iv'!Q:Q,0,0)+_xlfn.XLOOKUP($B6,'APPENDIX 6'!$B:$B,'APPENDIX 6'!J:J,0,0) -> 19101531 | S6: =SUM(Q6:R6) -> 73430998
B7: Share Premium_x000D_ | C7: 0 | D7: 0 | E7: 1160475.7 | F7: 0 | G7: 3768621.6 | H7: 30260 | I7: 0 | J7: 0 | K7: 0 | L7: 7755424.9 | N7: =SUMIFS('APPENDIX 4 iii'!$B7:$L7,'APPENDIX 4 iii'!$B$5:$L$5,"*total*")-O7 -> 7755424.9 | O7: =SUMIFS('APPENDIX 4 i'!$B7:$K7,'APPENDIX 4 i'!$B$5:$K$5,"*reinsurance*")+ SUMIFS('APPENDIX 4 ii'!$B7:$K7,'APPENDIX 4 ii'!$B$5:$K$5,"*reinsurance*")+ SUMIFS('APPENDIX 4 iii'!$B7:$K7,'APPENDIX 4 iii'!$B$5:$K$5,"*reinsurance*") -> 0 | Q7: =N7+_xlfn.XLOOKUP($B7,'APPENDIX 5 iv'!$B:$B,'APPENDIX 5 iv'!P:P,0,0)+_xlfn.XLOOKUP($B7,'APPENDIX 6'!$B:$B,'APPENDIX 6'!I:I,0,0) -> 9564516.2 | R7: =O7+_xlfn.XLOOKUP($B7,'APPENDIX 5 iv'!$B:$B,'APPENDIX 5 iv'!Q:Q,0,0)+_xlfn.XLOOKUP($B7,'APPENDIX 6'!$B:$B,'APPENDIX 6'!J:J,0,0) -> 10871.242 | S7: =SUM(Q7:R7) -> 9575387.4
B8: Revaluation Reserves | C8: 384946.36 | D8: 19341 | E8: 0 | F8: 0 | G8: 0 | H8: 0 | I8: 0 | J8: 0 | K8: 0 | L8: 400223.68 | N8: =SUMIFS('APPENDIX 4 iii'!$B8:$L8,'APPENDIX 4 iii'!$B$5:$L$5,"*total*")-O8 -> 400223.68 | O8: =SUMIFS('APPENDIX 4 i'!$B8:$K8,'APPENDIX 4 i'!$B$5:$K$5,"*reinsurance*")+ SUMIFS('APPENDIX 4 ii'!$B8:$K8,'APPENDIX 4 ii'!$B$5:$K$5,"*reinsurance*")+ SUMIFS('APPENDIX 4 iii'!$B8:$K8,'APPENDIX 4 iii'!$B$5:$K$5,"*reinsurance*") -> 0 | Q8: =N8+_xlfn.XLOOKUP($B8,'APPENDIX 5 iv'!$B:$B,'APPENDIX 5 iv'!P:P,0,0)+_xlfn.XLOOKUP($B8,'APPENDIX 6'!$B:$B,'APPENDIX 6'!I:I,0,0) -> 3241322.4 | R8: =O8+_xlfn.XLOOKUP($B8,'APPENDIX 5 iv'!$B:$B,'APPENDIX 5 iv'!Q:Q,0,0)+_xlfn.XLOOKUP($B8,'APPENDIX 6'!$B:$B,'APPENDIX 6'!J:J,0,0) -> 258456.3 | S8: =SUM(Q8:R8) -> 3499778.7
B9: Statutory Reserves | C9: 2071905.5 | D9: 0 | E9: 131486.3 | F9: 232406.33 | G9: 0 | H9: 3288226.9 | I9: 0 | J9: 0 | K9: 0 | L9: 54094056 | N9: =SUMIFS('APPENDIX 4 iii'!$B9:$L9,'APPENDIX 4 iii'!$B$5:$L$5,"*total*")-O9 -> 54094056 | O9: =SUMIFS('APPENDIX 4 i'!$B9:$K9,'APPENDIX 4 i'!$B$5:$K$5,"*reinsurance*")+ SUMIFS('APPENDIX 4 ii'!$B9:$K9,'APPENDIX 4 ii'!$B$5:$K$5,"*reinsurance*")+ SUMIFS('APPENDIX 4 iii'!$B9:$K9,'APPENDIX 4 iii'!$B$5:$K$5,"*reinsurance*") -> 0 | Q9: =N9+_xlfn.XLOOKUP($B9,'APPENDIX 5 iv'!$B:$B,'APPENDIX 5 iv'!P:P,0,0)+_xlfn.XLOOKUP($B9,'APPENDIX 6'!$B:$B,'APPENDIX 6'!I:I,0,0) -> 54094056 | R9: =O9+_xlfn.XLOOKUP($B9,'APPENDIX 5 iv'!$B:$B,'APPENDIX 5 iv'!Q:Q,0,0)+_xlfn.XLOOKUP($B9,'APPENDIX 6'!$B:$B,'APPENDIX 6'!J:J,0,0) -> 0 | S9: =SUM(Q9:R9) -> 54094056
B10: Other Equity | C10: 600000 | D10: 2050000 | E10: 0 | F10: 0 | G10: 0 | H10: 0 | I10: 0 | J10: 0 | K10: 0 | L10: 5658131.2 | N10: =SUMIFS('APPENDIX 4 iii'!$B10:$L10,'APPENDIX 4 iii'!$B$5:$L$5,"*total*")-O10 -> 5658131.3 | O10: =SUMIFS('APPENDIX 4 i'!$B10:$K10,'APPENDIX 4 i'!$B$5:$K$5,"*reinsurance*")+ SUMIFS('APPENDIX 4 ii'!$B10:$K10,'APPENDIX 4 ii'!$B$5:$K$5,"*reinsurance*")+ SUMIFS('APPENDIX 4 iii'!$B10:$K10,'APPENDIX 4 iii'!$B$5:$K$5,"*reinsurance*") -> -0.001 | Q10: =N10+_xlfn.XLOOKUP($B10,'APPENDIX 5 iv'!$B:$B,'APPENDIX 5 iv'!P:P,0,0)+_xlfn.XLOOKUP($B10,'APPENDIX 6'!$B:$B,'APPENDIX 6'!I:I,0,0) -> 9294304.1 | R10: =O10+_xlfn.XLOOKUP($B10,'APPENDIX 5 iv'!$B:$B,'APPENDIX 5 iv'!Q:Q,0,0)+_xlfn.XLOOKUP($B10,'APPENDIX 6'!$B:$B,'APPENDIX 6'!J:J,0,0) -> 627494.57 | S10: =SUM(Q10:R10) -> 9921798.7
B11: Retained Earnings | C11: -304169.9 | D11: 62000 | E11: -413300.98 | F11: 371258.93 | G11: -3475210.8 | H11: 235067.35 | I11: 305693.34 | J11: -630249.63 | K11: 0 | L11: 26731299 | N11: =SUMIFS('APPENDIX 4 iii'!$B11:$L11,'APPENDIX 4 iii'!$B$5:$L$5,"*total*")-O11 -> 14637022 | O11: =SUMIFS('APPENDIX 4 i'!$B11:$K11,'APPENDIX 4 i'!$B$5:$K$5,"*reinsurance*")+ SUMIFS('APPENDIX 4 ii'!$B11:$K11,'APPENDIX 4 ii'!$B$5:$K$5,"*reinsurance*")+ SUMIFS('APPENDIX 4 iii'!$B11:$K11,'APPENDIX 4 iii'!$B$5:$K$5,"*reinsurance*") -> 12094277 | Q11: =N11+_xlfn.XLOOKUP($B11,'APPENDIX 5 iv'!$B:$B,'APPENDIX 5 iv'!P:P,0,0)+_xlfn.XLOOKUP($B11,'APPENDIX 6'!$B:$B,'APPENDIX 6'!I:I,0,0) -> 60479169 | R11: =O11+_xlfn.XLOOKUP($B11,'APPENDIX 5 iv'!$B:$B,'APPENDIX 5 iv'!Q:Q,0,0)+_xlfn.XLOOKUP($B11,'APPENDIX 6'!$B:$B,'APPENDIX 6'!J:J,0,0) -> 45743195 | S11: =SUM(Q11:R11) -> 1.0622236e+08
B12: Other Reserves | C12: 0 | D12: -4263247 | E12: 27533.634 | F12: 0 | G12: 0 | H12: 0 | I12: 0 | J12: 0 | K12: 0 | L12: 5672261.3 | N12: =SUMIFS('APPENDIX 4 iii'!$B12:$L12,'APPENDIX 4 iii'!$B$5:$L$5,"*total*")-O12 -> 5672261.3 | O12: =SUMIFS('APPENDIX 4 i'!$B12:$K12,'APPENDIX 4 i'!$B$5:$K$5,"*reinsurance*")+ SUMIFS('APPENDIX 4 ii'!$B12:$K12,'APPENDIX 4 ii'!$B$5:$K$5,"*reinsurance*")+ SUMIFS('APPENDIX 4 iii'!$B12:$K12,'APPENDIX 4 iii'!$B$5:$K$5,"*reinsurance*") -> 0 | Q12: =N12+_xlfn.XLOOKUP($B12,'APPENDIX 5 iv'!$B:$B,'APPENDIX 5 iv'!P:P,0,0)+_xlfn.XLOOKUP($B12,'APPENDIX 6'!$B:$B,'APPENDIX 6'!I:I,0,0) -> 8286005.2 | R12: =O12+_xlfn.XLOOKUP($B12,'APPENDIX 5 iv'!$B:$B,'APPENDIX 5 iv'!Q:Q,0,0)+_xlfn.XLOOKUP($B12,'APPENDIX 6'!$B:$B,'APPENDIX 6'!J:J,0,0) -> 1421695.6 | S12: =SUM(Q12:R12) -> 9707700.7
B13: Total Equity_x000D_ | C13: 3495022 | D13: -1681906 | E13: 3852862 | F13: 1003665.3 | G13: 719108.84 | H13: 4396692.8 | I13: 705693.34 | J13: -120249.63 | K13: 0 | L13: 1.1746106e+08 | N13: =SUMIFS('APPENDIX 4 iii'!$B13:$L13,'APPENDIX 4 iii'!$B$5:$L$5,"*total*")-O13 -> 1.0386678e+08 | O13: =SUMIFS('APPENDIX 4 i'!$B13:$K13,'APPENDIX 4 i'!$B$5:$K$5,"*reinsurance*")+ SUMIFS('APPENDIX 4 ii'!$B13:$K13,'APPENDIX 4 ii'!$B$5:$K$5,"*reinsurance*")+ SUMIFS('APPENDIX 4 iii'!$B13:$K13,'APPENDIX 4 iii'!$B$5:$K$5,"*reinsurance*") -> 13594277 | Q13: =N13+_xlfn.XLOOKUP($B13,'APPENDIX 5 iv'!$B:$B,'APPENDIX 5 iv'!P:P,0,0)+_xlfn.XLOOKUP($B13,'APPENDIX 6'!$B:$B,'APPENDIX 6'!I:I,0,0) -> 1.9890684e+08 | R13: =O13+_xlfn.XLOOKUP($B13,'APPENDIX 5 iv'!$B:$B,'APPENDIX 5 iv'!Q:Q,0,0)+_xlfn.XLOOKUP($B13,'APPENDIX 6'!$B:$B,'APPENDIX 6'!J:J,0,0) -> 67163244 | S13: =SUM(Q13:R13) -> 2.6607009e+08
B14: Investment Contract Liabilites | C14: 12442208 | D14: 0 | E14: 707847.45 | F14: 0 | G14: 0 | H14: 0 | I14: 0 | J14: 4775158 | K14: 0 | L14: 70248042 | N14: =SUMIFS('APPENDIX 4 iii'!$B14:$L14,'APPENDIX 4 iii'!$B$5:$L$5,"*total*")-O14 -> 70248042 | O14: =SUMIFS('APPENDIX 4 i'!$B14:$K14,'APPENDIX 4 i'!$B$5:$K$5,"*reinsurance*")+ SUMIFS('APPENDIX 4 ii'!$B14:$K14,'APPENDIX 4 ii'!$B$5:$K$5,"*reinsurance*")+ SUMIFS('APPENDIX 4 iii'!$B14:$K14,'APPENDIX 4 iii'!$B$5:$K$5,"*reinsurance*") -> 0 | Q14: =N14+_xlfn.XLOOKUP($B14,'APPENDIX 5 iv'!$B:$B,'APPENDIX 5 iv'!P:P,0,0)+_xlfn.XLOOKUP($B14,'APPENDIX 6'!$B:$B,'APPENDIX 6'!I:I,0,0) -> 70248042 | R14: =O14+_xlfn.XLOOKUP($B14,'APPENDIX 5 iv'!$B:$B,'APPENDIX 5 iv'!Q:Q,0,0)+_xlfn.XLOOKUP($B14,'APPENDIX 6'!$B:$B,'APPENDIX 6'!J:J,0,0) -> 0 | S14: =SUM(Q14:R14) -> 70248042
B15: Insurance Contract Liabilites | C15: 14605242 | D15: 21460800 | E15: 23719671 | F15: 18032422 | G15: 6137082.7 | H15: 30420933 | I15: 174105.22 | J15: 911842.75 | K15: 0 | L15: 8.6350521e+08 | N15: =SUMIFS('APPENDIX 4 iii'!$B15:$L15,'APPENDIX 4 iii'!$B$5:$L$5,"*total*")-O15 -> 8.6053695e+08 | O15: =SUMIFS('APPENDIX 4 i'!$B15:$K15,'APPENDIX 4 i'!$B$5:$K$5,"*reinsurance*")+ SUMIFS('APPENDIX 4 ii'!$B15:$K15,'APPENDIX 4 ii'!$B$5:$K$5,"*reinsurance*")+ SUMIFS('APPENDIX 4 iii'!$B15:$K15,'APPENDIX 4 iii'!$B$5:$K$5,"*reinsurance*") -> 2968259 | Q15: =N15+_xlfn.XLOOKUP($B15,'APPENDIX 5 iv'!$B:$B,'APPENDIX 5 iv'!P:P,0,0)+_xlfn.XLOOKUP($B15,'APPENDIX 6'!$B:$B,'APPENDIX 6'!I:I,0,0) -> 1.0291078e+09 | R15: =O15+_xlfn.XLOOKUP($B15,'APPENDIX 5 iv'!$B:$B,'APPENDIX 5 iv'!Q:Q,0,0)+_xlfn.XLOOKUP($B15,'APPENDIX 6'!$B:$B,'APPENDIX 6'!J:J,0,0) -> 26080713 | S15: =SUM(Q15:R15) -> 1.0551886e+09
B16: Reinsurance Contract Liabilites | C16: 0 | D16: 228776 | E16: 0 | F16: 0 | G16: 0 | H16: 0 | I16: 0 | J16: 0 | K16: 0 | L16: 421076.12 | N16: =SUMIFS('APPENDIX 4 iii'!$B16:$L16,'APPENDIX 4 iii'!$B$5:$L$5,"*total*")-O16 -> 315946.47 | O16: =SUMIFS('APPENDIX 4 i'!$B16:$K16,'APPENDIX 4 i'!$B$5:$K$5,"*reinsurance*")+ SUMIFS('APPENDIX 4 ii'!$B16:$K16,'APPENDIX 4 ii'!$B$5:$K$5,"*reinsurance*")+ SUMIFS('APPENDIX 4 iii'!$B16:$K16,'APPENDIX 4 iii'!$B$5:$K$5,"*reinsurance*") -> 105129.65 | Q16: =N16+_xlfn.XLOOKUP($B16,'APPENDIX 5 iv'!$B:$B,'APPENDIX 5 iv'!P:P,0,0)+_xlfn.XLOOKUP($B16,'APPENDIX 6'!$B:$B,'APPENDIX 6'!I:I,0,0) -> 3806417.8 | R16: =O16+_xlfn.XLOOKUP($B16,'APPENDIX 5 iv'!$B:$B,'APPENDIX 5 iv'!Q:Q,0,0)+_xlfn.XLOOKUP($B16,'APPENDIX 6'!$B:$B,'APPENDIX 6'!J:J,0,0) -> 1754720 | S16: =SUM(Q16:R16) -> 5561137.8
B17: Long-Term Liabilites | C17: 1052931.6 | D17: 0 | E17: 0 | F17: 103666.28 | G17: 0 | H17: 1409654.3 | I17: 0 | J17: 0 | K17: 0 | L17: 20813263 | N17: =SUMIFS('APPENDIX 4 iii'!$B17:$L17,'APPENDIX 4 iii'!$B$5:$L$5,"*total*")-O17 -> 20175957 | O17: =SUMIFS('APPENDIX 4 i'!$B17:$K17,'APPENDIX 4 i'!$B$5:$K$5,"*reinsurance*")+ SUMIFS('APPENDIX 4 ii'!$B17:$K17,'APPENDIX 4 ii'!$B$5:$K$5,"*reinsurance*")+ SUMIFS('APPENDIX 4 iii'!$B17:$K17,'APPENDIX 4 iii'!$B$5:$K$5,"*reinsurance*") -> 637306.2 | Q17: =N17+_xlfn.XLOOKUP($B17,'APPENDIX 5 iv'!$B:$B,'APPENDIX 5 iv'!P:P,0,0)+_xlfn.XLOOKUP($B17,'APPENDIX 6'!$B:$B,'APPENDIX 6'!I:I,0,0) -> 21720981 | R17: =O17+_xlfn.XLOOKUP($B17,'APPENDIX 5 iv'!$B:$B,'APPENDIX 5 iv'!Q:Q,0,0)+_xlfn.XLOOKUP($B17,'APPENDIX 6'!$B:$B,'APPENDIX 6'!J:J,0,0) -> 2056840.6 | S17: =SUM(Q17:R17) -> 23777822
... B43: Total Assets | C43: 32389142 | D43: 20550769 | E43: 29904983 | F43: 19511797 | G43: 7326873 | H43: 37240489 | I43: 893565.17 | J43: 5610059.5 | K43: 0 | L43: 1.0934845e+09 | N43: =SUMIFS('APPENDIX 4 iii'!$B43:$L43,'APPENDIX 4 iii'!$B$5:$L$5,"*total*")-O43 -> 1.0759028e+09 | O43: =SUMIFS('APPENDIX 4 i'!$B43:$K43,'APPENDIX 4 i'!$B$5:$K$5,"*reinsurance*")+ SUMIFS('APPENDIX 4 ii'!$B43:$K43,'APPENDIX 4 ii'!$B$5:$K$5,"*reinsurance*")+ SUMIFS('APPENDIX 4 iii'!$B43:$K43,'APPENDIX 4 iii'!$B$5:$K$5,"*reinsurance*") -> 17581708 | Q43: =N43+_xlfn.XLOOKUP($B43,'APPENDIX 5 iv'!$B:$B,'APPENDIX 5 iv'!P:P,0,0)+_xlfn.XLOOKUP($B43,'APPENDIX 6'!$B:$B,'APPENDIX 6'!I:I,0,0) -> 1.3676787e+09 | R43: =O43+_xlfn.XLOOKUP($B43,'APPENDIX 5 iv'!$B:$B,'APPENDIX 5 iv'!Q:Q,0,0)+_xlfn.XLOOKUP($B43,'APPENDIX 6'!$B:$B,'APPENDIX 6'!J:J,0,0) -> 99402604 | S43: =SUM(Q43:R43) -> 1.4670813e+09
B44: Amounts in Thousand Shillings
N47: =N43-N40-N39-N41-N42-N38-N24-N21-N22 -> 1.0283786e+09 | O47: =O43-O40-O39-O41-O42-O38-O24-O21-O22 -> 16721934 | Q47: =Q43-Q40-Q39-Q41-Q42-Q38-Q24-Q21-Q22 -> 1.2200674e+09 | R47: =R43-R40-R39-R41-R42-R38-R24-R21-R22 -> 85200245 | S47: =S43-S40-S39-S41-S42-S38-S24-S21-S22 -> 1.3052676e+09
N48: Life | P48: General | R48: Micro | S48: Industry
N49: Insurers | O49: Reinsurers | P49: Insurers | Q49: Reinsurers | R49: Microinsurers | S49: Insurers | T49: Reinsurers | U49: Total
M50: Equity | N50: =N13 -> 1.0386678e+08 | O50: =O13 -> 13594277 | P50: ='[1]APPENDIX 5 iv'!P12 -> 90922729 | Q50: ='[1]APPENDIX 5 iv'!Q12 -> 53446421 | R50: ='[1]APPENDIX 6 i'!I12 -> 305551.66 | S50: =Q13 -> 1.9890684e+08 | T50: =R13 -> 67163244 | U50: =S13 -> 2.6607009e+08 | V50: =IF(AND(SUM(N50:R50)=SUM(S50:T50),SUM(S50:T50)=U50),"Ok","Check") -> Check
M51: Assets | N51: =N43 -> 1.0759028e+09 | O51: =O43 -> 17581708 | P51: ='[1]APPENDIX 5 iv'!P41 -> 3.0299732e+08 | Q51: ='[1]APPENDIX 5 iv'!Q41 -> 80549341 | R51: ='[1]APPENDIX 6 i'!I41 -> 995719.77 | S51: =Q43 -> 1.3676787e+09 | T51: =R43 -> 99402604 | U51: =S43 -> 1.4670813e+09 | V51: =IF(AND(SUM(N51:R51)=SUM(S51:T51),SUM(S51:T51)=U51),"Ok","Check") -> Check
M52: Investments | N52: =SUM(N23,N25:N37) -> 1.0283786e+09 | O52: =SUM(O23,O25:O37) -> 16721934 | P52: =SUM('[1]APPENDIX 5 iv'!P21,'[1]APPENDIX 5 iv'!P23:P35) -> 1.9170523e+08 | Q52: =SUM('[1]APPENDIX 5 iv'!Q21,'[1]APPENDIX 5 iv'!Q23:Q35) -> 67454378 | R52: =SUM('[1]APPENDIX 6 i'!I21,'[1]APPENDIX 6 i'!I23:I35) -> 600634.44 | S52: =SUM(Q23,Q25:Q37) -> 1.2200674e+09 | T52: =SUM(R23,R25:R37) -> 85200245 | U52: =SUM(S23,S25:S37) -> 1.3052676e+09 | V52: =IF(AND(SUM(N52:R52)=SUM(S52:T52),SUM(S52:T52)=U52),"Ok","Check") -> Check

Sheet APPENDIX 5 i
B4: =_xlfn.CONCAT('Table of Contents'!B14,": ",'Table of Contents'!C14) -> APPENDIX 5 i: SUMMARY OF GENERAL INSURANCE BUSINESS BALANCE SHEETS AS AT 31.12.2025
B5: COMPANY | C5: AAR INSURANCE KENYA | D5: AFRICAN MERCHANT ASSURANCE | E5: APA INSURANCE LIMITED | F5: BRITAM GENERAL INSURANCE | G5: BUPA GLOBAL INSURANCE | H5: CANNON GENERAL INSURANCE | I5: CIC GENERAL INSURANCE COMPANY | J5: CONTINENTAL REINSURANCE | K5: CORPORATE INSURANCE COMPANY | L5: DEFINITE ASSURANCE COMPANY
B6: Share Capital | C6: 1017626.6 | D6: 987386 | E6: 1250000 | F6: 2668000 | G6: 1086683.1 | H6: 453960.46 | I6: 1700000 | J6: 1000000 | K6: 0 | L6: 711518.66
B7: Share Premium | C7: 460523 | D7: 0 | E7: 0 | F7: 0 | G7: 0 | H7: 583039.52 | I7: 0 | J7: 0 | K7: 0 | L7: 0
B8: Revaluation Reserve | C8: 0 | D8: 0 | E8: 234618.57 | F8: 0 | G8: 0 | H8: 74345 | I8: 0 | J8: 0 | K8: 0 | L8: 0
B9: Other Equity | C9: 0 | D9: 26469.279 | E9: 0 | F9: 0 | G9: 0 | H9: -86582 | I9: 261491.19 | J9: 705.556 | K9: 0 | L9: 0
B10: Retained Earnings | C10: 1220426.3 | D10: 397365.52 | E10: 5902178.3 | F10: 5744747.7 | G10: -213218.59 | H10: -229587.65 | I10: 4458007.7 | J10: 2067774.5 | K10: 0 | L10: -346497.07
B11: Other Reserves | C11: 0 | D11: 0 | E11: 0 | F11: 0 | G11: 0 | H11: 0 | I11: 0 | J11: -92125.444 | K11: 0 | L11: 0
B12: Total Equity_x000D_ | C12: 2698575.9 | D12: 1411220.8 | E12: 7386796.9 | F12: 8412747.7 | G12: 873464.55 | H12: 795175.33 | I12: 6419498.9 | J12: 2976354.6 | K12: 0 | L12: 365021.59
B13: Insurance Contract Liabilites | C13: 4967299.8 | D13: 2468260.8 | E13: 11099375 | F13: 11546882 | G13: 1870579.1 | H13: 2668764.1 | I13: 12135575 | J13: 5160618.4 | K13: 0 | L13: 812680.6
B14: Reinsurance Contract Liabilites | C14: 0 | D14: 0 | E14: 0 | F14: 22449.235 | G14: 0 | H14: 0 | I14: 0 | J14: 24374.617 | K14: 0 | L14: 0
B15: Long-Term Liabilites | C15: 0 | D15: 0 | E15: 0 | F15: 0 | G15: 0 | H15: 84201.965 | I15: 0 | J15: 0 | K15: 0 | L15: 0
B16: Short-Term Liabilites | C16: 283965.24 | D16: 246833.47 | E16: 921953.03 | F16: 561630.12 | G16: 39113.9 | H16: 479149.38 | I16: 602357.58 | J16: 0 | K16: 0 | L16: 22810.555
B17: Other Liabilites | C17: 370865.22 | D17: 101052.91 | E17: 171376.46 | F17: 714347.33 | G17: 855354.92 | H17: 30741.775 | I17: 63774.41 | J17: 178786.6 | K17: 0 | L17: 111870.01
... B41: Total Assets | C41: 8320706.1 | D41: 4227367.9 | E41: 19579502 | F41: 21258056 | G41: 3638512.5 | H41: 4058032.6 | I41: 19221206 | J41: 8340134.2 | K41: 0 | L41: 1312382.8
B42: Amounts in Thousand Shillings | K42: Continued next page

Sheet APPENDIX 5 ii
B3: Continued from previous page
B4: =_xlfn.CONCAT('Table of Contents'!B15,": ",'Table of Contents'!C15) -> APPENDIX 5 ii: SUMMARY OF GENERAL INSURANCE BUSINESS BALANCE SHEETS AS AT 31.12.2025
B5: COMPANY | C5: DIRECTLINE ASSURANCE COMPANY | D5: EAST AFRICA REINSURANCE | E5: EQUITY GENERAL INSURANCE LIMITED | F5: EQUITY HEALTH INSURANCE LIMITED | G5: FIDELITY SHIELD INSURANCE | H5: FIRST ASSURANCE COMPANY | I5: GA INSURANCE COMPANY | J5: GEMINIA INSURANCE COMPANY | K5: GHANA REINSURANCE COMPANY | L5: ICEA LION GENERAL INSURANCE
B6: Share Capital | C6: 300000 | D6: 1000000 | E6: 600000 | F6: 600000 | G6: 600000 | H6: 810000 | I6: 1500000 | J6: 1006250 | K6: 1000000 | L6: 1000000
B7: Share Premium | C7: 0 | D7: 0 | E7: 0 | F7: 0 | G7: 0 | H7: 512138.51 | I7: 0 | J7: 0 | K7: 10871.242 | L7: 0
B8: Revaluation Reserve | C8: 15447.29 | D8: 221544.99 | E8: 0 | F8: 0 | G8: 100140.56 | H8: 339179.19 | I8: 904878.74 | J8: 0 | K8: 0 | L8: 22567.995
B9: Other Equity | C9: 0 | D9: 0 | E9: 0 | F9: 0 | G9: 0 | H9: 0 | I9: -750000 | J9: -11810.996 | K9: 0 | L9: 400000
B10: Retained Earnings | C10: -2739567.5 | D10: 4913251.4 | E10: 196224.68 | F10: 28145.033 | G10: 678092.83 | H10: 296670.55 | I10: 7597100.7 | J10: 165833.06 | K10: 1300553.3 | L10: 7341621.4
B11: Other Reserves | C11: 0 | D11: 0 | E11: 0 | F11: 0 | G11: 0 | H11: 0 | I11: 873227.88 | J11: 47953.118 | K11: 0 | L11: 0
B12: Total Equity_x000D_ | C12: -2424120.2 | D12: 6134796.3 | E12: 796224.68 | F12: 628145.03 | G12: 1378233.4 | H12: 1957988.2 | I12: 10125207 | J12: 1208225.2 | K12: 2311424.5 | L12: 8764189.4
B13: Insurance Contract Liabilites | C13: 9520265.7 | D13: 3115873.7 | E13: 540350.38 | F13: 18559.363 | G13: 5296684.5 | H13: 5180952.1 | I13: 13603087 | J13: 5132874.1 | K13: 1202000.5 | L13: 7175065.9
B14: Reinsurance Contract Liabilites | C14: 0 | D14: 111006.35 | E14: 0 | F14: 0 | G14: 0 | H14: 0 | I14: 2056755.7 | J14: 0 | K14: 0 | L14: 239516.29
B15: Long-Term Liabilites | C15: 0 | D15: 0 | E15: 200000 | F15: 200000 | G15: 0 | H15: 0 | I15: 137686.41 | J15: 0 | K15: 0 | L15: 449102.85
B16: Short-Term Liabilites | C16: 260706.15 | D16: 522662.39 | E16: 397928.64 | F16: 10550.603 | G16: 182328.9 | H16: 103765.34 | I16: 489615.82 | J16: 0 | K16: 78527.515 | L16: 962934.05
B17: Other Liabilites | C17: 112804.27 | D17: 32244.74 | E17: 45789.816 | F17: 12062.157 | G17: 7573.6145 | H17: 522017.52 | I17: 417561.57 | J17: 41391.059 | K17: -0.00015000001 | L17: 88888.494
... B41: Total Assets | C41: 7469655.9 | D41: 9916583.5 | E41: 1980293.5 | F41: 869317.16 | G41: 6864820.4 | H41: 7764723.2 | I41: 26829914 | J41: 6382490.4 | K41: 3592026.4 | L41: 17679697
B42: Amounts in Thousand Shillings | K42: Continued next page

Sheet APPENDIX 5 iii
B3: Continued from previous page
B4: =_xlfn.CONCAT('Table of Contents'!B16,": ",'Table of Contents'!C16) -> APPENDIX 5 iii: SUMMARY OF GENERAL INSURANCE BUSINESS BALANCE SHEETS AS AT 31.12.2025
B5: COMPANY | C5: INTRA-AFRICA ASSURANCE | D5: JUBILEE HEALTH INSURANCE | E5: KENINDIA ASSURANCE COMPANY | F5: KENYA ORIENT INSURANCE | G5: KENYA REINSURANCE CORPORATION | H5: MADISON INSURANCE COMPANY | I5: MAYFAIR INSURANCE COMPANY | J5: MUA INSURANCE COMPANY | K5: NCBA INSURANCE COMPANY | L5: OCCIDENTAL INSURANCE COMPANY | M5: OLD MUTUAL GENERAL INSURANCE
B6: Share Capital | C6: 800000 | D6: 2763720 | E6: 600000 | F6: 810721.06 | G6: 13498981 | H6: 605000 | I6: 1500000 | J6: 600000 | K6: 600000 | L6: 745831 | M6: 1000000
B7: Share Premium | C7: 0 | D7: 0 | E7: 1198.295 | F7: 0 | G7: 0 | H7: 0 | I7: 0 | J7: 0 | K7: 0 | L7: 100378.9 | M7: 0
B8: Revaluation Reserve | C8: 342209.34 | D8: 33523.352 | E8: 456053 | F8: 356.34275 | G8: 36911.31 | H8: 0 | I8: -51662.879 | J8: 0 | K8: 9514.7905 | L8: 0 | M8: 0
B9: Other Equity | C9: 30000 | D9: 0 | E9: 441589.77 | F9: 1644217.3 | G9: 626789.01 | H9: 0 | I9: 213735.07 | J9: 1233590.3 | K9: 0 | L9: 150000 | M9: 0
B10: Retained Earnings | C10: 241971.25 | D10: 2982704.4 | E10: 3304913.3 | F10: -3576928.1 | G10: 23201255 | H10: 584023.1 | I10: 3939650.5 | J10: -2122401.1 | K10: 1702361.3 | L10: -348062.29 | M10: 6158123.9
B11: Other Reserves | C11: 0 | D11: 0 | E11: 0 | F11: 0 | G11: 1513821 | H11: 0 | I11: 631146.7 | J11: 20990.634 | K11: 0 | L11: 0 | M11: 0
B12: Total Equity_x000D_ | C12: 1414180.6 | D12: 5779947.8 | E12: 4803754.4 | F12: -1121633.5 | G12: 38877758 | H12: 1189023.1 | I12: 6232869.4 | J12: -267820.12 | K12: 2311876.1 | L12: 648147.61 | M12: 7158123.9
B13: Insurance Contract Liabilites | C13: 1999942.9 | D13: 5108929.8 | E13: 6197381.5 | F13: 2754118.5 | G13: 11462688 | H13: 6715553.5 | I13: 7421699.9 | J13: 2465268.3 | K13: 2603727.3 | L13: 2154329.6 | M13: 11171668
B14: Reinsurance Contract Liabilites | C14: 10754.805 | D14: 0 | E14: 0 | F14: 0 | G14: 1161513.9 | H14: 0 | I14: 0 | J14: 0 | K14: 675836.33 | L14: 0 | M14: 329572.9
B15: Long-Term Liabilites | C15: 0 | D15: 0 | E15: 54306.604 | F15: 0 | G15: 1419534.4 | H15: 0 | I15: 126893.38 | J15: 0 | K15: 0 | L15: 0 | M15: 0
B16: Short-Term Liabilites | C16: 37375.949 | D16: 165113.46 | E16: 268039.32 | F16: 735918.76 | G16: 764449.3 | H16: 52973.053 | I16: 2009412.4 | J16: 580503.9 | K16: 471434.17 | L16: 479054.8 | M16: 473316.52
B17: Other Liabilites | C17: 66587.708 | D17: 486457.56 | E17: 70595.667 | F17: 83957.799 | G17: 324427.39 | H17: 3314.5374 | I17: 206353.72 | J17: 33940.353 | K17: 203345.74 | L17: 71038.118 | M17: 1425297.3
... B41: Total Assets | C41: 3528841.9 | D41: 11540449 | E41: 11394077 | F41: 2452361.6 | G41: 54010371 | H41: 7960864.2 | I41: 15997229 | J41: 2811892.4 | K41: 6266219.7 | L41: 3352570.2 | M41: 20557978
B42: Amounts in Thousand Shillings | L42: Continued next page

Sheet APPENDIX  5 iv
B3: Continued from previous page
B4: =_xlfn.CONCAT('Table of Contents'!B17,": ",'Table of Contents'!C17) -> APPENDIX 5 iv: SUMMARY OF GENERAL INSURANCE BUSINESS BALANCE SHEETS AS AT 31.12.2025
B5: COMPANY | C5: PACIS INSURANCE COMPANY | D5: PIONEER INSURANCE COMPANY | E5: SANLAM ALLIANZ GENERAL INSURANCE | F5: STAR DISCOVER INSURANCE | G5: TAKAFUL INSURANCE OF AFRICA | H5: TAUSI ASSURANCE COMPANY | I5: THE HERITAGE INSURANCE COMPANY | J5: THE KENYAN ALLIANCE INSURANCE | K5: THE MONARCH INSURANCE | L5: TRIDENT INSURANCE COMPANY | M5: WAICA REINSURANCE KENYA LIMITED | N5: TOTAL | P5: Insurers | Q5: Reinsurers
B6: Share Capital | C6: 688553.91 | D6: 700000 | E6: 6459848 | F6: 675000 | G6: 1239704.3 | H6: 600000 | I6: 1000000 | J6: 600000 | K6: 0 | L6: 0 | M6: 1102550 | N6: 55881334 | P6: =SUMIFS('APPENDIX 5 iv'!$B6:$O6,'APPENDIX 5 iv'!$B$5:$O$5,"*total*")-Q6 -> 38279803 | Q6: =SUMIFS('APPENDIX 5 i'!$B6:$O6,'APPENDIX 5 i'!$B$5:$O$5,"*reinsurance*")+ SUMIFS('APPENDIX 5 ii'!$B6:$O6,'APPENDIX 5 ii'!$B$5:$O$5,"*reinsurance*")+ SUMIFS('APPENDIX 5 iii'!$B6:$O6,'APPENDIX 5 iii'!$B$5:$O$5,"*reinsurance*")+ SUMIFS('APPENDIX 5 iv'!$B6:$O6,'APPENDIX 5 iv'!$B$5:$O$5,"*reinsurance*") -> 17601531
B7: Share Premium_x000D_ | C7: 5712 | D7: 0 | E7: 0 | F7: 0 | G7: 146101 | H7: 0 | I7: 0 | J7: 0 | K7: 0 | L7: 0 | M7: 0 | N7: 1819962.5 | P7: =SUMIFS('APPENDIX 5 iv'!$B7:$O7,'APPENDIX 5 iv'!$B$5:$O$5,"*total*")-Q7 -> 1809091.2 | Q7: =SUMIFS('APPENDIX 5 i'!$B7:$O7,'APPENDIX 5 i'!$B$5:$O$5,"*reinsurance*")+ SUMIFS('APPENDIX 5 ii'!$B7:$O7,'APPENDIX 5 ii'!$B$5:$O$5,"*reinsurance*")+ SUMIFS('APPENDIX 5 iii'!$B7:$O7,'APPENDIX 5 iii'!$B$5:$O$5,"*reinsurance*")+ SUMIFS('APPENDIX 5 iv'!$B7:$O7,'APPENDIX 5 iv'!$B$5:$O$5,"*reinsurance*") -> 10871.242
B8: Revaluation Reserves | C8: 0 | D8: 0 | E8: 0 | F8: 0 | G8: 25539.216 | H8: 206006.19 | I8: 0 | J8: 128382 | K8: 0 | L8: 0 | M8: 0 | N8: 3099555 | P8: =SUMIFS('APPENDIX 5 iv'!$B8:$O8,'APPENDIX 5 iv'!$B$5:$O$5,"*total*")-Q8 -> 2841098.7 | Q8: =SUMIFS('APPENDIX 5 i'!$B8:$O8,'APPENDIX 5 i'!$B$5:$O$5,"*reinsurance*")+ SUMIFS('APPENDIX 5 ii'!$B8:$O8,'APPENDIX 5 ii'!$B$5:$O$5,"*reinsurance*")+ SUMIFS('APPENDIX 5 iii'!$B8:$O8,'APPENDIX 5 iii'!$B$5:$O$5,"*reinsurance*")+ SUMIFS('APPENDIX 5 iv'!$B8:$O8,'APPENDIX 5 iv'!$B$5:$O$5,"*reinsurance*") -> 258456.3
B9: Other Equity | C9: 0 | D9: 0 | E9: 0 | F9: 0 | G9: 0 | H9: 53472.984 | I9: 0 | J9: 0 | K9: 0 | L9: 0 | M9: 0 | N9: 4233667.4 | P9: =SUMIFS('APPENDIX 5 iv'!$B9:$O9,'APPENDIX 5 iv'!$B$5:$O$5,"*total*")-Q9 -> 3606172.9 | Q9: =SUMIFS('APPENDIX 5 i'!$B9:$O9,'APPENDIX 5 i'!$B$5:$O$5,"*reinsurance*")+ SUMIFS('APPENDIX 5 ii'!$B9:$O9,'APPENDIX 5 ii'!$B$5:$O$5,"*reinsurance*")+ SUMIFS('APPENDIX 5 iii'!$B9:$O9,'APPENDIX 5 iii'!$B$5:$O$5,"*reinsurance*")+ SUMIFS('APPENDIX 5 iv'!$B9:$O9,'APPENDIX 5 iv'!$B$5:$O$5,"*reinsurance*") -> 627494.57
B10: Retained Earnings | C10: 348914.81 | D10: 213711.94 | E10: -2850363.1 | F10: 30896.77 | G10: -507346.63 | H10: 2291382 | I10: 4336725.4 | J10: -1337669.2 | K10: 0 | L10: 0 | M10: 2166084.2 | N10: 79539070 | P10: =SUMIFS('APPENDIX 5 iv'!$B10:$O10,'APPENDIX 5 iv'!$B$5:$O$5,"*total*")-Q10 -> 45890151 | Q10: =SUMIFS('APPENDIX 5 i'!$B10:$O10,'APPENDIX 5 i'!$B$5:$O$5,"*reinsurance*")+ SUMIFS('APPENDIX 5 ii'!$B10:$O10,'APPENDIX 5 ii'!$B$5:$O$5,"*reinsurance*")+ SUMIFS('APPENDIX 5 iii'!$B10:$O10,'APPENDIX 5 iii'!$B$5:$O$5,"*reinsurance*")+ SUMIFS('APPENDIX 5 iv'!$B10:$O10,'APPENDIX 5 iv'!$B$5:$O$5,"*reinsurance*") -> 33648918
B11: Other Reserves | C11: 24798.639 | D11: 1031184.4 | E11: 0 | F11: 0 | G11: 0 | H11: 0 | I11: 0 | J11: -15557.495 | K11: 0 | L11: 0 | M11: 0 | N11: 4035439.5 | P11: =SUMIFS('APPENDIX 5 iv'!$B11:$O11,'APPENDIX 5 iv'!$B$5:$O$5,"*total*")-Q11 -> 2613743.9 | Q11: =SUMIFS('APPENDIX 5 i'!$B11:$O11,'APPENDIX 5 i'!$B$5:$O$5,"*reinsurance*")+ SUMIFS('APPENDIX 5 ii'!$B11:$O11,'APPENDIX 5 ii'!$B$5:$O$5,"*reinsurance*")+ SUMIFS('APPENDIX 5 iii'!$B11:$O11,'APPENDIX 5 iii'!$B$5:$O$5,"*reinsurance*")+ SUMIFS('APPENDIX 5 iv'!$B11:$O11,'APPENDIX 5 iv'!$B$5:$O$5,"*reinsurance*") -> 1421695.6
B12: Total Equity_x000D_ | C12: 1067979.4 | D12: 1944896.4 | E12: 3609484.9 | F12: 705896.77 | G12: 903997.86 | H12: 3150861.2 | I12: 5336725.4 | J12: -624844.74 | K12: 0 | L12: 0 | M12: 3268634.2 | N12: 1.4860903e+08 | P12: =SUMIFS('APPENDIX 5 iv'!$B12:$O12,'APPENDIX 5 iv'!$B$5:$O$5,"*total*")-Q12 -> 95040061 | Q12: =SUMIFS('APPENDIX 5 i'!$B12:$O12,'APPENDIX 5 i'!$B$5:$O$5,"*reinsurance*")+ SUMIFS('APPENDIX 5 ii'!$B12:$O12,'APPENDIX 5 ii'!$B$5:$O$5,"*reinsurance*")+ SUMIFS('APPENDIX 5 iii'!$B12:$O12,'APPENDIX 5 iii'!$B$5:$O$5,"*reinsurance*")+ SUMIFS('APPENDIX 5 iv'!$B12:$O12,'APPENDIX 5 iv'!$B$5:$O$5,"*reinsurance*") -> 53568968
B13: Insurance Contract Liabilites | C13: 2923192.1 | D13: 2181593.5 | E13: 10322094 | F13: 345901.35 | G13: 1022158.3 | H13: 1176654.7 | I13: 6184587.2 | J13: 1175089.8 | K13: 0 | L13: 0 | M13: 2171274.1 | N13: 1.910736e+08 | P13: =SUMIFS('APPENDIX 5 iv'!$B13:$O13,'APPENDIX 5 iv'!$B$5:$O$5,"*total*")-Q13 -> 1.6796115e+08 | Q13: =SUMIFS('APPENDIX 5 i'!$B13:$O13,'APPENDIX 5 i'!$B$5:$O$5,"*reinsurance*")+ SUMIFS('APPENDIX 5 ii'!$B13:$O13,'APPENDIX 5 ii'!$B$5:$O$5,"*reinsurance*")+ SUMIFS('APPENDIX 5 iii'!$B13:$O13,'APPENDIX 5 iii'!$B$5:$O$5,"*reinsurance*")+ SUMIFS('APPENDIX 5 iv'!$B13:$O13,'APPENDIX 5 iv'!$B$5:$O$5,"*reinsurance*") -> 23112454
B14: Reinsurance Contract Liabilites | C14: 0 | D14: 0 | E14: 123395.9 | F14: 0 | G14: 77.224395 | H14: 0 | I14: 0 | J14: 23191.565 | K14: 0 | L14: 0 | M14: 352695.53 | N14: 5131140.3 | P14: =SUMIFS('APPENDIX 5 iv'!$B14:$O14,'APPENDIX 5 iv'!$B$5:$O$5,"*total*")-Q14 -> 3481549.9 | Q14: =SUMIFS('APPENDIX 5 i'!$B14:$O14,'APPENDIX 5 i'!$B$5:$O$5,"*reinsurance*")+ SUMIFS('APPENDIX 5 ii'!$B14:$O14,'APPENDIX 5 ii'!$B$5:$O$5,"*reinsurance*")+ SUMIFS('APPENDIX 5 iii'!$B14:$O14,'APPENDIX 5 iii'!$B$5:$O$5,"*reinsurance*")+ SUMIFS('APPENDIX 5 iv'!$B14:$O14,'APPENDIX 5 iv'!$B$5:$O$5,"*reinsurance*") -> 1649590.4
B15: Long-Term Liabilites | C15: 37385.016 | D15: 0 | E15: 0 | F15: 6698.482 | G15: 11988 | H15: 75328.124 | I15: 38586.533 | J15: 119413.41 | K15: 0 | L15: 0 | M15: 0 | N15: 2961125.2 | P15: =SUMIFS('APPENDIX 5 iv'!$B15:$O15,'APPENDIX 5 iv'!$B$5:$O$5,"*total*")-Q15 -> 1541590.8 | Q15: =SUMIFS('APPENDIX 5 i'!$B15:$O15,'APPENDIX 5 i'!$B$5:$O$5,"*reinsurance*")+ SUMIFS('APPENDIX 5 ii'!$B15:$O15,'APPENDIX 5 ii'!$B$5:$O$5,"*reinsurance*")+ SUMIFS('APPENDIX 5 iii'!$B15:$O15,'APPENDIX 5 iii'!$B$5:$O$5,"*reinsurance*")+ SUMIFS('APPENDIX 5 iv'!$B15:$O15,'APPENDIX 5 iv'!$B$5:$O$5,"*reinsurance*") -> 1419534.4
B16: Short-Term Liabilites | C16: 293944.99 | D16: 33239.479 | E16: 769886.48 | F16: 281631.94 | G16: 9032.383 | H16: 87501.419 | I16: 1006630.9 | J16: 1536950.7 | K16: 0 | L16: 0 | M16: 146147.38 | N16: 16369390 | P16: =SUMIFS('APPENDIX 5 iv'!$B16:$O16,'APPENDIX 5 iv'!$B$5:$O$5,"*total*")-Q16 -> 14857603 | Q16: =SUMIFS('APPENDIX 5 i'!$B16:$O16,'APPENDIX 5 i'!$B$5:$O$5,"*reinsurance*")+ SUMIFS('APPENDIX 5 ii'!$B16:$O16,'APPENDIX 5 ii'!$B$5:$O$5,"*reinsurance*")+ SUMIFS('APPENDIX 5 iii'!$B16:$O16,'APPENDIX 5 iii'!$B$5:$O$5,"*reinsurance*")+ SUMIFS('APPENDIX 5 iv'!$B16:$O16,'APPENDIX 5 iv'!$B$5:$O$5,"*reinsurance*") -> 1511786.6
B17: Other Liabilites | C17: 78702.861 | D17: 132981.77 | E17: 182069.33 | F17: 212250.35 | G17: 64265 | H17: 27477.418 | I17: 414356.06 | J17: 56147.649 | K17: 0 | L17: 0 | M17: 23030.269 | N17: 8045099.5 | P17: =SUMIFS('APPENDIX 5 iv'!$B17:$O17,'APPENDIX 5 iv'!$B$5:$O$5,"*total*")-Q17 -> 7486610.5 | Q17: =SUMIFS('APPENDIX 5 i'!$B17:$O17,'APPENDIX 5 i'!$B$5:$O$5,"*reinsurance*")+ SUMIFS('APPENDIX 5 ii'!$B17:$O17,'APPENDIX 5 ii'!$B$5:$O$5,"*reinsurance*")+ SUMIFS('APPENDIX 5 iii'!$B17:$O17,'APPENDIX 5 iii'!$B$5:$O$5,"*reinsurance*")+ SUMIFS('APPENDIX 5 iv'!$B17:$O17,'APPENDIX 5 iv'!$B$5:$O$5,"*reinsurance*") -> 558489
... B41: Total Assets | C41: 4401204.4 | D41: 4292711.2 | E41: 15006930 | F41: 1552378.9 | G41: 2011518.7 | H41: 4517822.8 | I41: 12980886 | J41: 2285948.5 | K41: 0 | L41: 0 | M41: 5961781.5 | N41: 3.7218946e+08 | P41: =SUMIFS('APPENDIX 5 iv'!$B41:$O41,'APPENDIX 5 iv'!$B$5:$O$5,"*total*")-Q41 -> 2.9036856e+08 | Q41: =SUMIFS('APPENDIX 5 i'!$B41:$O41,'APPENDIX 5 i'!$B$5:$O$5,"*reinsurance*")+ SUMIFS('APPENDIX 5 ii'!$B41:$O41,'APPENDIX 5 ii'!$B$5:$O$5,"*reinsurance*")+ SUMIFS('APPENDIX 5 iii'!$B41:$O41,'APPENDIX 5 iii'!$B$5:$O$5,"*reinsurance*")+ SUMIFS('APPENDIX 5 iv'!$B41:$O41,'APPENDIX 5 iv'!$B$5:$O$5,"*reinsurance*") -> 81820896
B42: Amounts in thousand Shillings

Sheet APPENDIX 6
B4: =_xlfn.CONCAT('Table of Contents'!B18,": ",'Table of Contents'!C18) -> APPENDIX 6: SUMMARY OF MICRO INSURANCE BUSINESS BALANCE SHEETS AS AT 31.12.2025
B5: COMPANY | C5: APA MICRO INSURANCE | D5: BIRDVIEW MICRO INSURANCE | E5: BRITAM MICRO INSURANCE | F5: CIC MICRO INSURANCE | G5: STAR DISCOVER MICRO INSURANCE | H5: TURACO MICRO INSURANCE | I5: TOTAL
B6: Share Capital | C6: 0 | D6: 50000 | E6: 150000 | F6: 50000 | G6: 100000 | H6: 50000 | I6: 400000
B7: Share Premium_x000D_ | C7: 0 | D7: 0 | E7: 0 | F7: 0 | G7: 0 | H7: 0 | I7: 0
B8: Revaluation Reserves | C8: 0 | D8: 0 | E8: 0 | F8: 0 | G8: 0 | H8: 0 | I8: 0
B9: Other Equity | C9: 0 | D9: 30000 | E9: 0 | F9: 0 | G9: 0 | H9: 0 | I9: 30000
B10: Retained Earnings | C10: 0 | D10: -34121.477 | E10: -2441.7778 | F10: -19450.436 | G10: -53556.462 | H10: 61566.036 | I10: -48004.117
