Workbook
Name Appendix_1_Range: 'APPENDIX 1'!$B$3:$R$51
Name Appendix_10_Range: 'APPENDIX 10'!$B$3:$Q$37
Name Appendix_11_Range: 'APPENDIX 11'!$B$3:$Q$37
Name Appendix_12_Range: 'APPENDIX 12'!$B$3:$Q$37
Name Appendix_13_Range: 'APPENDIX 13'!$B$3:$Q$37
Name Appendix_14_Range: 'APPENDIX 14'!$B$3:$Q$37
Name Appendix_15_Range: 'APPENDIX 15'!$B$3:$R$50
Name Appendix_16_Range: 'APPENDIX 16'!$B$3:$Q$50
Name Appendix_17_Range: 'APPENDIX 17'!$B$3:$Q$50
Name Appendix_18_Range: 'APPENDIX 18'!$B$3:$Q$50
Name Appendix_19_Range: 'APPENDIX 19'!$B$3:$Q$50
Name Appendix_2_Range: 'APPENDIX 2'!$B$3:$R$38
Name Appendix_20_Range: 'APPENDIX 20'!$B$3:$Q$50
Name Appendix_21_Range: 'APPENDIX 21'!$B$3:$Q$50
Name Appendix_22_Range: 'APPENDIX 22'!$B$3:$G$24
Name Appendix_23_Range: 'APPENDIX 23Micro'!$B$3:$F$13
Name Appendix_24_Range: 'APPENDIX 24Micro'!$B$3:$F$13
Name Appendix_25_Range: 'APPENDIX 25Micro'!$B$3:$F$13
Name Appendix_26_Range: 'APPENDIX 26Micro'!$B$3:$F$13
Name Appendix_27_Range: 'APPENDIX 27Micro'!$B$3:$F$13
Name Appendix_28_Range: 'APPENDIX 23'!$B$3:$Q$13
Name Appendix_29i_Range: 'APPENDIX 24 i'!$B$4:$L$44
Name Appendix_29ii_Range: 'APPENDIX 24 ii'!$B$3:$L$44
Name Appendix_29iii_Range: 'APPENDIX 24 iii'!$B$3:$K$44
Name Appendix_3_Range: 'APPENDIX 3'!$B$3:$R$12
Name Appendix_30i_Range: 'APPENDIX 25 i'!$B$4:$L$42
Name Appendix_30ii_Range: 'APPENDIX 25 ii'!$B$3:$L$42
Name Appendix_30iii_Range: 'APPENDIX 25 iii'!$B$3:$L$42
Name Appendix_30iv_Range: 'APPENDIX 25 iv'!$B$3:$N$42
Name Appendix_31i_Range: 'APPENDIX 26 i'!$B$4:$I$42
Name Appendix_4_Range: 'APPENDIX 4'!$B$3:$L$37
Name Appendix_5_Range: 'APPENDIX 5'!$B$3:$K$37
Name Appendix_6_Range: 'APPENDIX 6'!$B$3:$Q$37
Name Appendix_7_Range: 'APPENDIX 7'!$B$3:$Q$37
Name Appendix_8_Range: 'APPENDIX 8'!$B$3:$Q$37
Name Appendix_9_Range: 'APPENDIX 9'!$B$3:$Q$37
Name Details_Range: Details!$C$2:$J$21

Sheet Details
E6: INSURANCE REGULATORY AUTHORITY
E11: TYPE OF INDUSTRY STATISTICS | F11: Quarterly (Unaudited)
E13: QUARTER | F13: 1
E15: YEAR | F15: 2025
E18: PERIOD ENDED | F18: 31.03.2025

Sheet Reliance & Limitations
B3: RELIANCE AND LIMITATIONS
B4: The insurance information contained in this workbook has been extracted from the quarterly unaudited returns submitted to the Authority in line with Section 54 of the Insurance Act. No adjustments have been made to the returns’ data except where necessary in consultation with the affected insurer(s) or reinsurer(s). The publication of any summary of the returns in this report does not necessarily mean that the returns so summarized have satisfied all the requirements of the Insurance Act, or that the Commissioner of Insurance approves the accuracy or the contents of the returns Where necessary, figures have been adjusted to eliminate errors in totals due to rounding off, and are given in thousands Kenya shillings (‘000’ KES) except where otherwise stated. The report incorporates data from all insurers and reinsurers except for Jubilee Allianz General Insurance Limited, Invesco Assurance Company and Corporate Insurance Company Limited-Life due to non-submission of 2024 Q2 unaudited returns.

Sheet Table of Contents
B3: INSURANCE REGULATORY AUTHORITY
B5: 2025 QUARTER ONE STATISTICS
B6: TABLE OF CONTENTS
B7: Link | C7: Description
B8: APPENDIX 1 | C8: =_xlfn.CONCAT("SUMMARY OF GENERAL INSURANCE BUSINESS PROFIT & LOSS ACCOUNTS FOR THE PERIOD ENDED"," ",Details!F18) -> SUMMARY OF GENERAL INSURANCE BUSINESS PROFIT & LOSS ACCOUNTS FOR THE PERIOD ENDED 31.03.2025
B9: APPENDIX 2 | C9: =_xlfn.CONCAT("SUMMARY OF LONG TERM INSURANCE BUSINESS PROFIT & LOSS ACCOUNTS FOR THE PERIOD ENDED"," ",Details!$F$18) -> SUMMARY OF LONG TERM INSURANCE BUSINESS PROFIT & LOSS ACCOUNTS FOR THE PERIOD ENDED 31.03.2025
B10: APPENDIX 3 | C10: =_xlfn.CONCAT("SUMMARY OF MICRO INSURANCE BUSINESS PROFIT & LOSS ACCOUNTS FOR THE PERIOD ENDED"," ",Details!$F$18) -> SUMMARY OF MICRO INSURANCE BUSINESS PROFIT & LOSS ACCOUNTS FOR THE PERIOD ENDED 31.03.2025
B11: APPENDIX 4 | C11: =_xlfn.CONCAT("SUMMARY OF LONG TERM INSURANCE BUSINESS GROSS PREMIUM INCOME FOR THE PERIOD ENDED"," ",Details!F18) -> SUMMARY OF LONG TERM INSURANCE BUSINESS GROSS PREMIUM INCOME FOR THE PERIOD ENDED 31.03.2025
B12: APPENDIX 5 | C12: =_xlfn.CONCAT("SUMMARY OF LONG TERM INSURANCE BUSINESS MARKET SHARE PER CLASS FOR THE PERIOD ENDED"," ",Details!F18) -> SUMMARY OF LONG TERM INSURANCE BUSINESS MARKET SHARE PER CLASS FOR THE PERIOD ENDED 31.03.2025
B13: APPENDIX 6 | C13: =_xlfn.CONCAT("SUMMARY OF LIFE ASSURANCE BUSINESS REVENUE ACCOUNTS FOR THE PERIOD ENDED"," ",Details!F18) -> SUMMARY OF LIFE ASSURANCE BUSINESS REVENUE ACCOUNTS FOR THE PERIOD ENDED 31.03.2025
B14: APPENDIX 7 | C14: =_xlfn.CONCAT("SUMMARY OF ANNUITIES BUSINESS REVENUE ACCOUNTS FOR THE PERIOD ENDED"," ",Details!F18) -> SUMMARY OF ANNUITIES BUSINESS REVENUE ACCOUNTS FOR THE PERIOD ENDED 31.03.2025
B15: APPENDIX 8 | C15: =_xlfn.CONCAT("SUMMARY OF GROUP LIFE BUSINESS REVENUE ACCOUNTS FOR THE PERIOD ENDED"," ",Details!F18) -> SUMMARY OF GROUP LIFE BUSINESS REVENUE ACCOUNTS FOR THE PERIOD ENDED 31.03.2025
B16: APPENDIX 9 | C16: =_xlfn.CONCAT("SUMMARY OF GROUP CREDIT BUSINESS REVENUE ACCOUNTS FOR THE PERIOD ENDED"," ",Details!F18) -> SUMMARY OF GROUP CREDIT BUSINESS REVENUE ACCOUNTS FOR THE PERIOD ENDED 31.03.2025
B17: APPENDIX 10 | C17: =_xlfn.CONCAT("SUMMARY OF INVESTMENTS BUSINESS REVENUE ACCOUNTS FOR THE PERIOD ENDED"," ",Details!F18) -> SUMMARY OF INVESTMENTS BUSINESS REVENUE ACCOUNTS FOR THE PERIOD ENDED 31.03.2025
B18: APPENDIX 11 | C18: =_xlfn.CONCAT("SUMMARY OF PERMANENT HEALTH BUSINESS REVENUE ACCOUNTS FOR THE PERIOD ENDED"," ",Details!F18) -> SUMMARY OF PERMANENT HEALTH BUSINESS REVENUE ACCOUNTS FOR THE PERIOD ENDED 31.03.2025
B19: APPENDIX 12 | C19: =_xlfn.CONCAT("SUMMARY OF PERSONAL PENSIONS BUSINESS REVENUE ACCOUNTS FOR THE PERIOD ENDED"," ",Details!F18) -> SUMMARY OF PERSONAL PENSIONS BUSINESS REVENUE ACCOUNTS FOR THE PERIOD ENDED 31.03.2025
B20: APPENDIX 13 | C20: =_xlfn.CONCAT("SUMMARY OF DEPOSIT ADMINISTRATION BUSINESS REVENUE ACCOUNTS FOR THE PERIOD ENDED"," ",Details!F18) -> SUMMARY OF DEPOSIT ADMINISTRATION BUSINESS REVENUE ACCOUNTS FOR THE PERIOD ENDED 31.03.2025
B21: APPENDIX 14 | C21: =_xlfn.CONCAT("SUMMARY OF COMBINED LONG TERM BUSINESS REVENUE ACCOUNTS FOR THE PERIOD ENDED"," ",Details!F18) -> SUMMARY OF COMBINED LONG TERM BUSINESS REVENUE ACCOUNTS FOR THE PERIOD ENDED 31.03.2025
B22: APPENDIX 15 | C22: =_xlfn.CONCAT("SUMMARY OF GROSS PREMIUM INCOME UNDER GENERAL INSURANCE BUSINESS FOR THE PERIOD ENDED"," ",Details!$F$18) -> SUMMARY OF GROSS PREMIUM INCOME UNDER GENERAL INSURANCE BUSINESS FOR THE PERIOD ENDED 31.03.2025
B23: APPENDIX 16 | C23: =_xlfn.CONCAT("SUMMARY OF GENERAL INSURANCE BUSINESS MARKET SHARE PER CLASS FOR THE PERIOD ENDED"," ",Details!$F$18) -> SUMMARY OF GENERAL INSURANCE BUSINESS MARKET SHARE PER CLASS FOR THE PERIOD ENDED 31.03.2025
B24: APPENDIX 17 | C24: =_xlfn.CONCAT("SUMMARY OF CLAIMS PAID UNDER GENERAL INSURANCE BUSINESS FOR THE PERIOD ENDED"," ",Details!$F$18) -> SUMMARY OF CLAIMS PAID UNDER GENERAL INSURANCE BUSINESS FOR THE PERIOD ENDED 31.03.2025
B25: APPENDIX 18 | C25: =_xlfn.CONCAT("SUMMARY OF CLAIMS INCURRED UNDER GENERAL INSURANCE BUSINESS FOR THE PERIOD ENDED"," ",Details!$F$18) -> SUMMARY OF CLAIMS INCURRED UNDER GENERAL INSURANCE BUSINESS FOR THE PERIOD ENDED 31.03.2025
B26: APPENDIX 19 | C26: =_xlfn.CONCAT("SUMMARY OF INCURRED CLAIMS RATIOS UNDER GENERAL INSURANCE BUSINESS FOR THE PERIOD ENDED"," ",Details!$F$18) -> SUMMARY OF INCURRED CLAIMS RATIOS UNDER GENERAL INSURANCE BUSINESS FOR THE PERIOD ENDED 31.03.2025
B27: APPENDIX 20 | C27: =_xlfn.CONCAT("SUMMARY OF UNDERWRITING PROFITS UNDER GENERAL INSURANCE BUSINESS FOR THE PERIOD ENDED"," ",Details!$F$18) -> SUMMARY OF UNDERWRITING PROFITS UNDER GENERAL INSURANCE BUSINESS FOR THE PERIOD ENDED 31.03.2025
B28: APPENDIX 21 | C28: =_xlfn.CONCAT("SUMMARY OF GENERAL INSURANCE BUSINESS REVENUE ACCOUNTS FOR THE PERIOD ENDED"," ",Details!$F$18) -> SUMMARY OF GENERAL INSURANCE BUSINESS REVENUE ACCOUNTS FOR THE PERIOD ENDED 31.03.2025
B29: APPENDIX 22 | C29: =_xlfn.CONCAT("SUMMARY OF MICRO INSURANCE BUSINESS REVENUE ACCOUNT RESULTS FOR THE PERIOD ENDED"," ",Details!$F$18) -> SUMMARY OF MICRO INSURANCE BUSINESS REVENUE ACCOUNT RESULTS FOR THE PERIOD ENDED 31.03.2025
B30: APPENDIX 23Micro | C30: =_xlfn.CONCAT("SUMMARY OF MICRO INSURANCE BUSINESS MARKET SHARE PER CLASS FOR THE PERIOD ENDED"," ",Details!$F$18) -> SUMMARY OF MICRO INSURANCE BUSINESS MARKET SHARE PER CLASS FOR THE PERIOD ENDED 31.03.2025
B31: APPENDIX 24Micro | C31: =_xlfn.CONCAT("SUMMARY OF CLAIMS PAID UNDER MICRO INSURANCE BUSINESS FOR THE PERIOD ENDED"," ",Details!$F$18) -> SUMMARY OF CLAIMS PAID UNDER MICRO INSURANCE BUSINESS FOR THE PERIOD ENDED 31.03.2025
B32: APPENDIX 25Micro | C32: =_xlfn.CONCAT("SUMMARY OF CLAIMS INCURRED UNDER MICRO INSURANCE BUSINESS FOR THE PERIOD ENDED"," ",Details!$F$18) -> SUMMARY OF CLAIMS INCURRED UNDER MICRO INSURANCE BUSINESS FOR THE PERIOD ENDED 31.03.2025
B33: APPENDIX 26Micro | C33: =_xlfn.CONCAT("SUMMARY OF INCURRED CLAIMS RATIOS UNDER MICRO INSURANCE BUSINESS FOR THE PERIOD ENDED"," ",Details!$F$18) -> SUMMARY OF INCURRED CLAIMS RATIOS UNDER MICRO INSURANCE BUSINESS FOR THE PERIOD ENDED 31.03.2025
B34: APPENDIX 27Micro | C34: =_xlfn.CONCAT("SUMMARY OF UNDERWRITING PROFITS UNDER MICRO INSURANCE BUSINESS FOR THE PERIOD ENDED"," ",Details!$F$18) -> SUMMARY OF UNDERWRITING PROFITS UNDER MICRO INSURANCE BUSINESS FOR THE PERIOD ENDED 31.03.2025
B35: APPENDIX 23 | C35: =_xlfn.CONCAT("SUMMARY OF COMBINED MICRO INSURANCE BUSINESS REVENUE ACCOUNTS FOR THE PERIOD ENDED"," ",Details!F18) -> SUMMARY OF COMBINED MICRO INSURANCE BUSINESS REVENUE ACCOUNTS FOR THE PERIOD ENDED 31.03.2025
B36: APPENDIX 24 i | C36: =_xlfn.CONCAT("SUMMARY OF LONG TERM INSURANCE BUSINESS BALANCE SHEETS AS AT"," ",Details!F18) -> SUMMARY OF LONG TERM INSURANCE BUSINESS BALANCE SHEETS AS AT 31.03.2025
B37: APPENDIX 24 ii | C37: =_xlfn.CONCAT("SUMMARY OF LONG TERM INSURANCE BUSINESS BALANCE SHEETS AS AT"," ",Details!F18) -> SUMMARY OF LONG TERM INSURANCE BUSINESS BALANCE SHEETS AS AT 31.03.2025
B38: APPENDIX 24 iii | C38: =_xlfn.CONCAT("SUMMARY OF LONG TERM INSURANCE BUSINESS BALANCE SHEETS AS AT"," ",Details!F18) -> SUMMARY OF LONG TERM INSURANCE BUSINESS BALANCE SHEETS AS AT 31.03.2025
B39: APPENDIX 25 i | C39: =_xlfn.CONCAT("SUMMARY OF GENERAL INSURANCE BUSINESS BALANCE SHEETS AS AT"," ",Details!F18) -> SUMMARY OF GENERAL INSURANCE BUSINESS BALANCE SHEETS AS AT 31.03.2025
B40: APPENDIX 25 ii | C40: =_xlfn.CONCAT("SUMMARY OF GENERAL INSURANCE BUSINESS BALANCE SHEETS AS AT"," ",Details!F18) -> SUMMARY OF GENERAL INSURANCE BUSINESS BALANCE SHEETS AS AT 31.03.2025
B41: APPENDIX 25 iii | C41: =_xlfn.CONCAT("SUMMARY OF GENERAL INSURANCE BUSINESS BALANCE SHEETS AS AT"," ",Details!F18) -> SUMMARY OF GENERAL INSURANCE BUSINESS BALANCE SHEETS AS AT 31.03.2025
B42: APPENDIX 25 iv | C42: =_xlfn.CONCAT("SUMMARY OF GENERAL INSURANCE BUSINESS BALANCE SHEETS AS AT"," ",Details!F18) -> SUMMARY OF GENERAL INSURANCE BUSINESS BALANCE SHEETS AS AT 31.03.2025
B43: APPENDIX 26 i | C43: =_xlfn.CONCAT("SUMMARY OF MICRO INSURANCE BUSINESS BALANCE SHEETS AS AT"," ",Details!F18) -> SUMMARY OF MICRO INSURANCE BUSINESS BALANCE SHEETS AS AT 31.03.2025

Sheet APPENDIX 1
B3: =_xlfn.CONCAT('Table of Contents'!B8,": ",'Table of Contents'!C8) -> APPENDIX 1: SUMMARY OF GENERAL INSURANCE BUSINESS PROFIT & LOSS ACCOUNTS FOR THE PERIOD ENDED 31.03.2025
B4: Company | C4: Insurance Revenue | D4: Insurance Service Expense | E4: Net expenses from reinsurance contracts held | F4: Insurance Service Result | G4: Net Investment Income | H4: Finance expenses from insurance contracts | I4: Finance income from reinsurance contracts | J4: Net Financial Result | K4: Asset management services revenue | L4: Other Income | M4: Other finance costs | N4: Other operating expenses | O4: Share of profit of associates and joint ventures accounted for using the equity method | P4: Profit before income tax | Q4: Income tax expense | R4: Profit for the year
B5: INSURERS
B6: AAR INSURANCE KENYA | C6: 2767250 | D6: 2590990.5 | E6: 46409.727 | F6: 129849.81 | G6: 202123.65 | H6: 0 | I6: 0 | J6: 202123.65 | K6: 0 | L6: -1758.9654 | M6: 8583.0165 | N6: 148456.18 | O6: 0 | P6: 173175.3 | Q6: 0 | R6: 173175.3
B7: AFRICAN MERCHANT ASSURANCE | C7: 1079878.6 | D7: 869225.06 | E7: -11322.627 | F7: 221976.21 | G7: 31980 | H7: 62997.283 | I7: 7811.7527 | J7: -23205.53 | K7: 0 | L7: 0 | M7: 0 | N7: 130182.43 | O7: 0 | P7: 68588.254 | Q7: 0 | R7: 68588.254
B8: APA INSURANCE COMPANY | C8: 4372412.9 | D8: 3692799.7 | E8: 485219.7 | F8: 194393.48 | G8: 479526.05 | H8: 531144.71 | I8: 289726.87 | J8: 238108.21 | K8: 0 | L8: 0 | M8: 7261.4703 | N8: 88669.94 | O8: 0 | P8: 336570.29 | Q8: -17596.639 | R8: 354166.92
B9: BRITAM GENERAL INSURANCE | C9: 3951116.3 | D9: 3033554.2 | E9: 814691.46 | F9: 102870.7 | G9: 508908.73 | H9: 445718.98 | I9: 219527.93 | J9: 282717.67 | K9: 0 | L9: 8308.3264 | M9: 8704.1132 | N9: 93579.844 | O9: 0 | P9: 291612.74 | Q9: 0 | R9: 291612.74
B10: CANNON GENERAL INSURANCE (K) LIMITED | C10: 514448.92 | D10: 484901.3 | E10: 41414.308 | F10: -11866.687 | G10: 26549.271 | H10: 111612.1 | I10: 66305.029 | J10: -18757.803 | K10: 0 | L10: 0 | M10: 0 | N10: 47179.337 | O10: 0 | P10: -77803.827 | Q10: 0 | R10: -77803.827
B11: CIC GENERAL INSURANCE COMPANY | C11: 4394571.9 | D11: 3823921.2 | E11: 506033.61 | F11: 64617.114 | G11: 280735.3 | H11: 201066.73 | I11: 53258.674 | J11: 132927.25 | K11: 0 | L11: 64678.522 | M11: 0 | N11: 91658.724 | O11: 0 | P11: 170564.16 | Q11: 51169.249 | R11: 119394.91
B12: CORPORATE INSURANCE COMPANY | C12: 42952.314 | D12: -33854.017 | E12: 16177.318 | F12: 60629.013 | G12: 5746.453 | H12: 76899.083 | I12: 27687.468 | J12: -43465.162 | K12: 0 | L12: 0 | M12: 0 | N12: 25755.381 | O12: 0 | P12: -8591.5299 | Q12: 0 | R12: -8591.5299
B13: DEFINITE ASSURANCE COMPANY | C13: 25256.267 | D13: 21152.995 | E13: 477.41787 | F13: 3625.8544 | G13: 0 | H13: 0 | I13: 0 | J13: 0 | K13: 0 | L13: 0 | M13: 0 | N13: 0 | O13: 0 | P13: 3625.8544 | Q13: 0 | R13: 3625.8544
B14: DIRECTLINE ASSURANCE COMPANY | C14: 717147.63 | D14: 761039.08 | E14: 15745.425 | F14: -59636.87 | G14: 71430.841 | H14: 762416.41 | I14: 0 | J14: -690985.57 | K14: 0 | L14: 0 | M14: 0 | N14: 7500.808 | O14: 0 | P14: -758123.24 | Q14: 0 | R14: -758123.24
B15: EQUITY GENERAL INSURANCE LIMITED | C15: 280504.69 | D15: 319216.16 | E15: 19295.15 | F15: -58006.614 | G15: 29819.8 | H15: 0 | I15: 0 | J15: 29819.8 | K15: 0 | L15: 0 | M15: 0 | N15: 0 | O15: 0 | P15: -28186.814 | Q15: -8456.0442 | R15: -19730.77
B16: FIDELITY SHIELD INSURANCE | C16: 1074606.7 | D16: 929812.61 | E16: 193359.03 | F16: -48564.917 | G16: 128890.2 | H16: 46838.872 | I16: 8079.5037 | J16: 90130.836 | K16: 0 | L16: 14707.181 | M16: 0 | N16: 46489.123 | O16: 0 | P16: 9783.9779 | Q16: 0 | R16: 9783.9779
B17: FIRST ASSURANCE COMPANY | C17: 1679272.8 | D17: 1558410.2 | E17: 107490.29 | F17: 13372.4 | G17: 89512.957 | H17: -89215.97 | I17: -35054.097 | J17: 143674.83 | K17: 0 | L17: 0 | M17: 0 | N17: 87023.79 | O17: 0 | P17: 70023.439 | Q17: 21216 | R17: 48807.439
... B41: TRIDENT INSURANCE COMPANY | C41: 0 | D41: 0 | E41: 0 | F41: 0 | G41: 0 | H41: 0 | I41: 0 | J41: 0 | K41: 0 | L41: 0 | M41: 0 | N41: 0 | O41: 0 | P41: 0 | Q41: 0 | R41: 0
B42: TOTAL | C42: =SUM(C6:C41) -> 51594233 | D42: =SUM(D6:D41) -> 42921946 | E42: =SUM(E6:E41) -> 5987188.9 | F42: =SUM(F6:F41) -> 2685098.1 | G42: =SUM(G6:G41) -> 4579029.8 | H42: =SUM(H6:H41) -> 4214617.6 | I42: =SUM(I6:I41) -> 1277381.2 | J42: =SUM(J6:J41) -> 1641793.5 | ... R42: =SUM(R6:R41) -> 1810141.2
B43: REINSURERS
B44: CONTINENTAL REINSURANCE | C44: 1498541 | D44: 1460000.5 | E44: -80030.113 | F44: 118570.66 | G44: 61370.513 | H44: 155208.27 | I44: 62790.039 | J44: -31047.721 | K44: 0 | L44: 11022.149 | M44: 810.181 | N44: 6633.212 | O44: 0 | P44: 91101.699 | Q44: 27330.509 | R44: 63771.19
B45: EAST AFRICA REINSURANCE | C45: 1513009.7 | D45: 1297891.5 | E45: 123540.01 | F45: 91578.181 | G45: 169797.46 | H45: 42543.38 | I45: 8144.1956 | J45: 135398.27 | K45: 0 | L45: 0 | M45: 0 | N45: 3488.565 | O45: 0 | P45: 223487.89 | Q45: 55871.971 | R45: 167615.92
B46: GHANA REINSURANCE COMPANY | C46: 915568.14 | D46: 798999.17 | E46: 73348.869 | F46: 43220.1 | G46: 59297.68 | H46: 44096.781 | I46: 9334.2695 | J46: 24535.168 | K46: 0 | L46: 0 | M46: -6444.1883 | N46: 51366.221 | O46: 0 | P46: 22833.235 | Q46: 0 | R46: 22833.235
B47: KENYA REINSURANCE CORPORATION | C47: 2634223.2 | D47: 2837322.2 | E47: 173645.88 | F47: -376744.86 | G47: 1133012.2 | H47: -82747.898 | I47: 12356.061 | J47: 1228116.1 | K47: 0 | L47: 9605.024 | M47: -1895.489 | N47: 403490.64 | O47: 0 | P47: 459381.16 | Q47: 137814.35 | R47: 321566.81
B48: WAICA REINSURANCE KENYA LIMITED | C48: 1635403.3 | D48: 1008390 | E48: 271727.44 | F48: 355285.84 | G48: 89004.18 | H48: 122950.7 | I48: 13091.25 | J48: -20855.268 | K48: 0 | L48: 2070.5998 | M48: 0 | N48: 154865.24 | O48: 0 | P48: 181635.93 | Q48: 54490.779 | R48: 127145.15
B49: TOTAL | C49: =SUM(C44:C48) -> 8196745.4 | D49: =SUM(D44:D48) -> 7402603.4 | E49: =SUM(E44:E48) -> 562232.09 | F49: =SUM(F44:F48) -> 231909.93 | G49: =SUM(G44:G48) -> 1512482 | H49: =SUM(H44:H48) -> 282051.23 | I49: =SUM(I44:I48) -> 105715.81 | J49: =SUM(J44:J48) -> 1336146.6 | ... R49: =SUM(R44:R48) -> 702932.3
B50: GRAND TOTAL | C50: =C42+C49 -> 59790978 | D50: =D42+D49 -> 50324549 | E50: =E42+E49 -> 6549421 | F50: =F42+F49 -> 2917008.1 | G50: =G42+G49 -> 6091511.9 | H50: =H42+H49 -> 4496668.8 | I50: =I42+I49 -> 1383097 | J50: =J42+J49 -> 2977940 | ... R50: =R42+R49 -> 2513073.5
B51: Amounts in Thousand Shillings

Sheet APPENDIX 2
B3: =_xlfn.CONCAT('Table of Contents'!B9,": ",'Table of Contents'!C9) -> APPENDIX 2: SUMMARY OF LONG TERM INSURANCE BUSINESS PROFIT & LOSS ACCOUNTS FOR THE PERIOD ENDED 31.03.2025
B4: Company | C4: Insurance Revenue | D4: Insurance Service Expense | E4: Net expenses from reinsurance contracts held | F4: Insurance Service Result | G4: Net Investment Income | H4: Finance expenses from insurance contracts | I4: Finance income from reinsurance contracts | J4: Net Financial Result | K4: Asset management services revenue | L4: Other Income | M4: Other finance costs | N4: Other operating expenses | O4: Share of profit of associates and joint ventures accounted for using the equity method | P4: Profit before income tax | Q4: Income tax expense | R4: Profit for the year
B5: INSURERS
B6: ABSA LIFE ASSURANCE | C6: 2086213.3 | D6: 1665485.3 | E6: 119654.65 | F6: 301073.31 | G6: 459692.37 | H6: 1162010.6 | I6: 14883.6 | J6: -687434.66 | K6: 0 | L6: 0 | M6: 0 | N6: 44993.901 | O6: 0 | P6: -431355.24 | Q6: 45466.182 | R6: -476821.43
B7: APA LIFE ASSURANCE COMPANY | C7: 1345408.7 | D7: 868201.33 | E7: 476738.86 | F7: 468.54316 | G7: 596632.61 | H7: 476681.92 | I7: 5473.9033 | J7: 125424.6 | K7: 0 | L7: 0 | M7: 7388.641 | N7: 25123.075 | O7: 0 | P7: 93381.423 | Q7: 19511.08 | R7: 73870.343
B8: BRITAM LIFE ASSURANCE | C8: 3480058 | D8: 2554301.8 | E8: 201473.48 | F8: 724282.71 | G8: 9804614.4 | H8: 9955073.9 | I8: 38503.529 | J8: -111956.01 | K8: 0 | L8: -15078.871 | M8: 10471.147 | N8: 128343.45 | O8: 149927.78 | P8: 608361.01 | Q8: 182508.3 | R8: 425852.71
B9: CANNON LIFE ASSURANCE (K) LIMITED | C9: 121787.11 | D9: 147480.24 | E9: 5100.417 | F9: -30793.546 | G9: 40307.388 | H9: 32676.434 | I9: 755.22343 | J9: 8386.1773 | K9: 0 | L9: 3743.4 | M9: 0 | N9: 1885.3023 | O9: 0 | P9: -20549.271 | Q9: 1806.882 | R9: -22356.153
B10: CAPEX LIFE ASSURANCE COMPANY | C10: 398941.75 | D10: 408018.18 | E10: -8977.387 | F10: -99.043759 | G10: 13332.822 | H10: 11087.15 | I10: 8161.032 | J10: 10406.704 | K10: 0 | L10: 0 | M10: 0 | N10: 5100.12 | O10: 0 | P10: 5207.5402 | Q10: 0 | R10: 5207.5402
B11: CIC LIFE ASSURANCE COMPANY | C11: 1592770.2 | D11: 1517857 | E11: 90103.488 | F11: -15190.305 | G11: 501325.41 | H11: 464442.56 | I11: 20488.986 | J11: 57371.835 | K11: 0 | L11: 146827.75 | M11: 0 | N11: 60543.563 | O11: 0 | P11: 128465.72 | Q11: 38539.716 | R11: 89926.004
B12: CORPORATE INSURANCE COMPANY | C12: 59706.503 | D12: 54129.934 | E12: 4750.5172 | F12: 826.05232 | G12: 4813.398 | H12: 35647.354 | I12: 0 | J12: -30833.956 | K12: 0 | L12: 0 | M12: 0 | N12: 190.07583 | O12: 0 | P12: -30197.979 | Q12: 0 | R12: -30197.979
B13: EQUITY LIFE ASSURANCE | C13: 448608.63 | D13: 366370.22 | E13: -75098.176 | F13: 157336.59 | G13: 767664.74 | H13: 474933.83 | I13: 15980.041 | J13: 308710.95 | K13: 0 | L13: 47172.976 | M13: 0 | N13: 70550.568 | O13: 0 | P13: 442669.95 | Q13: 132800.99 | R13: 309868.97
B14: GA LIFE ASSURANCE COMPANY | C14: 22123.436 | D14: 9977.4012 | E14: -6663.914 | F14: 18809.949 | G14: 1615731.9 | H14: 0 | I14: 0 | J14: 1615731.9 | K14: 0 | L14: 331877.67 | M14: 0 | N14: 67946.851 | O14: 0 | P14: 1898472.7 | Q14: 5248.199 | R14: 1893224.5
B15: GEMINIA LIFE INSURANCE COMPANY | C15: 310433.83 | D15: 147421.11 | E15: 5642.784 | F15: 157369.93 | G15: 6146.895 | H15: 0 | I15: 0 | J15: 6146.895 | K15: 0 | L15: 0 | M15: 0 | N15: 29267.578 | O15: 0 | P15: 134249.25 | Q15: 0 | R15: 134249.25
B16: ICEA LION LIFE ASSURANCE | C16: 1389953.9 | D16: 1179225.3 | E16: -96901.208 | F16: 307629.77 | G16: 7974626.6 | H16: 7862984.7 | I16: 0 | J16: 111641.97 | K16: 0 | L16: 63249.497 | M16: 0 | N16: 275626.67 | O16: 0 | P16: 206894.57 | Q16: 46564.349 | R16: 160330.22
B17: JUBILEE LIFE INSURANCE | C17: 1097635.6 | D17: 999433.19 | E17: 177540.61 | F17: -79338.179 | G17: 6223309.3 | H17: 5534370.5 | I17: 0 | J17: 688938.75 | K17: 0 | L17: 0 | M17: 0 | N17: 259888.09 | O17: 15332.819 | P17: 365045.3 | Q17: 86090.688 | R17: 278954.61
... B30: THE MONARCH INSURANCE | C30: 0 | D30: 0 | E30: 0 | F30: 0 | G30: 0 | H30: 0 | I30: 0 | J30: 0 | K30: 0 | L30: 0 | M30: 0 | N30: 0 | O30: 0 | P30: 0 | Q30: 0 | R30: 0
B31: TOTAL | C31: =SUM(C6:C30) -> 18361442 | D31: =SUM(D6:D30) -> 16131998 | E31: =SUM(E6:E30) -> 1203450.7 | F31: =SUM(F6:F30) -> 1025993.1 | G31: =SUM(G6:G30) -> 36975973 | H31: =SUM(H6:H30) -> 34156545 | I31: =SUM(I6:I30) -> 107049.1 | J31: =SUM(J6:J30) -> 2926476.6 | ... R31: =SUM(R6:R30) -> 3127551.6
B32: REINSURERS
B33: CONTINENTAL REINSURANCE | C33: 22961.78 | D33: 24268.422 | E33: 31.049 | F33: -1337.6906 | G33: 16974.278 | H33: 1324.463 | I33: 74 | J33: 15723.815 | K33: 0 | L33: 0 | M33: 43.998 | N33: 677 | O33: 0 | P33: 13753.052 | Q33: -4125.916 | R33: 9627.1364
B34: EAST AFRICA REINSURANCE | C34: 361178.95 | D34: 252517.47 | E34: 51013.29 | F34: 57648.186 | G34: 65895.28 | H34: 7098.455 | I34: 1468.1674 | J34: 60264.992 | K34: 0 | L34: 0 | M34: 0 | N34: 4741 | O34: 0 | P34: 113171.7 | Q34: -33951.511 | R34: 79220.192
B35: KENYA REINSURANCE CORPORATION | C35: 688924.38 | D35: 840979.3 | E35: 8998.1368 | F35: -161053.05 | G35: 205888.07 | H35: 94599.293 | I35: 952.43524 | J35: 112241.21 | K35: 0 | L35: 0 | M35: 0 | N35: 131088 | O35: 0 | P35: -179900.02 | Q35: 53970.006 | R35: -125930.01
B36: TOTAL | C36: =SUM(C33:C35) -> 1073065.1 | D36: =SUM(D33:D35) -> 1117765.2 | E36: =SUM(E33:E35) -> 60042.476 | F36: =SUM(F33:F35) -> -104742.56 | G36: =SUM(G33:G35) -> 288757.63 | H36: =SUM(H33:H35) -> 103022.21 | I36: =SUM(I33:I35) -> 2494.6026 | J36: =SUM(J33:J35) -> 188230.02 | ... R36: =SUM(R33:R35) -> -37082.686
B37: GRAND TOTAL | C37: =C36+C31 -> 19434507 | D37: =D36+D31 -> 17249763 | E37: =E36+E31 -> 1263493.2 | F37: =F36+F31 -> 921250.57 | G37: =G36+G31 -> 37264730 | H37: =H36+H31 -> 34259567 | I37: =I36+I31 -> 109543.7 | J37: =J36+J31 -> 3114706.7 | ... R37: =R36+R31 -> 3090468.9
B38: Amounts in Thousand Shillings

Sheet APPENDIX 3
B3: =_xlfn.CONCAT('Table of Contents'!B10,": ",'Table of Contents'!C10) -> APPENDIX 3: SUMMARY OF MICRO INSURANCE BUSINESS PROFIT & LOSS ACCOUNTS FOR THE PERIOD ENDED 31.03.2025
B4: Company | C4: Insurance Revenue | D4: Insurance Service Expense | E4: Net expenses from reinsurance contracts held | F4: Insurance Service Result | G4: Net Investment Income | H4: Finance expenses from insurance contracts | I4: Finance income from reinsurance contracts | J4: Net Financial Result | K4: Asset management services revenue | L4: Other Income | M4: Other finance costs | N4: Other operating expenses | O4: Share of profit of associates and joint ventures accounted for using the equity method | P4: Profit before income tax | Q4: Income tax expense | R4: Profit for the year
B5: INSURERS
B6: APA MICRO INSURANCE | C6: 0 | D6: 0 | E6: 0 | F6: 0 | G6: 0 | H6: 0 | I6: 0 | J6: 0 | K6: 0 | L6: 0 | M6: 0 | N6: 0 | O6: 0 | P6: 0 | Q6: 0 | R6: 0
B7: BIRDVIEW MICRO INSURANCE | C7: 0 | D7: 0 | E7: 0 | F7: 0 | G7: 0 | H7: 0 | I7: 0 | J7: 0 | K7: 0 | L7: 0 | M7: 0 | N7: 0 | O7: 0 | P7: 0 | Q7: 0 | R7: 0
B8: BRITAM MICRO INSURANCE | C8: 151301.27 | D8: 137594.63 | E8: 17581.794 | F8: -3875.1561 | G8: 11352.201 | H8: 3904.0245 | I8: 28.893163 | J8: 7477.0702 | K8: 0 | L8: 246.72707 | M8: 1295.7948 | N8: 5099.7644 | O8: 0 | P8: -2546.918 | Q8: 0 | R8: -2546.918
B9: CIC MICRO INSURANCE | C9: 0 | D9: 0 | E9: 0 | F9: 0 | G9: 0 | H9: 0 | I9: 0 | J9: 0 | K9: 0 | L9: 0 | M9: 0 | N9: 0 | O9: 0 | P9: 0 | Q9: 0 | R9: 0
B10: STAR DISCOVER MICRO INSURANCE | C10: 23728.542 | D10: 30528.194 | E10: 10240.628 | F10: -17040.279 | G10: 0 | H10: 214.64969 | I10: 122.15404 | J10: -92.495651 | K10: 0 | L10: 272.554 | M10: 0 | N10: 0 | O10: 0 | P10: -16860.221 | Q10: 0 | R10: -16860.221
B11: TURACO MICRO INSURANCE | C11: 98546.435 | D11: 87976.48 | E11: 7905.9752 | F11: 2663.9803 | G11: 1052.0548 | H11: 39.096737 | I11: 7.2545134 | J11: 1020.2126 | K11: 0 | L11: 0 | M11: 0 | N11: 0 | O11: 0 | P11: 3684.1929 | Q11: 1105.2579 | R11: 2578.935
B12: TOTAL | C12: =SUM(C6:C11) -> 273576.25 | D12: =SUM(D6:D11) -> 256099.3 | E12: =SUM(E6:E11) -> 35728.397 | F12: =SUM(F6:F11) -> -18251.455 | G12: =SUM(G6:G11) -> 12404.256 | H12: =SUM(H6:H11) -> 4157.7709 | I12: =SUM(I6:I11) -> 158.30172 | J12: =SUM(J6:J11) -> 8404.7871 | ... R12: =SUM(R6:R11) -> -16828.204
B13: Amounts in Thousand Shillings

Sheet APPENDIX 4
B3: =_xlfn.CONCAT('Table of Contents'!B11,": ",'Table of Contents'!C11) -> APPENDIX 4: SUMMARY OF LONG TERM INSURANCE BUSINESS GROSS PREMIUM INCOME FOR THE PERIOD ENDED 31.03.2025
B4: Company | C4: Life Assurances | D4: Annuities | E4: Personal Pensions | F4: Deposit Administration | G4: Group Life | H4: Group Credit | I4: Permanent Health | J4: Investments | K4: Total | L4: Market Share (%)
B5: INSURERS
B6: ='APPENDIX 6'!B6 -> ABSA LIFE ASSURANCE | C6: ='APPENDIX 6'!D6 -> 1419720.3 | D6: ='APPENDIX 7'!D6 -> 0 | E6: ='APPENDIX 12'!D6 -> 0 | F6: ='APPENDIX 13'!D6 -> 0 | G6: ='APPENDIX 8'!D6 -> 1397419.6 | H6: ='APPENDIX 9'!D6 -> 155932.11 | I6: ='APPENDIX 11'!D6 -> 0 | J6: ='APPENDIX 10'!D6 -> 0 | K6: =SUM(C6:J6) -> 2973072 | L6: =IFERROR(K6/$K$31,0)*100 -> 5.5632577
B7: ='APPENDIX 6'!B7 -> APA LIFE ASSURANCE COMPANY | C7: ='APPENDIX 6'!D7 -> 140563.62 | D7: ='APPENDIX 7'!D7 -> 18694.998 | E7: ='APPENDIX 12'!D7 -> 51601.347 | F7: ='APPENDIX 13'!D7 -> 253912.34 | G7: ='APPENDIX 8'!D7 -> 750660.01 | H7: ='APPENDIX 9'!D7 -> 190625.79 | I7: ='APPENDIX 11'!D7 -> 0 | J7: ='APPENDIX 10'!D7 -> 1093378.7 | K7: =SUM(C7:J7) -> 2499436.8 | L7: =IFERROR(K7/$K$31,0)*100 -> 4.6769842
B8: ='APPENDIX 6'!B8 -> BRITAM LIFE ASSURANCE | C8: ='APPENDIX 6'!D8 -> 2845011 | D8: ='APPENDIX 7'!D8 -> 1516175.6 | E8: ='APPENDIX 12'!D8 -> 979427.72 | F8: ='APPENDIX 13'!D8 -> 1291968 | G8: ='APPENDIX 8'!D8 -> 500832.27 | H8: ='APPENDIX 9'!D8 -> 120684.12 | I8: ='APPENDIX 11'!D8 -> 0 | J8: ='APPENDIX 10'!D8 -> 2404280 | K8: =SUM(C8:J8) -> 9658378.7 | L8: =IFERROR(K8/$K$31,0)*100 -> 18.072905
B9: ='APPENDIX 6'!B9 -> CANNON LIFE ASSURANCE (K) LIMITED | C9: ='APPENDIX 6'!D9 -> 6556.598 | D9: ='APPENDIX 7'!D9 -> 0 | E9: ='APPENDIX 12'!D9 -> 0 | F9: ='APPENDIX 13'!D9 -> 0 | G9: ='APPENDIX 8'!D9 -> 226335.44 | H9: ='APPENDIX 9'!D9 -> 4106.174 | I9: ='APPENDIX 11'!D9 -> 0 | J9: ='APPENDIX 10'!D9 -> 0 | K9: =SUM(C9:J9) -> 236998.21 | L9: =IFERROR(K9/$K$31,0)*100 -> 0.44347467
B10: ='APPENDIX 6'!B10 -> CAPEX LIFE ASSURANCE COMPANY | C10: ='APPENDIX 6'!D10 -> 7679.969 | D10: ='APPENDIX 7'!D10 -> 127646.8 | E10: ='APPENDIX 12'!D10 -> 0 | F10: ='APPENDIX 13'!D10 -> 0 | G10: ='APPENDIX 8'!D10 -> 200062.22 | H10: ='APPENDIX 9'!D10 -> 43060.997 | I10: ='APPENDIX 11'!D10 -> 0 | J10: ='APPENDIX 10'!D10 -> 0 | K10: =SUM(C10:J10) -> 378449.98 | L10: =IFERROR(K10/$K$31,0)*100 -> 0.70816137
B11: ='APPENDIX 6'!B11 -> CIC LIFE ASSURANCE COMPANY | C11: ='APPENDIX 6'!D11 -> 325786.32 | D11: ='APPENDIX 7'!D11 -> 119075.01 | E11: ='APPENDIX 12'!D11 -> 0 | F11: ='APPENDIX 13'!D11 -> 863483.16 | G11: ='APPENDIX 8'!D11 -> 388787.88 | H11: ='APPENDIX 9'!D11 -> 2352717.4 | I11: ='APPENDIX 11'!D11 -> 0 | J11: ='APPENDIX 10'!D11 -> 0 | K11: =SUM(C11:J11) -> 4049849.8 | L11: =IFERROR(K11/$K$31,0)*100 -> 7.5781407
B12: ='APPENDIX 6'!B12 -> CORPORATE INSURANCE COMPANY | C12: ='APPENDIX 6'!D12 -> 8452.4385 | D12: ='APPENDIX 7'!D12 -> 0 | E12: ='APPENDIX 12'!D12 -> 0 | F12: ='APPENDIX 13'!D12 -> 0 | G12: ='APPENDIX 8'!D12 -> 0 | H12: ='APPENDIX 9'!D12 -> 0 | I12: ='APPENDIX 11'!D12 -> 0 | J12: ='APPENDIX 10'!D12 -> 0 | K12: =SUM(C12:J12) -> 8452.4385 | L12: =IFERROR(K12/$K$31,0)*100 -> 0.015816332
B13: ='APPENDIX 6'!B13 -> EQUITY LIFE ASSURANCE | C13: ='APPENDIX 6'!D13 -> 0 | D13: ='APPENDIX 7'!D13 -> 0 | E13: ='APPENDIX 12'!D13 -> 59723.999 | F13: ='APPENDIX 13'!D13 -> 633735.15 | G13: ='APPENDIX 8'!D13 -> 574687.98 | H13: ='APPENDIX 9'!D13 -> 652617.51 | I13: ='APPENDIX 11'!D13 -> 0 | J13: ='APPENDIX 10'!D13 -> 155652.82 | K13: =SUM(C13:J13) -> 2076417.5 | L13: =IFERROR(K13/$K$31,0)*100 -> 3.885424
B14: ='APPENDIX 6'!B14 -> GA LIFE ASSURANCE COMPANY | C14: ='APPENDIX 6'!D14 -> 18244.757 | D14: ='APPENDIX 7'!D14 -> 0 | E14: ='APPENDIX 12'!D14 -> 310066.09 | F14: ='APPENDIX 13'!D14 -> 5040249 | G14: ='APPENDIX 8'!D14 -> 34320.526 | H14: ='APPENDIX 9'!D14 -> 896.95848 | I14: ='APPENDIX 11'!D14 -> 0 | J14: ='APPENDIX 10'!D14 -> 0 | K14: =SUM(C14:J14) -> 5403777.4 | L14: =IFERROR(K14/$K$31,0)*100 -> 10.111631
B15: ='APPENDIX 6'!B15 -> GEMINIA LIFE INSURANCE COMPANY | C15: ='APPENDIX 6'!D15 -> 17232.776 | D15: ='APPENDIX 7'!D15 -> 0 | E15: ='APPENDIX 12'!D15 -> 164999.69 | F15: ='APPENDIX 13'!D15 -> 598310.41 | G15: ='APPENDIX 8'!D15 -> 122624.96 | H15: ='APPENDIX 9'!D15 -> 80579.255 | I15: ='APPENDIX 11'!D15 -> 0 | J15: ='APPENDIX 10'!D15 -> 168430.38 | K15: =SUM(C15:J15) -> 1152177.5 | L15: =IFERROR(K15/$K$31,0)*100 -> 2.1559721
B16: ='APPENDIX 6'!B16 -> ICEA LION LIFE ASSURANCE | C16: ='APPENDIX 6'!D16 -> 1863890.6 | D16: ='APPENDIX 7'!D16 -> 518127.29 | E16: ='APPENDIX 12'!D16 -> 1903461.8 | F16: ='APPENDIX 13'!D16 -> 2474247.9 | G16: ='APPENDIX 8'!D16 -> 186560.47 | H16: ='APPENDIX 9'!D16 -> 35161.351 | I16: ='APPENDIX 11'!D16 -> 0 | J16: ='APPENDIX 10'!D16 -> 1312.6909 | K16: =SUM(C16:J16) -> 6982762.2 | L16: =IFERROR(K16/$K$31,0)*100 -> 13.066251
B17: ='APPENDIX 6'!B17 -> JUBILEE LIFE INSURANCE | C17: ='APPENDIX 6'!D17 -> 1698033.3 | D17: ='APPENDIX 7'!D17 -> 577366.4 | E17: ='APPENDIX 12'!D17 -> 670804.03 | F17: ='APPENDIX 13'!D17 -> 3614808.5 | G17: ='APPENDIX 8'!D17 -> 420477.76 | H17: ='APPENDIX 9'!D17 -> 93087.809 | I17: ='APPENDIX 11'!D17 -> 0 | J17: ='APPENDIX 10'!D17 -> 0 | K17: =SUM(C17:J17) -> 7074577.8 | L17: =IFERROR(K17/$K$31,0)*100 -> 13.238058
... B30: ='APPENDIX 6'!B30 -> THE MONARCH INSURANCE | C30: ='APPENDIX 6'!D30 -> 0 | D30: ='APPENDIX 7'!D30 -> 0 | E30: ='APPENDIX 12'!D30 -> 0 | F30: ='APPENDIX 13'!D30 -> 0 | G30: ='APPENDIX 8'!D30 -> 0 | H30: ='APPENDIX 9'!D30 -> 0 | I30: ='APPENDIX 11'!D30 -> 0 | J30: ='APPENDIX 10'!D30 -> 0 | K30: =SUM(C30:J30) -> 0 | L30: =IFERROR(K30/$K$31,0)*100 -> 0
B31: TOTAL | C31: =SUM(C6:C30) -> 11796272 | D31: =SUM(D6:D30) -> 3292672.4 | E31: =SUM(E6:E30) -> 5043446.6 | F31: =SUM(F6:F30) -> 16490309 | G31: =SUM(G6:G30) -> 7163503.3 | H31: =SUM(H6:H30) -> 5548840.9 | I31: =SUM(I6:I30) -> 0 | J31: =SUM(J6:J30) -> 4106161.7 | ... L31: =SUM(L6:L30) -> 100
B32: REINSURERS
B33: ='APPENDIX 6'!B33 -> CONTINENTAL REINSURANCE | C33: ='APPENDIX 6'!D33 -> 0 | D33: ='APPENDIX 7'!D33 -> 0 | E33: ='APPENDIX 12'!D33 -> 0 | F33: ='APPENDIX 13'!F33 -> 0 | G33: ='APPENDIX 8'!D33 -> 22961.78 | H33: ='APPENDIX 9'!D33 -> 0 | I33: ='APPENDIX 11'!D33 -> 0 | J33: ='APPENDIX 10'!D33 -> 0 | K33: =SUM(C33:J33) -> 22961.78 | L33: =IFERROR(K33/$K$36,0)*100 -> 1.9511532
B34: ='APPENDIX 6'!B34 -> EAST AFRICA REINSURANCE | C34: ='APPENDIX 6'!D34 -> 34147.043 | D34: ='APPENDIX 7'!D34 -> 0 | E34: ='APPENDIX 12'!D34 -> 0 | F34: ='APPENDIX 13'!F34 -> 0 | G34: ='APPENDIX 8'!D34 -> 327031.9 | H34: ='APPENDIX 9'!D34 -> 0 | I34: ='APPENDIX 11'!D34 -> 0 | J34: ='APPENDIX 10'!D34 -> 0 | K34: =SUM(C34:J34) -> 361178.95 | L34: =IFERROR(K34/$K$36,0)*100 -> 30.690803
B35: ='APPENDIX 6'!B35 -> KENYA REINSURANCE CORPORATION | C35: ='APPENDIX 6'!D35 -> 36014.078 | D35: ='APPENDIX 7'!D35 -> 0 | E35: ='APPENDIX 12'!D35 -> 0 | F35: ='APPENDIX 13'!F35 -> 0 | G35: ='APPENDIX 8'!D35 -> 756676.39 | H35: ='APPENDIX 9'!D35 -> 0 | I35: ='APPENDIX 11'!D35 -> 0 | J35: ='APPENDIX 10'!D35 -> 0 | K35: =SUM(C35:J35) -> 792690.47 | L35: =IFERROR(K35/$K$36,0)*100 -> 67.358044
B36: TOTAL | C36: =SUM(C33:C35) -> 70161.121 | D36: =SUM(D33:D35) -> 0 | E36: =SUM(E33:E35) -> 0 | F36: =SUM(F33:F35) -> 0 | G36: =SUM(G33:G35) -> 1106670.1 | H36: =SUM(H33:H35) -> 0 | I36: =SUM(I33:I35) -> 0 | J36: =SUM(J33:J35) -> 0 | ... L36: =SUM(L33:L35) -> 100
B37: Amounts in Thousand Shillings

Sheet APPENDIX 5
B3: =_xlfn.CONCAT('Table of Contents'!B12,": ",'Table of Contents'!C12) -> APPENDIX 5: SUMMARY OF LONG TERM INSURANCE BUSINESS MARKET SHARE PER CLASS FOR THE PERIOD ENDED 31.03.2025
B4: Company | C4: Life Assurances | D4: Annuities | E4: Pensions | F4: Deposit Administration | G4: Group Life | H4: Group Credit | I4: Permanent Health | J4: Investments | K4: Total
B5: INSURERS
B6: ='APPENDIX 6'!B6 -> ABSA LIFE ASSURANCE | C6: =IFERROR(('APPENDIX 4'!C6/'APPENDIX 4'!C$31)*100,0) -> 12.03533 | D6: =IFERROR(('APPENDIX 4'!D6/'APPENDIX 4'!D$31)*100,0) -> 0 | E6: =IFERROR(('APPENDIX 4'!E6/'APPENDIX 4'!E$31)*100,0) -> 0 | F6: =IFERROR(('APPENDIX 4'!F6/'APPENDIX 4'!F$31)*100,0) -> 0 | G6: =IFERROR(('APPENDIX 4'!G6/'APPENDIX 4'!G$31)*100,0) -> 19.507489 | H6: =IFERROR(('APPENDIX 4'!H6/'APPENDIX 4'!H$31)*100,0) -> 2.8101745 | I6: =IFERROR(('APPENDIX 4'!I6/'APPENDIX 4'!I$31)*100,0) -> 0 | J6: =IFERROR(('APPENDIX 4'!J6/'APPENDIX 4'!J$31)*100,0) -> 0 | K6: =IFERROR(('APPENDIX 4'!K6/'APPENDIX 4'!K$31)*100,0) -> 5.5632577 | L6: =RANK(K6,$K$6:$K$30) -> 6 | M6: =COUNTIF(K6:K30,">5") -> 6
B7: ='APPENDIX 6'!B7 -> APA LIFE ASSURANCE COMPANY | C7: =IFERROR(('APPENDIX 4'!C7/'APPENDIX 4'!C$31)*100,0) -> 1.1915936 | D7: =IFERROR(('APPENDIX 4'!D7/'APPENDIX 4'!D$31)*100,0) -> 0.56777584 | E7: =IFERROR(('APPENDIX 4'!E7/'APPENDIX 4'!E$31)*100,0) -> 1.0231366 | F7: =IFERROR(('APPENDIX 4'!F7/'APPENDIX 4'!F$31)*100,0) -> 1.539767 | G7: =IFERROR(('APPENDIX 4'!G7/'APPENDIX 4'!G$31)*100,0) -> 10.478951 | H7: =IFERROR(('APPENDIX 4'!H7/'APPENDIX 4'!H$31)*100,0) -> 3.4354165 | I7: =IFERROR(('APPENDIX 4'!I7/'APPENDIX 4'!I$31)*100,0) -> 0 | J7: =IFERROR(('APPENDIX 4'!J7/'APPENDIX 4'!J$31)*100,0) -> 26.627754 | K7: =IFERROR(('APPENDIX 4'!K7/'APPENDIX 4'!K$31)*100,0) -> 4.6769842 | L7: =RANK(K7,$K$6:$K$30) -> 7
B8: ='APPENDIX 6'!B8 -> BRITAM LIFE ASSURANCE | C8: =IFERROR(('APPENDIX 4'!C8/'APPENDIX 4'!C$31)*100,0) -> 24.117881 | D8: =IFERROR(('APPENDIX 4'!D8/'APPENDIX 4'!D$31)*100,0) -> 46.046962 | E8: =IFERROR(('APPENDIX 4'!E8/'APPENDIX 4'!E$31)*100,0) -> 19.419809 | F8: =IFERROR(('APPENDIX 4'!F8/'APPENDIX 4'!F$31)*100,0) -> 7.8347109 | G8: =IFERROR(('APPENDIX 4'!G8/'APPENDIX 4'!G$31)*100,0) -> 6.9914432 | H8: =IFERROR(('APPENDIX 4'!H8/'APPENDIX 4'!H$31)*100,0) -> 2.1749429 | I8: =IFERROR(('APPENDIX 4'!I8/'APPENDIX 4'!I$31)*100,0) -> 0 | J8: =IFERROR(('APPENDIX 4'!J8/'APPENDIX 4'!J$31)*100,0) -> 58.552977 | K8: =IFERROR(('APPENDIX 4'!K8/'APPENDIX 4'!K$31)*100,0) -> 18.072905 | L8: =RANK(K8,$K$6:$K$30) -> 1
B9: ='APPENDIX 6'!B9 -> CANNON LIFE ASSURANCE (K) LIMITED | C9: =IFERROR(('APPENDIX 4'!C9/'APPENDIX 4'!C$31)*100,0) -> 0.055581948 | D9: =IFERROR(('APPENDIX 4'!D9/'APPENDIX 4'!D$31)*100,0) -> 0 | E9: =IFERROR(('APPENDIX 4'!E9/'APPENDIX 4'!E$31)*100,0) -> 0 | F9: =IFERROR(('APPENDIX 4'!F9/'APPENDIX 4'!F$31)*100,0) -> 0 | G9: =IFERROR(('APPENDIX 4'!G9/'APPENDIX 4'!G$31)*100,0) -> 3.1595635 | H9: =IFERROR(('APPENDIX 4'!H9/'APPENDIX 4'!H$31)*100,0) -> 0.074000572 | I9: =IFERROR(('APPENDIX 4'!I9/'APPENDIX 4'!I$31)*100,0) -> 0 | J9: =IFERROR(('APPENDIX 4'!J9/'APPENDIX 4'!J$31)*100,0) -> 0 | K9: =IFERROR(('APPENDIX 4'!K9/'APPENDIX 4'!K$31)*100,0) -> 0.44347467 | L9: =RANK(K9,$K$6:$K$30) -> 20
B10: ='APPENDIX 6'!B10 -> CAPEX LIFE ASSURANCE COMPANY | C10: =IFERROR(('APPENDIX 4'!C10/'APPENDIX 4'!C$31)*100,0) -> 0.065105049 | D10: =IFERROR(('APPENDIX 4'!D10/'APPENDIX 4'!D$31)*100,0) -> 3.876693 | E10: =IFERROR(('APPENDIX 4'!E10/'APPENDIX 4'!E$31)*100,0) -> 0 | F10: =IFERROR(('APPENDIX 4'!F10/'APPENDIX 4'!F$31)*100,0) -> 0 | G10: =IFERROR(('APPENDIX 4'!G10/'APPENDIX 4'!G$31)*100,0) -> 2.7927985 | H10: =IFERROR(('APPENDIX 4'!H10/'APPENDIX 4'!H$31)*100,0) -> 0.77603589 | I10: =IFERROR(('APPENDIX 4'!I10/'APPENDIX 4'!I$31)*100,0) -> 0 | J10: =IFERROR(('APPENDIX 4'!J10/'APPENDIX 4'!J$31)*100,0) -> 0 | K10: =IFERROR(('APPENDIX 4'!K10/'APPENDIX 4'!K$31)*100,0) -> 0.70816137 | L10: =RANK(K10,$K$6:$K$30) -> 18
B11: ='APPENDIX 6'!B11 -> CIC LIFE ASSURANCE COMPANY | C11: =IFERROR(('APPENDIX 4'!C11/'APPENDIX 4'!C$31)*100,0) -> 2.7617734 | D11: =IFERROR(('APPENDIX 4'!D11/'APPENDIX 4'!D$31)*100,0) -> 3.6163638 | E11: =IFERROR(('APPENDIX 4'!E11/'APPENDIX 4'!E$31)*100,0) -> 0 | F11: =IFERROR(('APPENDIX 4'!F11/'APPENDIX 4'!F$31)*100,0) -> 5.2363067 | G11: =IFERROR(('APPENDIX 4'!G11/'APPENDIX 4'!G$31)*100,0) -> 5.4273428 | H11: =IFERROR(('APPENDIX 4'!H11/'APPENDIX 4'!H$31)*100,0) -> 42.40016 | I11: =IFERROR(('APPENDIX 4'!I11/'APPENDIX 4'!I$31)*100,0) -> 0 | J11: =IFERROR(('APPENDIX 4'!J11/'APPENDIX 4'!J$31)*100,0) -> 0 | K11: =IFERROR(('APPENDIX 4'!K11/'APPENDIX 4'!K$31)*100,0) -> 7.5781407 | L11: =RANK(K11,$K$6:$K$30) -> 5
B12: ='APPENDIX 6'!B12 -> CORPORATE INSURANCE COMPANY | C12: =IFERROR(('APPENDIX 4'!C12/'APPENDIX 4'!C$31)*100,0) -> 0.07165347 | D12: =IFERROR(('APPENDIX 4'!D12/'APPENDIX 4'!D$31)*100,0) -> 0 | E12: =IFERROR(('APPENDIX 4'!E12/'APPENDIX 4'!E$31)*100,0) -> 0 | F12: =IFERROR(('APPENDIX 4'!F12/'APPENDIX 4'!F$31)*100,0) -> 0 | G12: =IFERROR(('APPENDIX 4'!G12/'APPENDIX 4'!G$31)*100,0) -> 0 | H12: =IFERROR(('APPENDIX 4'!H12/'APPENDIX 4'!H$31)*100,0) -> 0 | I12: =IFERROR(('APPENDIX 4'!I12/'APPENDIX 4'!I$31)*100,0) -> 0 | J12: =IFERROR(('APPENDIX 4'!J12/'APPENDIX 4'!J$31)*100,0) -> 0 | K12: =IFERROR(('APPENDIX 4'!K12/'APPENDIX 4'!K$31)*100,0) -> 0.015816332 | L12: =RANK(K12,$K$6:$K$30) -> 23
B13: ='APPENDIX 6'!B13 -> EQUITY LIFE ASSURANCE | C13: =IFERROR(('APPENDIX 4'!C13/'APPENDIX 4'!C$31)*100,0) -> 0 | D13: =IFERROR(('APPENDIX 4'!D13/'APPENDIX 4'!D$31)*100,0) -> 0 | E13: =IFERROR(('APPENDIX 4'!E13/'APPENDIX 4'!E$31)*100,0) -> 1.1841902 | F13: =IFERROR(('APPENDIX 4'!F13/'APPENDIX 4'!F$31)*100,0) -> 3.8430763 | G13: =IFERROR(('APPENDIX 4'!G13/'APPENDIX 4'!G$31)*100,0) -> 8.0224431 | H13: =IFERROR(('APPENDIX 4'!H13/'APPENDIX 4'!H$31)*100,0) -> 11.76133 | I13: =IFERROR(('APPENDIX 4'!I13/'APPENDIX 4'!I$31)*100,0) -> 0 | J13: =IFERROR(('APPENDIX 4'!J13/'APPENDIX 4'!J$31)*100,0) -> 3.7907133 | K13: =IFERROR(('APPENDIX 4'!K13/'APPENDIX 4'!K$31)*100,0) -> 3.885424 | L13: =RANK(K13,$K$6:$K$30) -> 8
B14: ='APPENDIX 6'!B14 -> GA LIFE ASSURANCE COMPANY | C14: =IFERROR(('APPENDIX 4'!C14/'APPENDIX 4'!C$31)*100,0) -> 0.15466544 | D14: =IFERROR(('APPENDIX 4'!D14/'APPENDIX 4'!D$31)*100,0) -> 0 | E14: =IFERROR(('APPENDIX 4'!E14/'APPENDIX 4'!E$31)*100,0) -> 6.1479008 | F14: =IFERROR(('APPENDIX 4'!F14/'APPENDIX 4'!F$31)*100,0) -> 30.564916 | G14: =IFERROR(('APPENDIX 4'!G14/'APPENDIX 4'!G$31)*100,0) -> 0.47910253 | H14: =IFERROR(('APPENDIX 4'!H14/'APPENDIX 4'!H$31)*100,0) -> 0.01616479 | I14: =IFERROR(('APPENDIX 4'!I14/'APPENDIX 4'!I$31)*100,0) -> 0 | J14: =IFERROR(('APPENDIX 4'!J14/'APPENDIX 4'!J$31)*100,0) -> 0 | K14: =IFERROR(('APPENDIX 4'!K14/'APPENDIX 4'!K$31)*100,0) -> 10.111631 | L14: =RANK(K14,$K$6:$K$30) -> 4
B15: ='APPENDIX 6'!B15 -> GEMINIA LIFE INSURANCE COMPANY | C15: =IFERROR(('APPENDIX 4'!C15/'APPENDIX 4'!C$31)*100,0) -> 0.14608663 | D15: =IFERROR(('APPENDIX 4'!D15/'APPENDIX 4'!D$31)*100,0) -> 0 | E15: =IFERROR(('APPENDIX 4'!E15/'APPENDIX 4'!E$31)*100,0) -> 3.2715661 | F15: =IFERROR(('APPENDIX 4'!F15/'APPENDIX 4'!F$31)*100,0) -> 3.6282547 | G15: =IFERROR(('APPENDIX 4'!G15/'APPENDIX 4'!G$31)*100,0) -> 1.7118016 | H15: =IFERROR(('APPENDIX 4'!H15/'APPENDIX 4'!H$31)*100,0) -> 1.4521818 | I15: =IFERROR(('APPENDIX 4'!I15/'APPENDIX 4'!I$31)*100,0) -> 0 | J15: =IFERROR(('APPENDIX 4'!J15/'APPENDIX 4'!J$31)*100,0) -> 4.1018935 | K15: =IFERROR(('APPENDIX 4'!K15/'APPENDIX 4'!K$31)*100,0) -> 2.1559721 | L15: =RANK(K15,$K$6:$K$30) -> 14
B16: ='APPENDIX 6'!B16 -> ICEA LION LIFE ASSURANCE | C16: =IFERROR(('APPENDIX 4'!C16/'APPENDIX 4'!C$31)*100,0) -> 15.800675 | D16: =IFERROR(('APPENDIX 4'!D16/'APPENDIX 4'!D$31)*100,0) -> 15.735768 | E16: =IFERROR(('APPENDIX 4'!E16/'APPENDIX 4'!E$31)*100,0) -> 37.74129 | F16: =IFERROR(('APPENDIX 4'!F16/'APPENDIX 4'!F$31)*100,0) -> 15.004255 | G16: =IFERROR(('APPENDIX 4'!G16/'APPENDIX 4'!G$31)*100,0) -> 2.6043188 | H16: =IFERROR(('APPENDIX 4'!H16/'APPENDIX 4'!H$31)*100,0) -> 0.63367019 | I16: =IFERROR(('APPENDIX 4'!I16/'APPENDIX 4'!I$31)*100,0) -> 0 | J16: =IFERROR(('APPENDIX 4'!J16/'APPENDIX 4'!J$31)*100,0) -> 0.031968807 | K16: =IFERROR(('APPENDIX 4'!K16/'APPENDIX 4'!K$31)*100,0) -> 13.066251 | L16: =RANK(K16,$K$6:$K$30) -> 3
B17: ='APPENDIX 6'!B17 -> JUBILEE LIFE INSURANCE | C17: =IFERROR(('APPENDIX 4'!C17/'APPENDIX 4'!C$31)*100,0) -> 14.39466 | D17: =IFERROR(('APPENDIX 4'!D17/'APPENDIX 4'!D$31)*100,0) -> 17.534888 | E17: =IFERROR(('APPENDIX 4'!E17/'APPENDIX 4'!E$31)*100,0) -> 13.300508 | F17: =IFERROR(('APPENDIX 4'!F17/'APPENDIX 4'!F$31)*100,0) -> 21.920805 | G17: =IFERROR(('APPENDIX 4'!G17/'APPENDIX 4'!G$31)*100,0) -> 5.8697224 | H17: =IFERROR(('APPENDIX 4'!H17/'APPENDIX 4'!H$31)*100,0) -> 1.6776082 | I17: =IFERROR(('APPENDIX 4'!I17/'APPENDIX 4'!I$31)*100,0) -> 0 | J17: =IFERROR(('APPENDIX 4'!J17/'APPENDIX 4'!J$31)*100,0) -> 0 | K17: =IFERROR(('APPENDIX 4'!K17/'APPENDIX 4'!K$31)*100,0) -> 13.238058 | L17: =RANK(K17,$K$6:$K$30) -> 2
B18: ='APPENDIX 6'!B18 -> KENINDIA ASSURANCE COMPANY | C18: =IFERROR(('APPENDIX 4'!C18/'APPENDIX 4'!C$31)*100,0) -> 5.7681031 | D18: =IFERROR(('APPENDIX 4'!D18/'APPENDIX 4'!D$31)*100,0) -> 2.9471525 | E18: =IFERROR(('APPENDIX 4'!E18/'APPENDIX 4'!E$31)*100,0) -> 6.6907025 | F18: =IFERROR(('APPENDIX 4'!F18/'APPENDIX 4'!F$31)*100,0) -> 4.8124161 | G18: =IFERROR(('APPENDIX 4'!G18/'APPENDIX 4'!G$31)*100,0) -> 0.33936433 | H18: =IFERROR(('APPENDIX 4'!H18/'APPENDIX 4'!H$31)*100,0) -> 0.00054470836 | I18: =IFERROR(('APPENDIX 4'!I18/'APPENDIX 4'!I$31)*100,0) -> 0 | J18: =IFERROR(('APPENDIX 4'!J18/'APPENDIX 4'!J$31)*100,0) -> 0 | K18: =IFERROR(('APPENDIX 4'!K18/'APPENDIX 4'!K$31)*100,0) -> 3.6167337 | L18: =RANK(K18,$K$6:$K$30) -> 9
... B30: ='APPENDIX 6'!B30 -> THE MONARCH INSURANCE | C30: =IFERROR(('APPENDIX 4'!C30/'APPENDIX 4'!C$31)*100,0) -> 0 | D30: =IFERROR(('APPENDIX 4'!D30/'APPENDIX 4'!D$31)*100,0) -> 0 | E30: =IFERROR(('APPENDIX 4'!E30/'APPENDIX 4'!E$31)*100,0) -> 0 | F30: =IFERROR(('APPENDIX 4'!F30/'APPENDIX 4'!F$31)*100,0) -> 0 | G30: =IFERROR(('APPENDIX 4'!G30/'APPENDIX 4'!G$31)*100,0) -> 0 | H30: =IFERROR(('APPENDIX 4'!H30/'APPENDIX 4'!H$31)*100,0) -> 0 | I30: =IFERROR(('APPENDIX 4'!I30/'APPENDIX 4'!I$31)*100,0) -> 0 | J30: =IFERROR(('APPENDIX 4'!J30/'APPENDIX 4'!J$31)*100,0) -> 0 | K30: =IFERROR(('APPENDIX 4'!K30/'APPENDIX 4'!K$31)*100,0) -> 0 | L30: =RANK(K30,$K$6:$K$30) -> 25
B31: TOTAL | C31: =SUM(C6:C30) -> 100 | D31: =SUM(D6:D30) -> 100 | E31: =SUM(E6:E30) -> 100 | F31: =SUM(F6:F30) -> 100 | G31: =SUM(G6:G30) -> 100 | H31: =SUM(H6:H30) -> 100 | I31: =SUM(I6:I30) -> 0 | J31: =SUM(J6:J30) -> 100 | K31: =SUM(K6:K30) -> 100
B32: REINSURERS
B33: ='APPENDIX 6'!B33 -> CONTINENTAL REINSURANCE | C33: =IFERROR(('APPENDIX 4'!C33/'APPENDIX 4'!C$36)*100,0) -> 0 | D33: =IFERROR(('APPENDIX 4'!D33/'APPENDIX 4'!D$36)*100,0) -> 0 | E33: =IFERROR(('APPENDIX 4'!E33/'APPENDIX 4'!E$36)*100,0) -> 0 | F33: =IFERROR(('APPENDIX 4'!F33/'APPENDIX 4'!F$36)*100,0) -> 0 | G33: =IFERROR(('APPENDIX 4'!G33/'APPENDIX 4'!G$36)*100,0) -> 2.0748532 | H33: =IFERROR(('APPENDIX 4'!H33/'APPENDIX 4'!H$36)*100,0) -> 0 | I33: =IFERROR(('APPENDIX 4'!I33/'APPENDIX 4'!I$36)*100,0) -> 0 | J33: =IFERROR(('APPENDIX 4'!J33/'APPENDIX 4'!J$36)*100,0) -> 0 | K33: =IFERROR(('APPENDIX 4'!K33/'APPENDIX 4'!K$36)*100,0) -> 1.9511532
B34: ='APPENDIX 6'!B34 -> EAST AFRICA REINSURANCE | C34: =IFERROR(('APPENDIX 4'!C34/'APPENDIX 4'!C$36)*100,0) -> 48.669466 | D34: =IFERROR(('APPENDIX 4'!D34/'APPENDIX 4'!D$36)*100,0) -> 0 | E34: =IFERROR(('APPENDIX 4'!E34/'APPENDIX 4'!E$36)*100,0) -> 0 | F34: =IFERROR(('APPENDIX 4'!F34/'APPENDIX 4'!F$36)*100,0) -> 0 | G34: =IFERROR(('APPENDIX 4'!G34/'APPENDIX 4'!G$36)*100,0) -> 29.550985 | H34: =IFERROR(('APPENDIX 4'!H34/'APPENDIX 4'!H$36)*100,0) -> 0 | I34: =IFERROR(('APPENDIX 4'!I34/'APPENDIX 4'!I$36)*100,0) -> 0 | J34: =IFERROR(('APPENDIX 4'!J34/'APPENDIX 4'!J$36)*100,0) -> 0 | K34: =IFERROR(('APPENDIX 4'!K34/'APPENDIX 4'!K$36)*100,0) -> 30.690803
B35: ='APPENDIX 6'!B35 -> KENYA REINSURANCE CORPORATION | C35: =IFERROR(('APPENDIX 4'!C35/'APPENDIX 4'!C$36)*100,0) -> 51.330534 | D35: =IFERROR(('APPENDIX 4'!D35/'APPENDIX 4'!D$36)*100,0) -> 0 | E35: =IFERROR(('APPENDIX 4'!E35/'APPENDIX 4'!E$36)*100,0) -> 0 | F35: =IFERROR(('APPENDIX 4'!F35/'APPENDIX 4'!F$36)*100,0) -> 0 | G35: =IFERROR(('APPENDIX 4'!G35/'APPENDIX 4'!G$36)*100,0) -> 68.374162 | H35: =IFERROR(('APPENDIX 4'!H35/'APPENDIX 4'!H$36)*100,0) -> 0 | I35: =IFERROR(('APPENDIX 4'!I35/'APPENDIX 4'!I$36)*100,0) -> 0 | J35: =IFERROR(('APPENDIX 4'!J35/'APPENDIX 4'!J$36)*100,0) -> 0 | K35: =IFERROR(('APPENDIX 4'!K35/'APPENDIX 4'!K$36)*100,0) -> 67.358044
B36: TOTAL | C36: =SUM(C33:C35) -> 100 | D36: =SUM(D33:D35) -> 0 | E36: =SUM(E33:E35) -> 0 | F36: =SUM(F33:F35) -> 0 | G36: =SUM(G33:G35) -> 100 | H36: =SUM(H33:H35) -> 0 | I36: =SUM(I33:I35) -> 0 | J36: =SUM(J33:J35) -> 0 | K36: =SUM(K33:K35) -> 100
B37: Figures in %

Sheet APPENDIX 6
B3: =_xlfn.CONCAT('Table of Contents'!B13,": ",'Table of Contents'!C13) -> APPENDIX 6: SUMMARY OF LIFE ASSURANCE BUSINESS REVENUE ACCOUNTS FOR THE PERIOD ENDED 31.03.2025
B4: Company | C4: Life Fund BF | D4: Gross Premium | E4: Net Premium | F4: Other (Fee) Income | G4: Total Benefits | H4: Claims | I4: Surrenders_x000D_ | J4: Bonuses Paid | K4: Annuities Paid | L4: Net Commisions | M4: Expense of Management | N4: Investment Income | O4: Investment Expenses | P4: Transfer To (From) P & L | Q4: Life Fund CF
B5: INSURERS
B6: ABSA LIFE ASSURANCE | C6: 10636609 | D6: 1419720.3 | E6: 1409541.5 | F6: 0 | G6: 451168.12 | H6: 451168.12 | I6: 0 | J6: 0 | K6: 0 | L6: 204810.99 | M6: 87691.463 | N6: 381924.46 | O6: 0 | P6: 0 | Q6: 11684404
B7: APA LIFE ASSURANCE COMPANY | C7: 995078.63 | D7: 140563.62 | E7: 137275.5 | F7: 0 | G7: 49906.008 | H7: 49906.008 | I7: 0 | J7: 0 | K7: 0 | L7: 14935.125 | M7: 32405.377 | N7: 32414.031 | O7: 320.89121 | P7: 0 | Q7: 1067200.8
B8: BRITAM LIFE ASSURANCE | C8: 43886184 | D8: 2845011 | E8: 2843523.8 | F8: -15078.871 | G8: 2025235.4 | H8: 2025235.4 | I8: 0 | J8: 0 | K8: 0 | L8: 377857.62 | M8: 577779.63 | N8: 2646290.5 | O8: 35659.441 | P8: 108220.34 | Q8: 46236167
B9: CANNON LIFE ASSURANCE (K) LIMITED | C9: 527806.79 | D9: 6556.598 | E9: 6398.732 | F9: 0 | G9: 19258.763 | H9: 19258.763 | I9: 0 | J9: 0 | K9: 0 | L9: -328.957 | M9: 15355.272 | N9: 11144.338 | O9: 0 | P9: 0 | Q9: 511064.78
B10: CAPEX LIFE ASSURANCE COMPANY | C10: 33226.715 | D10: 7679.969 | E10: 7679.969 | F10: 0 | G10: 1174.0861 | H10: 1174.0861 | I10: 0 | J10: 0 | K10: 0 | L10: 414.18722 | M10: 2069.9568 | N10: 270.56587 | O10: 0 | P10: 0 | Q10: 37519.02
B11: CIC LIFE ASSURANCE COMPANY | C11: 5139412.2 | D11: 325786.32 | E11: 304364.72 | F11: 0 | G11: 211040.38 | H11: 211040.38 | I11: 0 | J11: 0 | K11: 0 | L11: 42444.646 | M11: 76054.005 | N11: 113755.69 | O11: 0 | P11: 0 | Q11: 5227993.6
B12: CORPORATE INSURANCE COMPANY | C12: 73832.62 | D12: 8452.4385 | E12: 8452.4385 | F12: 0 | G12: 51459.937 | H12: 51459.937 | I12: 0 | J12: 0 | K12: 0 | L12: 0 | M12: 1795.0758 | N12: 0 | O12: 0 | P12: 0 | Q12: 29030.046
B13: EQUITY LIFE ASSURANCE | C13: 0 | D13: 0 | E13: 0 | F13: 0 | G13: 0 | H13: 0 | I13: 0 | J13: 0 | K13: 0 | L13: 0 | M13: 0 | N13: 0 | O13: 0 | P13: 0 | Q13: 0
B14: GA LIFE ASSURANCE COMPANY | C14: 4094574 | D14: 18244.757 | E14: 18244.757 | F14: 0 | G14: 16018.311 | H14: 16018.311 | I14: 0 | J14: 0 | K14: 0 | L14: 258 | M14: 75.1867 | N14: 314280.72 | O14: 0 | P14: 0 | Q14: 4410747.9
B15: GEMINIA LIFE INSURANCE COMPANY | C15: 423624.61 | D15: 17232.776 | E15: 17232.776 | F15: 0 | G15: 17219.716 | H15: 17219.716 | I15: 0 | J15: 0 | K15: 0 | L15: 2452.1477 | M15: 7178.0856 | N15: 6146.895 | O15: 0 | P15: 0 | Q15: 420154.33
B16: ICEA LION LIFE ASSURANCE | C16: 22398339 | D16: 1863890.6 | E16: 1844086.3 | F16: 0 | G16: 950476.66 | H16: 766843.57 | I16: 183633.09 | J16: 0 | K16: 0 | L16: 361276.98 | M16: 341572.81 | N16: 777397.74 | O16: 0 | P16: 0 | Q16: 23366497
B17: JUBILEE LIFE INSURANCE | C17: 13044508 | D17: 1698033.3 | E17: 1693593.4 | F17: 0 | G17: 1194266.8 | H17: 1194266.8 | I17: 0 | J17: 0 | K17: 0 | L17: 213878.19 | M17: 183235.76 | N17: 1091820.5 | O17: 3952.5977 | P17: 0 | Q17: 14234588
... B30: THE MONARCH INSURANCE | C30: 0 | D30: 0 | E30: 0 | F30: 0 | G30: 0 | H30: 0 | I30: 0 | J30: 0 | K30: 0 | L30: 0 | M30: 0 | N30: 0 | O30: 0 | P30: 0 | Q30: 0
B31: TOTAL | C31: =SUM(C6:C30) -> 1.5416208e+08 | D31: =SUM(D6:D30) -> 11796272 | E31: =SUM(E6:E30) -> 11668238 | F31: =SUM(F6:F30) -> 51704.138 | G31: =SUM(G6:G30) -> 7413025.3 | H31: =SUM(H6:H30) -> 7246710.9 | I31: =SUM(I6:I30) -> 183633.09 | J31: =SUM(J6:J30) -> -17318.718 | ... Q31: =SUM(Q6:Q30) -> 1.6105419e+08
B32: REINSURERS
B33: CONTINENTAL REINSURANCE | C33: 0 | D33: 0 | E33: 0 | F33: 0 | G33: 0 | H33: 0 | I33: 0 | J33: 0 | K33: 0 | L33: 0 | M33: 0 | N33: 0 | O33: 0 | P33: 0 | Q33: 0
B34: EAST AFRICA REINSURANCE | C34: 139860.33 | D34: 34147.043 | E34: 28491.054 | F34: 0 | G34: 7061.0911 | H34: 7061.0911 | I34: 0 | J34: 0 | K34: 0 | L34: 7359.1425 | M34: 1989.7898 | N34: 6229.956 | O34: 279.72185 | P34: 0 | Q34: 157891.6
B35: KENYA REINSURANCE CORPORATION | C35: 430383.33 | D35: 36014.078 | E35: 36014.078 | F35: 0 | G35: 607.114 | H35: 607.114 | I35: 0 | J35: 0 | K35: 0 | L35: 17610.706 | M35: 13108.819 | N35: 9357.049 | O35: 0 | P35: 0 | Q35: 444427.82
B36: TOTAL | C36: =SUM(C33:C35) -> 570243.66 | D36: =SUM(D33:D35) -> 70161.121 | E36: =SUM(E33:E35) -> 64505.132 | F36: =SUM(F33:F35) -> 0 | G36: =SUM(G33:G35) -> 7668.2051 | H36: =SUM(H33:H35) -> 7668.2051 | I36: =SUM(I33:I35) -> 0 | J36: =SUM(J33:J35) -> 0 | ... Q36: =SUM(Q33:Q35) -> 602319.42
B37: Amounts in Thousand Shillings
C38: =C36+C31 -> 1.5473232e+08 | D38: =D36+D31 -> 11866434 | E38: =E36+E31 -> 11732743 | F38: =F36+F31 -> 51704.138 | G38: =G36+G31 -> 7420693.5 | H38: =H36+H31 -> 7254379.1 | I38: =I36+I31 -> 183633.09 | J38: =J36+J31 -> -17318.718 | ... Q38: =Q36+Q31 -> 1.6165651e+08

Sheet APPENDIX 7
B3: =_xlfn.CONCAT('Table of Contents'!B14,": ",'Table of Contents'!C14) -> APPENDIX 7: SUMMARY OF ANNUITIES BUSINESS REVENUE ACCOUNTS FOR THE PERIOD ENDED 31.03.2025
B4: Company | C4: Life Fund BF | D4: Gross Premium | E4: Net Premium | F4: Other (Fee) Income | G4: Total Benefits | H4: Claims | I4: Surrenders_x000D_ | J4: Bonuses Paid | K4: Annuities Paid | L4: Net Commisions | M4: Expense of Management | N4: Investment Income | O4: Investment Expenses | P4: Transfer To (From) P & L | Q4: Life Fund CF
B5: INSURERS
B6: ABSA LIFE ASSURANCE | C6: 0 | D6: 0 | E6: 0 | F6: 0 | G6: 0 | H6: 0 | I6: 0 | J6: 0 | K6: 0 | L6: 0 | M6: 0 | N6: 0 | O6: 0 | P6: 0 | Q6: 0
B7: APA LIFE ASSURANCE COMPANY | C7: 1015040.1 | D7: 18694.998 | E7: 18694.998 | F7: 0 | G7: 40603.681 | H7: 40603.681 | I7: 0 | J7: 0 | K7: 0 | L7: 0 | M7: 2218.2519 | N7: 14052.191 | O7: 55.754074 | P7: 0 | Q7: 1004909.6
B8: BRITAM LIFE ASSURANCE | C8: 24059616 | D8: 1516175.6 | E8: 1516175.6 | F8: 0 | G8: 787650.57 | H8: 787650.57 | I8: 0 | J8: 0 | K8: 0 | L8: 30046.709 | M8: 20486.333 | N8: 2987463.3 | O8: 9066.6004 | P8: 22856.322 | Q8: 27693149
B9: CANNON LIFE ASSURANCE (K) LIMITED | C9: 11532.723 | D9: 0 | E9: 0 | F9: 0 | G9: 327.37725 | H9: 327.37725 | I9: 0 | J9: 0 | K9: 0 | L9: 0 | M9: 0 | N9: 0 | O9: 0 | P9: 0 | Q9: 11205.346
B10: CAPEX LIFE ASSURANCE COMPANY | C10: 862965.63 | D10: 127646.8 | E10: 127646.8 | F10: 0 | G10: 106748.06 | H10: 106748.06 | I10: 0 | J10: 0 | K10: 0 | L10: 6400.2924 | M10: 34404.227 | N10: 4497.0066 | O10: 0 | P10: 0 | Q10: 847556.85
B11: CIC LIFE ASSURANCE COMPANY | C11: 1829277.5 | D11: 119075.01 | E11: 119075.01 | F11: 0 | G11: 85608.618 | H11: 85608.618 | I11: 0 | J11: 0 | K11: 0 | L11: 2115.121 | M11: 5963.6513 | N11: 69925.733 | O11: 0 | P11: 0 | Q11: 1924590.9
B12: CORPORATE INSURANCE COMPANY | C12: 0 | D12: 0 | E12: 0 | F12: 0 | G12: 0 | H12: 0 | I12: 0 | J12: 0 | K12: 0 | L12: 0 | M12: 0 | N12: 0 | O12: 0 | P12: 0 | Q12: 0
B13: EQUITY LIFE ASSURANCE | C13: 0 | D13: 0 | E13: 0 | F13: 0 | G13: 0 | H13: 0 | I13: 0 | J13: 0 | K13: 0 | L13: 0 | M13: 0 | N13: 0 | O13: 0 | P13: 0 | Q13: 0
B14: GA LIFE ASSURANCE COMPANY | C14: 0 | D14: 0 | E14: 0 | F14: 0 | G14: 0 | H14: 0 | I14: 0 | J14: 0 | K14: 0 | L14: 0 | M14: 0 | N14: 0 | O14: 0 | P14: 0 | Q14: 0
B15: GEMINIA LIFE INSURANCE COMPANY | C15: 0 | D15: 0 | E15: 0 | F15: 0 | G15: 0 | H15: 0 | I15: 0 | J15: 0 | K15: 0 | L15: 0 | M15: 0 | N15: 0 | O15: 0 | P15: 0 | Q15: 0
B16: ICEA LION LIFE ASSURANCE | C16: 22651302 | D16: 518127.29 | E16: 518127.29 | F16: 0 | G16: 644708.92 | H16: 20312.706 | I16: 0 | J16: 0 | K16: 624396.22 | L16: 8225.4073 | M16: 11418.054 | N16: 2275980.1 | O16: 0 | P16: 0 | Q16: 24781057
B17: JUBILEE LIFE INSURANCE | C17: 12997600 | D17: 577366.4 | E17: 577366.4 | F17: 0 | G17: 414386.22 | H17: 414386.22 | I17: 0 | J17: 0 | K17: 0 | L17: 9784.612 | M17: 2854.494 | N17: 1327119.4 | O17: 3646.73 | P17: 0 | Q17: 14471414
... B30: THE MONARCH INSURANCE | C30: 0 | D30: 0 | E30: 0 | F30: 0 | G30: 0 | H30: 0 | I30: 0 | J30: 0 | K30: 0 | L30: 0 | M30: 0 | N30: 0 | O30: 0 | P30: 0 | Q30: 0
B31: TOTAL | C31: =SUM(C6:C30) -> 95757120 | D31: =SUM(D6:D30) -> 3292672.4 | E31: =SUM(E6:E30) -> 3292672.4 | F31: =SUM(F6:F30) -> 0 | G31: =SUM(G6:G30) -> 3157213.5 | H31: =SUM(H6:H30) -> 2526072.5 | I31: =SUM(I6:I30) -> 0 | J31: =SUM(J6:J30) -> 6744.7092 | ... Q31: =SUM(Q6:Q30) -> 1.0464428e+08
B32: REINSURERS
B33: CONTINENTAL REINSURANCE | C33: 0 | D33: 0 | E33: 0 | F33: 0 | G33: 0 | H33: 0 | I33: 0 | J33: 0 | K33: 0 | L33: 0 | M33: 0 | N33: 0 | O33: 0 | P33: 0 | Q33: 0
B34: EAST AFRICA REINSURANCE | C34: 0 | D34: 0 | E34: 0 | F34: 0 | G34: 0 | H34: 0 | I34: 0 | J34: 0 | K34: 0 | L34: 0 | M34: 0 | N34: 0 | O34: 0 | P34: 0 | Q34: 0
B35: KENYA REINSURANCE CORPORATION | C35: 0 | D35: 0 | E35: 0 | F35: 0 | G35: 0 | H35: 0 | I35: 0 | J35: 0 | K35: 0 | L35: 0 | M35: 0 | N35: 0 | O35: 0 | P35: 0 | Q35: 0
B36: TOTAL | C36: =SUM(C33:C35) -> 0 | D36: =SUM(D33:D35) -> 0 | E36: =SUM(E33:E35) -> 0 | F36: =SUM(F33:F35) -> 0 | G36: =SUM(G33:G35) -> 0 | H36: =SUM(H33:H35) -> 0 | I36: =SUM(I33:I35) -> 0 | J36: =SUM(J33:J35) -> 0 | ... Q36: =SUM(Q33:Q35) -> 0
B37: Amounts in Thousand Shillings

Sheet APPENDIX 8
B3: =_xlfn.CONCAT('Table of Contents'!B15,": ",'Table of Contents'!C15) -> APPENDIX 8: SUMMARY OF GROUP LIFE BUSINESS REVENUE ACCOUNTS FOR THE PERIOD ENDED 31.03.2025
B4: Company | C4: Life Fund BF | D4: Gross Premium | E4: Net Premium | F4: Other (Fee) Income | G4: Total Benefits | H4: Claims | I4: Surrenders_x000D_ | J4: Bonuses Paid | K4: Annuities Paid | L4: Net Commisions | M4: Expense of Management | N4: Investment Income | O4: Investment Expenses | P4: Transfer To (From) P & L | Q4: Life Fund CF
B5: INSURERS
B6: ABSA LIFE ASSURANCE | C6: 454028.71 | D6: 1397419.6 | E6: 645621.89 | F6: 0 | G6: 665879.69 | H6: 665879.69 | I6: 0 | J6: 0 | K6: 0 | L6: 32555.169 | M6: 106292.68 | N6: 12669.187 | O6: 0 | P6: 0 | Q6: 307592.25
B7: APA LIFE ASSURANCE COMPANY | C7: 639163.48 | D7: 750660.01 | E7: 213990.34 | F7: 0 | G7: 92797.424 | H7: 92797.424 | I7: 0 | J7: 0 | K7: 0 | L7: -59731.331 | M7: 54607.722 | N7: 60340.593 | O7: 2238.6926 | P7: 0 | Q7: 823581.91
B8: BRITAM LIFE ASSURANCE | C8: 2772767 | D8: 500832.27 | E8: 288136.79 | F8: 0 | G8: 118450.09 | H8: 118450.09 | I8: 0 | J8: 0 | K8: 0 | L8: -73739.994 | M8: 83358.407 | N8: 144439.08 | O8: -80.92076 | P8: 137101.29 | Q8: 2940254
B9: CANNON LIFE ASSURANCE (K) LIMITED | C9: 168205.61 | D9: 226335.44 | E9: 162537.25 | F9: 0 | G9: 23117.277 | H9: 23117.277 | I9: 0 | J9: 0 | K9: 0 | L9: 16799.638 | M9: 28804.936 | N9: 20905.648 | O9: 0 | P9: 0 | Q9: 282926.66
B10: CAPEX LIFE ASSURANCE COMPANY | C10: 335333.11 | D10: 200062.22 | E10: 140222.29 | F10: 0 | G10: 96013.963 | H10: 96013.963 | I10: 0 | J10: 0 | K10: 0 | L10: 57444.104 | M10: 53922.119 | N10: 7048.2073 | O10: 0 | P10: 0 | Q10: 275223.42
B11: CIC LIFE ASSURANCE COMPANY | C11: 1654152.2 | D11: 388787.88 | E11: 1322650 | F11: 0 | G11: 147787.29 | H11: 147787.29 | I11: 0 | J11: 0 | K11: 0 | L11: -180283.35 | M11: 103732.13 | N11: 297004.79 | O11: 0 | P11: 0 | Q11: 3202571
B12: CORPORATE INSURANCE COMPANY | C12: 0 | D12: 0 | E12: 0 | F12: 0 | G12: 0 | H12: 0 | I12: 0 | J12: 0 | K12: 0 | L12: 0 | M12: 0 | N12: 0 | O12: 0 | P12: 0 | Q12: 0
B13: EQUITY LIFE ASSURANCE | C13: 587628.71 | D13: 574687.98 | E13: 193862.11 | F13: 0 | G13: 21004.975 | H13: 21004.975 | I13: 0 | J13: 0 | K13: 0 | L13: -82823.103 | M13: 13439.96 | N13: 81534.865 | O13: 0 | P13: 0 | Q13: 911403.86
B14: GA LIFE ASSURANCE COMPANY | C14: 27060.958 | D14: 34320.526 | E14: 1976.779 | F14: 0 | G14: 1481.6327 | H14: 1481.6327 | I14: 0 | J14: 0 | K14: 0 | L14: -24583.933 | M14: 6319.5804 | N14: 959.23479 | O14: 0 | P14: 0 | Q14: 46779.692
B15: GEMINIA LIFE INSURANCE COMPANY | C15: 1007272.1 | D15: 122624.96 | E15: 90886.962 | F15: 0 | G15: 131199.95 | H15: 131199.95 | I15: 0 | J15: 0 | K15: 0 | L15: 13773.206 | M15: 46331.28 | N15: 0 | O15: 0 | P15: 0 | Q15: 906854.67
B16: ICEA LION LIFE ASSURANCE | C16: 433367.02 | D16: 186560.47 | E16: 100977.86 | F16: 0 | G16: 35627.835 | H16: 35627.835 | I16: 0 | J16: 0 | K16: 0 | L16: -7528.4667 | M16: 38974.28 | N16: 13069.638 | O16: 0 | P16: 0 | Q16: 480340.87
B17: JUBILEE LIFE INSURANCE | C17: 747633.55 | D17: 420477.76 | E17: 185931.17 | F17: 0 | G17: 119419.83 | H17: 119419.83 | I17: 0 | J17: 0 | K17: 0 | L17: -8395.651 | M17: 34178.713 | N17: 41870.618 | O17: 348.57769 | P17: 0 | Q17: 829883.86
... B30: THE MONARCH INSURANCE | C30: 0 | D30: 0 | E30: 0 | F30: 0 | G30: 0 | H30: 0 | I30: 0 | J30: 0 | K30: 0 | L30: 0 | M30: 0 | N30: 0 | O30: 0 | P30: 0 | Q30: 0
B31: TOTAL | C31: =SUM(C6:C30) -> 15381348 | D31: =SUM(D6:D30) -> 7163503.3 | E31: =SUM(E6:E30) -> 4925860 | F31: =SUM(F6:F30) -> -211950.23 | G31: =SUM(G6:G30) -> 2305916.8 | H31: =SUM(H6:H30) -> 2146998.9 | I31: =SUM(I6:I30) -> 0 | J31: =SUM(J6:J30) -> 158917.94 | ... Q31: =SUM(Q6:Q30) -> 18178817
B32: REINSURERS
B33: CONTINENTAL REINSURANCE | C33: 0 | D33: 22961.78 | E33: 22961.78 | F33: 0 | G33: 16283.717 | H33: 16283.717 | I33: 0 | J33: 0 | K33: 0 | L33: 7104.372 | M33: 1924.579 | N33: 16974.278 | O33: 0 | P33: 0 | Q33: 14623.39
B34: EAST AFRICA REINSURANCE | C34: 1039475.6 | D34: 327031.9 | E34: 272863.56 | F34: 0 | G34: 142805.84 | H34: 142805.84 | I34: 0 | J34: 0 | K34: 0 | L34: 70479.731 | M34: 19056.548 | N34: 59665.324 | O34: 2678.9427 | P34: 0 | Q34: 1136983.4
