Workbook
Name Appendix_1_Range: 'APPENDIX 1'!$B$3:$T$50
Name Appendix_10_Range: 'APPENDIX 10'!$B$3:$Q$34
Name Appendix_11_Range: 'APPENDIX 11'!$B$3:$Q$34
Name Appendix_12_Range: 'APPENDIX 12'!$B$3:$Q$34
Name Appendix_13_Range: 'APPENDIX 13'!$B$3:$Q$34
Name Appendix_14_Range: 'APPENDIX 14'!$B$3:$Q$34
Name Appendix_15_Range: 'APPENDIX 15'!$B$3:$Q$34
Name Appendix_16_Range: 'APPENDIX 16'!$B$3:$Q$34
Name Appendix_17_Range: 'APPENDIX 17'!$B$3:$Q$33
Name Appendix_18_Range: 'APPENDIX 18'!$B$3:$R$49
Name Appendix_19_Range: 'APPENDIX 19'!$B$3:$Q$49
Name Appendix_2_Range: 'APPENDIX 2'!$B$3:$T$35
Name Appendix_20_Range: 'APPENDIX 20'!$B$3:$Q$49
Name Appendix_21_Range: 'APPENDIX 21'!$B$3:$Q$49
Name Appendix_22_Range: 'APPENDIX 22'!$B$3:$Q$49
Name Appendix_23_Range: 'APPENDIX 23'!$B$3:$Q$49
Name Appendix_24_Range: 'APPENDIX 24'!$B$3:$L$35
Name Appendix_25_Range: 'APPENDIX 25'!$B$3:$Q$13
Name Appendix_3_Range: 'APPENDIX 3'!$B$3:$T$13
Name Appendix_4i_Range: 'APPENDIX 4 i'!$B$4:$K$46
Name Appendix_4ii_Range: 'APPENDIX 4 ii'!$B$3:$K$46
Name Appendix_4iii_Range: 'APPENDIX 4 iii'!$B$3:$L$46
Name Appendix_5i_Range: 'APPENDIX 5 i'!$B$4:$L$44
Name Appendix_5ii_Range: 'APPENDIX 5 ii'!$B$3:$L$44
Name Appendix_5iii_Range: 'APPENDIX 5 iii'!$B$3:$M$44
Name Appendix_5iv_Range: 'APPENDIX 5 iv'!$B$3:$N$44
Name Appendix_6i_Range: 'APPENDIX 6'!$B$4:$I$44
Name Appendix_7_Range: 'APPENDIX 7'!$B$3:$L$34
Name Appendix_8_Range: 'APPENDIX 8'!$B$3:$K$34
Name Appendix_9_Range: 'APPENDIX 9'!$B$3:$Q$34
Name Details_Range: Details!$C$2:$J$21
Name Reliances_and_Limitations: 'Reliance & Limitations'!$A$2:$G$8
Name Table_of_Contents: 'Table of Contents'!$A$1:$D$37

Sheet Details
E6: INSURANCE REGULATORY AUTHORITY
E11: TYPE OF INDUSTRY STATISTICS | F11: Quarterly (Unaudited)
E13: QUARTER | F13: 1
E15: YEAR | F15: 2026
E18: PERIOD ENDED | F18: 31.03.2026

Sheet Reliance & Limitations
B3: RELIANCE AND LIMITATIONS
B4: The insurance information contained in this workbook has been extracted from the quarterly unaudited returns submitted to the Authority in line with Section 54 of the Insurance Act. No adjustments have been made to the returns’ data except where necessary in consultation with the affected insurer(s) or reinsurer(s). The publication of any summary of the returns in this report does not necessarily mean that the returns so summarized have satisfied all the requirements of the Insurance Act, or that the Commissioner of Insurance approves the accuracy or the contents of the returns Where necessary, figures have been adjusted to eliminate errors in totals due to rounding off, and are given in thousands Kenya Shillings (‘000’ KES) except where otherwise stated. The report incorporates data from all insurers and reinsurers except for, Definite Assurance Company, The Kenyan Alliance Insurance Company Limited- General, The Monarch Insurance Company Limited- General, The Kenyan Alliance Insurance Company Limited- Life, The Monarch Insurance Company Limited-Life, Star Discover Micro Insurance Limited and Birdview Micro Insurance due to non-compliance with the submission requirements

Sheet Table of Contents
B3: INSURANCE REGULATORY AUTHORITY
B5: =Details!F15&" QUARTER"&" "&Details!F13&" "&"STATISTICS" -> 2026 QUARTER 1 STATISTICS
B6: TABLE OF CONTENTS
B7: Link | C7: Description
B8: APPENDIX 1 | C8: =_xlfn.CONCAT("SUMMARY OF GENERAL INSURANCE BUSINESS PROFIT & LOSS ACCOUNTS FOR THE PERIOD ENDED"," ",Details!F18) -> SUMMARY OF GENERAL INSURANCE BUSINESS PROFIT & LOSS ACCOUNTS FOR THE PERIOD ENDED 31.03.2026
B9: APPENDIX 2 | C9: =_xlfn.CONCAT("SUMMARY OF LONG TERM INSURANCE BUSINESS PROFIT & LOSS ACCOUNTS FOR THE PERIOD ENDED"," ",Details!$F$18) -> SUMMARY OF LONG TERM INSURANCE BUSINESS PROFIT & LOSS ACCOUNTS FOR THE PERIOD ENDED 31.03.2026
B10: APPENDIX 3 | C10: =_xlfn.CONCAT("SUMMARY OF MICRO INSURANCE BUSINESS PROFIT & LOSS ACCOUNTS FOR THE PERIOD ENDED"," ",Details!$F$18) -> SUMMARY OF MICRO INSURANCE BUSINESS PROFIT & LOSS ACCOUNTS FOR THE PERIOD ENDED 31.03.2026
B11: APPENDIX 4 i | C11: =_xlfn.CONCAT("SUMMARY OF LONG TERM INSURANCE BUSINESS BALANCE SHEETS AS AT"," ",Details!F18) -> SUMMARY OF LONG TERM INSURANCE BUSINESS BALANCE SHEETS AS AT 31.03.2026
B12: APPENDIX 4 ii | C12: =_xlfn.CONCAT("SUMMARY OF LONG TERM INSURANCE BUSINESS BALANCE SHEETS AS AT"," ",Details!F18) -> SUMMARY OF LONG TERM INSURANCE BUSINESS BALANCE SHEETS AS AT 31.03.2026
B13: APPENDIX 4 iii | C13: =_xlfn.CONCAT("SUMMARY OF LONG TERM INSURANCE BUSINESS BALANCE SHEETS AS AT"," ",Details!F18) -> SUMMARY OF LONG TERM INSURANCE BUSINESS BALANCE SHEETS AS AT 31.03.2026
B14: APPENDIX 5 i | C14: =_xlfn.CONCAT("SUMMARY OF GENERAL INSURANCE BUSINESS BALANCE SHEETS AS AT"," ",Details!F18) -> SUMMARY OF GENERAL INSURANCE BUSINESS BALANCE SHEETS AS AT 31.03.2026
B15: APPENDIX 5 ii | C15: =_xlfn.CONCAT("SUMMARY OF GENERAL INSURANCE BUSINESS BALANCE SHEETS AS AT"," ",Details!F18) -> SUMMARY OF GENERAL INSURANCE BUSINESS BALANCE SHEETS AS AT 31.03.2026
B16: APPENDIX 5 iii | C16: =_xlfn.CONCAT("SUMMARY OF GENERAL INSURANCE BUSINESS BALANCE SHEETS AS AT"," ",Details!F18) -> SUMMARY OF GENERAL INSURANCE BUSINESS BALANCE SHEETS AS AT 31.03.2026
B17: APPENDIX 5 iv | C17: =_xlfn.CONCAT("SUMMARY OF GENERAL INSURANCE BUSINESS BALANCE SHEETS AS AT"," ",Details!F18) -> SUMMARY OF GENERAL INSURANCE BUSINESS BALANCE SHEETS AS AT 31.03.2026
B18: APPENDIX 6 | C18: =_xlfn.CONCAT("SUMMARY OF MICRO INSURANCE BUSINESS BALANCE SHEETS AS AT"," ",Details!F18) -> SUMMARY OF MICRO INSURANCE BUSINESS BALANCE SHEETS AS AT 31.03.2026
B19: APPENDIX 7 | C19: =_xlfn.CONCAT("SUMMARY OF LONG TERM INSURANCE BUSINESS GROSS PREMIUM INCOME FOR THE PERIOD ENDED"," ",Details!F18) -> SUMMARY OF LONG TERM INSURANCE BUSINESS GROSS PREMIUM INCOME FOR THE PERIOD ENDED 31.03.2026
B20: APPENDIX 8 | C20: =_xlfn.CONCAT("SUMMARY OF LONG TERM INSURANCE BUSINESS MARKET SHARE PER CLASS FOR THE PERIOD ENDED"," ",Details!F18) -> SUMMARY OF LONG TERM INSURANCE BUSINESS MARKET SHARE PER CLASS FOR THE PERIOD ENDED 31.03.2026
B21: APPENDIX 9 | C21: =_xlfn.CONCAT("SUMMARY OF LIFE ASSURANCE BUSINESS REVENUE ACCOUNTS FOR THE PERIOD ENDED"," ",Details!F18) -> SUMMARY OF LIFE ASSURANCE BUSINESS REVENUE ACCOUNTS FOR THE PERIOD ENDED 31.03.2026
B22: APPENDIX 10 | C22: =_xlfn.CONCAT("SUMMARY OF ANNUITIES BUSINESS REVENUE ACCOUNTS FOR THE PERIOD ENDED"," ",Details!F18) -> SUMMARY OF ANNUITIES BUSINESS REVENUE ACCOUNTS FOR THE PERIOD ENDED 31.03.2026
B23: APPENDIX 11 | C23: =_xlfn.CONCAT("SUMMARY OF GROUP LIFE BUSINESS REVENUE ACCOUNTS FOR THE PERIOD ENDED"," ",Details!F18) -> SUMMARY OF GROUP LIFE BUSINESS REVENUE ACCOUNTS FOR THE PERIOD ENDED 31.03.2026
B24: APPENDIX 12 | C24: =_xlfn.CONCAT("SUMMARY OF GROUP CREDIT BUSINESS REVENUE ACCOUNTS FOR THE PERIOD ENDED"," ",Details!F18) -> SUMMARY OF GROUP CREDIT BUSINESS REVENUE ACCOUNTS FOR THE PERIOD ENDED 31.03.2026
B25: APPENDIX 13 | C25: =_xlfn.CONCAT("SUMMARY OF INVESTMENTS BUSINESS REVENUE ACCOUNTS FOR THE PERIOD ENDED"," ",Details!F18) -> SUMMARY OF INVESTMENTS BUSINESS REVENUE ACCOUNTS FOR THE PERIOD ENDED 31.03.2026
B26: APPENDIX 14 | C26: =_xlfn.CONCAT("SUMMARY OF PERMANENT HEALTH BUSINESS REVENUE ACCOUNTS FOR THE PERIOD ENDED"," ",Details!F18) -> SUMMARY OF PERMANENT HEALTH BUSINESS REVENUE ACCOUNTS FOR THE PERIOD ENDED 31.03.2026
B27: APPENDIX 15 | C27: =_xlfn.CONCAT("SUMMARY OF PERSONAL PENSIONS BUSINESS REVENUE ACCOUNTS FOR THE PERIOD ENDED"," ",Details!F18) -> SUMMARY OF PERSONAL PENSIONS BUSINESS REVENUE ACCOUNTS FOR THE PERIOD ENDED 31.03.2026
B28: APPENDIX 16 | C28: =_xlfn.CONCAT("SUMMARY OF DEPOSIT ADMINISTRATION BUSINESS REVENUE ACCOUNTS FOR THE PERIOD ENDED"," ",Details!F18) -> SUMMARY OF DEPOSIT ADMINISTRATION BUSINESS REVENUE ACCOUNTS FOR THE PERIOD ENDED 31.03.2026
B29: APPENDIX 17 | C29: =_xlfn.CONCAT("SUMMARY OF COMBINED LONG TERM BUSINESS REVENUE ACCOUNTS FOR THE PERIOD ENDED"," ",Details!F18) -> SUMMARY OF COMBINED LONG TERM BUSINESS REVENUE ACCOUNTS FOR THE PERIOD ENDED 31.03.2026
B30: APPENDIX 18 | C30: =_xlfn.CONCAT("SUMMARY OF GROSS PREMIUM INCOME UNDER GENERAL INSURANCE BUSINESS FOR THE PERIOD ENDED"," ",Details!$F$18) -> SUMMARY OF GROSS PREMIUM INCOME UNDER GENERAL INSURANCE BUSINESS FOR THE PERIOD ENDED 31.03.2026
B31: APPENDIX 19 | C31: =_xlfn.CONCAT("SUMMARY OF GENERAL INSURANCE BUSINESS MARKET SHARE PER CLASS FOR THE PERIOD ENDED"," ",Details!$F$18) -> SUMMARY OF GENERAL INSURANCE BUSINESS MARKET SHARE PER CLASS FOR THE PERIOD ENDED 31.03.2026
B32: APPENDIX 20 | C32: =_xlfn.CONCAT("SUMMARY OF CLAIMS PAID UNDER GENERAL INSURANCE BUSINESS FOR THE PERIOD ENDED"," ",Details!$F$18) -> SUMMARY OF CLAIMS PAID UNDER GENERAL INSURANCE BUSINESS FOR THE PERIOD ENDED 31.03.2026
B33: APPENDIX 21 | C33: =_xlfn.CONCAT("SUMMARY OF CLAIMS INCURRED UNDER GENERAL INSURANCE BUSINESS FOR THE PERIOD ENDED"," ",Details!$F$18) -> SUMMARY OF CLAIMS INCURRED UNDER GENERAL INSURANCE BUSINESS FOR THE PERIOD ENDED 31.03.2026
B34: APPENDIX 22 | C34: =_xlfn.CONCAT("SUMMARY OF INCURRED CLAIMS RATIOS UNDER GENERAL INSURANCE BUSINESS FOR THE PERIOD ENDED"," ",Details!$F$18) -> SUMMARY OF INCURRED CLAIMS RATIOS UNDER GENERAL INSURANCE BUSINESS FOR THE PERIOD ENDED 31.03.2026
B35: APPENDIX 23 | C35: =_xlfn.CONCAT("SUMMARY OF GENERAL INSURANCE BUSINESS REVENUE ACCOUNTS FOR THE PERIOD ENDED"," ",Details!$F$18) -> SUMMARY OF GENERAL INSURANCE BUSINESS REVENUE ACCOUNTS FOR THE PERIOD ENDED 31.03.2026
B36: APPENDIX 24 | C36: =_xlfn.CONCAT("SUMMARY OF BUSINESS RESULTS UNDER MICRO INSURANCE BUSINESS FOR THE PERIOD ENDED"," ",Details!$F$18) -> SUMMARY OF BUSINESS RESULTS UNDER MICRO INSURANCE BUSINESS FOR THE PERIOD ENDED 31.03.2026
B37: APPENDIX 25 | C37: =_xlfn.CONCAT("SUMMARY OF MICROINSURANCE BUSINESS REVENUE ACCOUNTS FOR THE PERIOD ENDED"," ",Details!$F$18) -> SUMMARY OF MICROINSURANCE BUSINESS REVENUE ACCOUNTS FOR THE PERIOD ENDED 31.03.2026

Sheet APPENDIX 1
B3: =_xlfn.CONCAT('Table of Contents'!B8,": ",'Table of Contents'!C8) -> APPENDIX 1: SUMMARY OF GENERAL INSURANCE BUSINESS PROFIT & LOSS ACCOUNTS FOR THE PERIOD ENDED 31.03.2026
B4: Company | C4: Insurance Revenue | D4: Insurance Service Expense | E4: Expenses from reinsurance contracts held | F4: Income from reinsurance contracts held | G4: Net expenses from reinsurance contracts held | H4: Insurance Service Result | I4: Net Investment Income | J4: Finance expenses from insurance contracts | K4: Finance income from reinsurance contracts | L4: Net Financial Result | M4: Asset management services revenue | N4: Other Income | O4: Other finance costs | P4: Other operating expenses | Q4: Share of profit of associates and joint ventures accounted for using the equity method | R4: Profit before income tax | S4: Income tax expense | T4: Profit for the year
B5: INSURERS
B6: AAR INSURANCE KENYA | C6: 3202261.9 | D6: 3036621.4 | E6: 22124.191 | F6: 0 | G6: 22124.191 | H6: 143516.31 | I6: 208160.32 | J6: 0 | K6: 0 | L6: 208160.32 | M6: 0 | N6: 4445.5469 | O6: 3353.5401 | P6: 167211.99 | Q6: 0 | R6: 185556.65 | S6: 46389.163 | T6: 139167.49
B7: AFRICAN MERCHANT ASSURANCE | C7: 800487.62 | D7: 634518.85 | E7: 49863.665 | F7: 151240.22 | G7: -101376.56 | H7: 267345.33 | I7: 45789.717 | J7: 56125.077 | K7: 4890.452 | L7: -5444.9081 | M7: 0 | N7: 0 | O7: 0 | P7: 249033.18 | Q7: 0 | R7: 12867.24 | S7: 0 | T7: 12867.24
B8: APA INSURANCE LIMITED | C8: 4549400.7 | D8: 5603433.7 | E8: -1209741.1 | F8: -341775.45 | G8: -867965.68 | H8: -186067.34 | I8: 601951.92 | J8: 174821.07 | K8: 66016.795 | L8: 493147.64 | M8: 0 | N8: 0 | O8: 5446.5043 | P8: 107884.24 | Q8: 0 | R8: 193749.55 | S8: -84898.094 | T8: 278647.65
B9: BRITAM GENERAL INSURANCE | C9: 3458627.1 | D9: 2756486.5 | E9: 623981.57 | F9: 133911.1 | G9: 490070.47 | H9: 212070.06 | I9: 630122.89 | J9: 434200.69 | K9: 123941.82 | L9: 319864.02 | M9: 0 | N9: 24648.583 | O9: 8211.5912 | P9: 80187.757 | Q9: 0 | R9: 468183.31 | S9: -53.131 | T9: 468236.44
B10: BUPA GLOBAL INSURANCE | C10: 1696347.5 | D10: 1262355.5 | E10: 1027449.5 | F10: 789973.98 | G10: 237475.49 | H10: 196516.45 | I10: 17855.662 | J10: 7634.503 | K10: 6135.509 | L10: 16356.668 | M10: 0 | N10: 0 | O10: 1065.637 | P10: 0 | Q10: 0 | R10: 211807.48 | S10: -1446.204 | T10: 213253.68
B11: CANNON GENERAL INSURANCE | C11: 660128.23 | D11: 501286.28 | E11: 151778.36 | F11: 0 | G11: 151778.36 | H11: 7063.5919 | I11: 23555.661 | J11: 137409.28 | K11: 74194.313 | L11: -39659.311 | M11: 0 | N11: 0 | O11: 0 | P11: 44798.478 | Q11: 0 | R11: -77394.196 | S11: 0 | T11: -77394.196
B12: CIC GENERAL INSURANCE COMPANY | C12: 5156201.8 | D12: 4291089.8 | E12: 0 | F12: -683136.81 | G12: 683136.81 | H12: 181975.16 | I12: 288836.17 | J12: 159414.61 | K12: 38852.052 | L12: 168273.61 | M12: 0 | N12: 89023.816 | O12: 0 | P12: 204312.95 | Q12: 0 | R12: 234959.64 | S12: 70487.893 | T12: 164471.75
B13: DEFINITE ASSURANCE COMPANY | C13: 0 | D13: 0 | E13: 0 | F13: 0 | G13: 0 | H13: 0 | I13: 0 | J13: 0 | K13: 0 | L13: 0 | M13: 0 | N13: 0 | O13: 0 | P13: 0 | Q13: 0 | R13: 0 | S13: 0 | T13: 0
B14: DIRECTLINE ASSURANCE COMPANY | C14: 763980.07 | D14: 667574.48 | E14: 15464.006 | F14: 0 | G14: 15464.006 | H14: 80941.586 | I14: 62690.069 | J14: 572751.86 | K14: 0 | L14: -510061.79 | M14: 0 | N14: 0 | O14: 0 | P14: 5467.809 | Q14: 0 | R14: -434588.02 | S14: 0 | T14: -434588.02
B15: EQUITY GENERAL INSURANCE LIMITED | C15: 245871.04 | D15: 142223.61 | E15: 163325.55 | F15: 114027.21 | G15: 49298.345 | H15: 54349.09 | I15: 36411.339 | J15: 0 | K15: 0 | L15: 36411.339 | M15: 0 | N15: 0 | O15: 0 | P15: 26360.481 | Q15: 0 | R15: 64399.947 | S15: 19319.984 | T15: 45079.963
B16: EQUITY HEALTH INSURANCE LIMITED | C16: 297359.2 | D16: 288381.46 | E16: 2690.6589 | F16: 0 | G16: 2690.6589 | H16: 6287.0782 | I16: 34895.824 | J16: 0 | K16: 0 | L16: 34895.824 | M16: 0 | N16: 0 | O16: 0 | P16: 24558.183 | Q16: 0 | R16: 16624.72 | S16: 4987.4159 | T16: 11637.304
B17: FIDELITY SHIELD INSURANCE | C17: 1285985.4 | D17: 1126437.5 | E17: 161995.9 | F17: 0 | G17: 161995.9 | H17: -2448.0109 | I17: 141318.66 | J17: 20033.672 | K17: 4549.7516 | L17: 125834.74 | M17: 0 | N17: 25956.051 | O17: 0 | P17: 73968.99 | Q17: 0 | R17: 75373.79 | S17: 0 | T17: 75373.79
... B40: THE MONARCH INSURANCE | C40: 0 | D40: 0 | E40: 0 | F40: 0 | G40: 0 | H40: 0 | I40: 0 | J40: 0 | K40: 0 | L40: 0 | M40: 0 | N40: 0 | O40: 0 | P40: 0 | Q40: 0 | R40: 0 | S40: 0 | T40: 0
B41: TOTAL | C41: =SUM(C6:C40) -> 55312561 | D41: =SUM(D6:D40) -> 55655013 | E41: =SUM(E6:E40) -> 5542954.9 | F41: =SUM(F6:F40) -> 6660814.6 | G41: =SUM(G6:G40) -> -1117859.6 | H41: =SUM(H6:H40) -> 775406.89 | I41: =SUM(I6:I40) -> 5174267.4 | J41: =SUM(J6:J40) -> 2837120.4 | ... T41: =SUM(T6:T40) -> 1269468.6
B42: REINSURERS
B43: CONTINENTAL REINSURANCE | C43: 1609409.6 | D43: 1630625.6 | E43: 229289.21 | F43: 395160.31 | G43: -165871.11 | H43: 144655.18 | I43: 59311.322 | J43: 136532.3 | K43: 61954.964 | L43: -15266.015 | M43: 0 | N43: 138.32 | O43: -12104.573 | P43: 9273.035 | Q43: 0 | R43: 132359.03 | S43: 39707.708 | T43: 92651.318
B44: EAST AFRICA REINSURANCE | C44: 1680189.9 | D44: 1482152.9 | E44: 184270.39 | F44: 49360.343 | G44: 134910.05 | H44: 63127.005 | I44: 180013.09 | J44: 30363.298 | K44: 6433.3212 | L44: 156083.11 | M44: 0 | N44: 9489.1519 | O44: 0 | P44: 0 | Q44: 0 | R44: 228699.27 | S44: 57174.817 | T44: 171524.45
B45: GHANA REINSURANCE COMPANY | C45: 645671.68 | D45: 826825.91 | E45: -327932.36 | F45: 0 | G45: -327932.36 | H45: 146778.13 | I45: 53070.601 | J45: 56920.005 | K45: 12649.018 | L45: 8799.6136 | M45: 0 | N45: 32 | O45: -5871.9968 | P45: 24890.213 | Q45: 0 | R45: 136591.53 | S45: 43656.054 | T45: 92935.474
B46: KENYA REINSURANCE CORPORATION | C46: 3266279.4 | D46: 2563104 | E46: 324183.65 | F46: 68356.203 | G46: 255827.45 | H46: 447347.89 | I46: 1014402.3 | J46: 78130.209 | K46: 4806.0969 | L46: 941078.18 | M46: 0 | N46: 14552.346 | O46: -78884.316 | P46: 283582.87 | Q46: 0 | R46: 1198279.9 | S46: 359459.42 | T46: 838820.44
B47: WAICA REINSURANCE KENYA LIMITED | C47: 992776.51 | D47: 685386.9 | E47: 144903.12 | F47: 161262.72 | G47: -16359.594 | H47: 323749.21 | I47: 82495.79 | J47: 98074.797 | K47: 10957.348 | L47: -4621.6594 | M47: 0 | N47: 46.548 | O47: -27064.498 | P47: 102575.24 | Q47: 0 | R47: 243663.36 | S47: 73099.008 | T47: 170564.35
B48: TOTAL | C48: =SUM(C43:C47) -> 8194327.1 | D48: =SUM(D43:D47) -> 7188095.3 | E48: =SUM(E43:E47) -> 554714.01 | F48: =SUM(F43:F47) -> 674139.58 | G48: =SUM(G43:G47) -> -119425.57 | H48: =SUM(H43:H47) -> 1125657.4 | I48: =SUM(I43:I47) -> 1389293.1 | J48: =SUM(J43:J47) -> 400020.61 | ... T48: =SUM(T43:T47) -> 1366496
B49: GRAND TOTAL | C49: =C41+C48 -> 63506888 | D49: =D41+D48 -> 62843109 | E49: =E41+E48 -> 6097669 | F49: =F41+F48 -> 7334954.1 | G49: =G41+G48 -> -1237285.2 | H49: =H41+H48 -> 1901064.3 | I49: =I41+I48 -> 6563560.5 | J49: =J41+J48 -> 3237141 | ... T49: =T41+T48 -> 2635964.6
B50: Amounts in Thousand Shillings

Sheet APPENDIX 2
B3: =_xlfn.CONCAT('Table of Contents'!B9,": ",'Table of Contents'!C9) -> APPENDIX 2: SUMMARY OF LONG TERM INSURANCE BUSINESS PROFIT & LOSS ACCOUNTS FOR THE PERIOD ENDED 31.03.2026
B4: Company | C4: Insurance Revenue | D4: Insurance Service Expense | E4: Finance expenses from insurance contracts | F4: Finance income from reinsurance contracts | G4: Net expenses from reinsurance contracts held | H4: Insurance Service Result | I4: Net Investment Income | J4: Finance expenses from insurance contracts | K4: Finance income from reinsurance contracts | L4: Net Financial Result | M4: Asset management services revenue | N4: Other Income | O4: Other finance costs | P4: Other operating expenses | Q4: Share of profit of associates and joint ventures accounted for using the equity method | R4: Profit before income tax | S4: Income tax expense | T4: Profit for the year
B5: INSURERS
B6: ABSA LIFE ASSURANCE | C6: 2452929 | D6: 2386849 | E6: 76105.12 | F6: 0 | G6: 76105.12 | H6: -10025.137 | I6: 1061506.7 | J6: 937033.31 | K6: 14233.555 | L6: 138706.94 | M6: 0 | N6: 4139.5 | O6: 0 | P6: 73584.076 | Q6: 0 | R6: 59237.228 | S6: 0 | T6: 59237.228
B7: APA LIFE ASSURANCE COMPANY | C7: 1297258.5 | D7: 1049350 | E7: 138992.1 | F7: 0 | G7: 138992.1 | H7: 108916.44 | I7: 1227885.2 | J7: 1028908.9 | K7: 9246.9951 | L7: 208223.36 | M7: 0 | N7: 0 | O7: 0 | P7: 0 | Q7: 0 | R7: 317139.79 | S7: -3440.4889 | T7: 320580.28
B8: BRITAM LIFE ASSURANCE | C8: 3983747.4 | D8: 3305577.7 | E8: -429143.74 | F8: -805082.21 | G8: 375938.47 | H8: 302231.23 | I8: 8980422.6 | J8: 8387009.2 | K8: 57690.59 | L8: 651103.98 | M8: 0 | N8: 3860.959 | O8: 6994.439 | P8: 176281.15 | Q8: 227237.74 | R8: 1001158.3 | S8: 300347.5 | T8: 700810.83
B9: CANNON LIFE ASSURANCE (K) LIMITED | C9: 116599.69 | D9: 153244.89 | E9: 3001.2428 | F9: 0 | G9: 3001.2428 | H9: -39646.441 | I9: 25550.816 | J9: 18525.173 | K9: 50.498751 | L9: 7076.1416 | M9: 0 | N9: 3608.05 | O9: 0 | P9: 1246.8328 | Q9: 0 | R9: -30209.082 | S9: 1628.8964 | T9: -31837.979
B10: CAPEX LIFE ASSURANCE COMPANY | C10: 498694.04 | D10: 478312.69 | E10: 29157.292 | F10: 46481.674 | G10: -17324.382 | H10: 37705.731 | I10: 1351.796 | J10: 15968.959 | K10: 3303.644 | L10: -11313.519 | M10: 0 | N10: 0 | O10: 0 | P10: 5234.486 | Q10: 0 | R10: 21157.726 | S10: 511.705 | T10: 20646.021
B11: CIC LIFE ASSURANCE COMPANY | C11: 1977934.7 | D11: 2053019.4 | E11: 410996.8 | F11: 372456.1 | G11: 38540.7 | H11: -113625.33 | I11: 1514414.9 | J11: 1259479.1 | K11: 25110.505 | L11: 280046.24 | M11: 0 | N11: 42838.783 | O11: 0 | P11: 85507.804 | Q11: 0 | R11: 123751.88 | S11: 0 | T11: 123751.88
B12: EQUITY LIFE ASSURANCE | C12: 619030.47 | D12: 474505.31 | E12: 189613.11 | F12: 230345.32 | G12: -40732.201 | H12: 185257.37 | I12: 983317.98 | J12: 558203.87 | K12: 592.8039 | L12: 425706.92 | M12: 0 | N12: 42083.237 | O12: 0 | P12: 92535.099 | Q12: 0 | R12: 560512.42 | S12: 168153.73 | T12: 392358.69
B13: GA LIFE ASSURANCE COMPANY | C13: 20607.22 | D13: 12342.797 | E13: 10826.751 | F13: 0 | G13: 10826.751 | H13: -2562.3275 | I13: 2136112.6 | J13: 0 | K13: 0 | L13: 2136112.6 | M13: 0 | N13: 311690.45 | O13: 0 | P13: 86299.013 | Q13: 0 | R13: 2358941.7 | S13: 4665.926 | T13: 2354275.7
B14: GEMINIA LIFE INSURANCE COMPANY | C14: 214047.7 | D14: 27952.135 | E14: 36704.587 | F14: 0 | G14: 36704.587 | H14: 149390.98 | I14: 66708.844 | J14: 26329.25 | K14: 0 | L14: 40379.594 | M14: 0 | N14: 0 | O14: 0 | P14: 92796.78 | Q14: 0 | R14: 96973.794 | S14: 5.8267581 | T14: 96967.967
B15: ICEA LION LIFE ASSURANCE | C15: 2264310.3 | D15: 1541593.3 | E15: 107630.24 | F15: 7810.3228 | G15: 99819.914 | H15: 622897.15 | I15: 8685851 | J15: 8183802.4 | K15: 0 | L15: 502048.64 | M15: 0 | N15: 26092.754 | O15: 0 | P15: 101556.57 | Q15: 0 | R15: 1049482 | S15: 314844.72 | T15: 734637.26
B16: JUBILEE LIFE INSURANCE | C16: 1992524.2 | D16: 941163.24 | E16: 203771.76 | F16: 0 | G16: 203771.76 | H16: 847589.24 | I16: 7007526.5 | J16: 6766128 | K16: 0 | L16: 241398.56 | M16: 0 | N16: 0 | O16: 0 | P16: 259127.64 | Q16: 0 | R16: 829860.16 | S16: 0 | T16: 829860.16
B17: KENINDIA ASSURANCE COMPANY | C17: 524489.98 | D17: 505801.43 | E17: 23148.927 | F17: -2709.6587 | G17: 25858.586 | H17: -7170.0395 | I17: 3854466 | J17: 3269396.2 | K17: 0 | L17: 585069.81 | M17: 0 | N17: 0 | O17: 0 | P17: 0 | Q17: 0 | R17: 577899.77 | S17: 0 | T17: 577899.77
... B27: THE MONARCH INSURANCE | C27: 0 | D27: 0 | E27: 0 | F27: 0 | G27: 0 | H27: 0 | I27: 0 | J27: 0 | K27: 0 | L27: 0 | M27: 0 | N27: 0 | O27: 0 | P27: 0 | Q27: 0 | R27: 0 | S27: 0 | T27: 0
B28: TOTAL | C28: =SUM(C6:C27) -> 20886057 | D28: =SUM(D6:D27) -> 17527998 | E28: =SUM(E6:E27) -> 1138620.4 | F28: =SUM(F6:F27) -> -29075.259 | G28: =SUM(G6:G27) -> 1167695.6 | H28: =SUM(H6:H27) -> 2190362.9 | I28: =SUM(I6:I27) -> 39964430 | J28: =SUM(J6:J27) -> 35464493 | ... T28: =SUM(T6:T27) -> 5745304.1
B29: REINSURERS
B30: CONTINENTAL REINSURANCE | C30: 0 | D30: 0 | E30: 0 | F30: 0 | G30: 0 | H30: 0 | I30: 0 | J30: 0 | K30: 0 | L30: 0 | M30: 0 | N30: 0 | O30: 0 | P30: 0 | Q30: 0 | R30: 0 | S30: 0 | T30: 0
B31: EAST AFRICA REINSURANCE | C31: 256732.76 | D31: 217185.15 | E31: 33019.025 | F31: 35505.969 | G31: -2486.9439 | H31: 42034.55 | I31: 67687.47 | J31: 6005.3906 | K31: 977.10648 | L31: 62659.186 | M31: 0 | N31: 2186.8106 | O31: 0 | P31: 0 | Q31: 0 | R31: 106880.55 | S31: -32465.739 | T31: 74414.807
B32: KENYA REINSURANCE CORPORATION | C32: 631050.78 | D32: 783326.62 | E32: 0 | F32: 0 | G32: 24284.519 | H32: -176560.36 | I32: 243322.29 | J32: -17099.385 | K32: -246.54125 | L32: 260175.13 | M32: 0 | N32: 0 | O32: -0.55550396 | P32: 17511.4 | Q32: 0 | R32: 66103.927 | S32: 19831.178 | T32: 46272.749
B33: TOTAL | C33: =SUM(C30:C32) -> 887783.53 | D33: =SUM(D30:D32) -> 1000511.8 | E33: =SUM(E30:E32) -> 33019.025 | F33: =SUM(F30:F32) -> 35505.969 | G33: =SUM(G30:G32) -> 21797.576 | H33: =SUM(H30:H32) -> -134525.81 | I33: =SUM(I30:I32) -> 311009.76 | J33: =SUM(J30:J32) -> -11093.994 | ... T33: =SUM(T30:T32) -> 120687.56
B34: GRAND TOTAL | C34: =C33+C28 -> 21773840 | D34: =D33+D28 -> 18528510 | E34: =E33+E28 -> 1171639.4 | F34: =F33+F28 -> 6430.71 | G34: =G33+G28 -> 1189493.2 | H34: =H33+H28 -> 2055837.1 | I34: =I33+I28 -> 40275440 | J34: =J33+J28 -> 35453399 | ... T34: =T33+T28 -> 5865991.7
B35: Amounts in Thousand Shillings

Sheet APPENDIX 3
B3: =_xlfn.CONCAT('Table of Contents'!B10,": ",'Table of Contents'!C10) -> APPENDIX 3: SUMMARY OF MICRO INSURANCE BUSINESS PROFIT & LOSS ACCOUNTS FOR THE PERIOD ENDED 31.03.2026
B4: Company | C4: Insurance Revenue | D4: Insurance Service Expense | E4: Finance expenses from insurance contracts | F4: Finance income from reinsurance contracts | G4: Net expenses from reinsurance contracts held | H4: Insurance Service Result | I4: Net Investment Income | J4: Finance expenses from insurance contracts | K4: Finance income from reinsurance contracts | L4: Net Financial Result | M4: Asset management services revenue | N4: Other Income | O4: Other finance costs | P4: Other operating expenses | Q4: Share of profit of associates and joint ventures accounted for using the equity method | R4: Profit before income tax | S4: Income tax expense | T4: Profit for the year
B5: INSURERS
B6: APA MICRO INSURANCE | C6: 0 | D6: 0 | E6: 0 | F6: 0 | G6: 0 | H6: 0 | I6: 2181.524 | J6: 0 | K6: 0 | L6: 2181.524 | M6: 0 | N6: 0 | O6: 0 | P6: 0 | Q6: 0 | R6: 2181.524 | S6: 0 | T6: 2181.524
B7: BIRDVIEW MICRO INSURANCE | C7: 0 | D7: 0 | E7: 0 | F7: 0 | G7: 0 | H7: 0 | I7: 0 | J7: 0 | K7: 0 | L7: 0 | M7: 0 | N7: 0 | O7: 0 | P7: 0 | Q7: 0 | R7: 0 | S7: 0 | T7: 0
B8: BRITAM MICRO INSURANCE | C8: 367803.3 | D8: 341934.26 | E8: 26271.107 | F8: 12466.498 | G8: 13804.609 | H8: 12064.43 | I8: 29295.682 | J8: 11603.812 | K8: -259.75681 | L8: 17432.113 | M8: 0 | N8: 1882.022 | O8: 1244.4324 | P8: 14535.733 | Q8: 0 | R8: 15598.399 | S8: 0 | T8: 15598.399
B9: CIC MICRO INSURANCE | C9: 5704.9331 | D9: 16557.839 | E9: 0 | F9: 0 | G9: 0 | H9: -10852.906 | I9: 935.08493 | J9: 0 | K9: 0 | L9: 935.08493 | M9: 0 | N9: 0 | O9: 0 | P9: 5773.6347 | Q9: 0 | R9: -15691.456 | S9: 0 | T9: -15691.456
B10: STAR DISCOVER MICRO INSURANCE | C10: 0 | D10: 0 | E10: 0 | F10: 0 | G10: 0 | H10: 0 | I10: 0 | J10: 0 | K10: 0 | L10: 0 | M10: 0 | N10: 0 | O10: 0 | P10: 0 | Q10: 0 | R10: 0 | S10: 0 | T10: 0
B11: TURACO MICRO INSURANCE | C11: 132624.78 | D11: 74251.727 | E11: 0 | F11: 0 | G11: 0 | H11: 58373.054 | I11: 3207.863 | J11: 0 | K11: 0 | L11: 3207.863 | M11: 0 | N11: 0 | O11: 0 | P11: 15197.956 | Q11: 0 | R11: 46382.961 | S11: 13644.849 | T11: 32738.111
B12: TOTAL | C12: =SUM(C6:C11) -> 506133.01 | D12: =SUM(D6:D11) -> 432743.82 | E12: =SUM(E6:E11) -> 26271.107 | F12: =SUM(F6:F11) -> 12466.498 | G12: =SUM(G6:G11) -> 13804.609 | H12: =SUM(H6:H11) -> 59584.578 | I12: =SUM(I6:I11) -> 35620.154 | J12: =SUM(J6:J11) -> 11603.812 | ... T12: =SUM(T6:T11) -> 34826.579
B13: Amounts in Thousand Shillings

Sheet APPENDIX 4 i
B4: =_xlfn.CONCAT('Table of Contents'!B11,": ",'Table of Contents'!C11) -> APPENDIX 4 i: SUMMARY OF LONG TERM INSURANCE BUSINESS BALANCE SHEETS AS AT 31.03.2026
B5: Company | C5: ABSA LIFE ASSURANCE | D5: APA LIFE ASSURANCE COMPANY | E5: BRITAM LIFE ASSURANCE | F5: CANNON LIFE ASSURANCE (K) LIMITED | G5: CAPEX LIFE ASSURANCE COMPANY | H5: CIC LIFE ASSURANCE COMPANY | I5: CONTINENTAL REINSURANCE | J5: EAST AFRICA REINSURANCE | K5: EQUITY LIFE ASSURANCE
B6: Share Capital | C6: 699000 | D6: 1100000 | E6: 1200000 | F6: 416725.77 | G6: 400000 | H6: 800000 | I6: 0 | J6: 500000 | K6: 420000
B7: Share Premium_x000D_ | C7: 0 | D7: 0 | E7: 0 | F7: 491067.65 | G7: 0 | H7: 0 | I7: 0 | J7: 0 | K7: 180000
B8: Revaluation Reserves | C8: 0 | D8: 0 | E8: 0 | F8: 2500 | G8: 2072.909 | H8: 0 | I8: 0 | J8: 0 | K8: 0
B9: Statutory Reserves | C9: 1011470.8 | D9: 127630.99 | E9: 18590906 | F9: 0 | G9: 0 | H9: 2255766.2 | I9: 0 | J9: 0 | K9: 0
B10: Other Equity | C10: 1000000 | D10: 0 | E10: 0 | F10: 405066.13 | G10: 0 | H10: 911550.06 | I10: 0 | J10: 0 | K10: 0
B11: Retained Earnings | C11: -940992.74 | D11: 714860.81 | E11: 75000 | F11: -1281726.8 | G11: 309039.36 | H11: 123751.88 | I11: 0 | J11: 1401742.9 | K11: 3835946.4
B12: Other Reserves | C12: 0 | D12: 76549.767 | E12: 1.1920929e-10 | F12: 518154.63 | G12: 1120.164 | H12: 0 | I12: 0 | J12: 0 | K12: 2244635.9
B13: Total Equity_x000D_ | C13: 1769478.1 | D13: 2019041.6 | E13: 19865906 | F13: 551787.36 | G13: 712232.43 | H13: 4091068.1 | I13: 0 | J13: 1901742.9 | K13: 6680582.3
B14: Investment Contract Liabilites | C14: 0 | D14: 292125.61 | E14: 0 | F14: 0 | G14: 68155.135 | H14: 95079.348 | I14: 0 | J14: 0 | K14: 0
B15: Insurance Contract Liabilites | C15: 21599497 | D15: 31326467 | E15: 1.9110872e+08 | F15: 847020.05 | G15: 1409826.4 | H15: 41099195 | I15: 0 | J15: 847712.04 | K15: 26601226
B16: Reinsurance Contract Liabilites | C16: 0 | D16: 17405.565 | E16: 1665.75 | F16: 0 | G16: 26175.576 | H16: 0 | I16: 0 | J16: 80953.52 | K16: 0
B17: Long-Term Liabilites | C17: 0 | D17: 0 | E17: 0 | F17: 0 | G17: 0 | H17: 0 | I17: 0 | J17: 0 | K17: 0
... B45: Total Assets | C45: 24782186 | D45: 34457598 | E45: 2.2074457e+08 | F45: 1808467.2 | G45: 2322706.9 | H45: 47974057 | I45: 0 | J45: 3452233 | K45: 36540717
B46: Amounts in Thousand Shillings | J46: Continued next page

Sheet APPENDIX 4 ii
B3: Continued from previous page
B4: =_xlfn.CONCAT('Table of Contents'!B12,": ",'Table of Contents'!C12) -> APPENDIX 4 ii: SUMMARY OF LONG TERM INSURANCE BUSINESS BALANCE SHEETS AS AT 31.03.2026
B5: Company | C5: GA LIFE ASSURANCE COMPANY | D5: GEMINIA LIFE INSURANCE COMPANY | E5: ICEA LION LIFE ASSURANCE | F5: JUBILEE LIFE INSURANCE | G5: KENINDIA ASSURANCE COMPANY | H5: KENYA ORIENT LIFE ASSURANCE | I5: KENYA REINSURANCE CORPORATION | J5: LIBERTY LIFE ASSURANCE COMPANY | K5: MADISON INSURANCE COMPANY
B6: Share Capital | C6: 400000 | D6: 458093.68 | E6: 1125000 | F6: 500000 | G6: 900000 | H6: 313000 | I6: 500000 | J6: 742340 | K6: 450000
B7: Share Premium_x000D_ | C7: 0 | D7: 0 | E7: 1125000 | F7: 0 | G7: 1000000 | H7: 0 | I7: 0 | J7: 0 | K7: 0
B8: Revaluation Reserves | C8: 0 | D8: 0 | E8: 0 | F8: 0 | G8: 0 | H8: 0 | I8: 0 | J8: 384946.36 | K8: 19341
B9: Statutory Reserves | C9: 5472480.5 | D9: 388371.7 | E9: 18240363 | F9: 0 | G9: 2759237.2 | H9: 264952.49 | I9: 0 | J9: 2094358.5 | K9: -5333877
B10: Other Equity | C10: 0 | D10: 0 | E10: 1470000 | F10: 0 | G10: -514.885 | H10: 0 | I10: 0 | J10: 600000 | K10: 2050000
B11: Retained Earnings | C11: 338109.32 | D11: 277492.59 | E11: 3011861.5 | F11: 6716726.3 | G11: 2764516.8 | H11: 101354.33 | I11: 10808752 | J11: -304169.9 | K11: 62000
B12: Other Reserves | C12: 0 | D12: 0 | E12: 0 | F12: 5312333 | G12: 0 | H12: 0 | I12: 0 | J12: 0 | K12: 0
B13: Total Equity_x000D_ | C13: 6210589.8 | D13: 1123958 | E13: 24972224 | F13: 12529059 | G13: 7423239.2 | H13: 679306.82 | I13: 11308752 | J13: 3517475 | K13: -2752536
B14: Investment Contract Liabilites | C14: 55575689 | D14: 1532928.4 | E14: 0 | F14: 0 | G14: 0 | H14: 2179480.9 | I14: 0 | J14: 13131324 | K14: 0
B15: Insurance Contract Liabilites | C15: 42881.254 | D15: 1383986.9 | E15: 1.9630499e+08 | F15: 1.7637858e+08 | G15: 1.1139575e+08 | H15: 3214395.7 | I15: 2543031.4 | J15: 15234566 | K15: 23286039
B16: Reinsurance Contract Liabilites | C16: 0 | D16: 0 | E16: 0 | F16: 0 | G16: 35903.497 | H16: 0 | I16: 0 | J16: 0 | K16: 0
B17: Long-Term Liabilites | C17: 0 | D17: 0 | E17: 0 | F17: 0 | G17: 0 | H17: 0 | I17: 0 | J17: 0 | K17: 0
... B45: Total Assets | C45: 67259389 | D45: 4151135.3 | E45: 2.2834978e+08 | F45: 1.9351947e+08 | G45: 1.2129353e+08 | H45: 6284243.8 | I45: 13851783 | J45: 33816797 | K45: 21028844
B46: Amounts in Thousand Shillings | J46: Continued next page

Sheet APPENDIX 4 iii
B3: Continued from previous page
B4: =_xlfn.CONCAT('Table of Contents'!B13,": ",'Table of Contents'!C13) -> APPENDIX 4 iii: SUMMARY OF LONG TERM INSURANCE BUSINESS BALANCE SHEETS AS AT 31.03.2026 | Q4: Industry
B5: Company | C5: OLD MUTUAL LIFE ASSURANCE KENYA | D5: PIONEER ASSURANCE COMPANY | E5: PRUDENTIAL LIFE ASSURANCE | F5: SANLAM LIFE ASSURANCE | G5: STAR DISCOVER LIFE INSURANCE | H5: THE KENYAN ALLIANCE INSURANCE | I5: THE MONARCH INSURANCE | J5: TOTAL | N5: Insurers | O5: Reinsurers | Q5: Insurers | R5: Reinsurers | S5: Total
B6: Share Capital | C6: 2946667.4 | D6: 600000 | E6: 425698.08 | F6: 843138.54 | G6: 400000 | H6: 0 | I6: 0 | J6: 16139663 | N6: =SUMIFS('APPENDIX 4 iii'!$B6:$L6,'APPENDIX 4 iii'!$B$5:$L$5,"*total*")-O6 -> 15139663 | O6: =SUMIFS('APPENDIX 4 i'!$B6:$K6,'APPENDIX 4 i'!$B$5:$K$5,"*reinsurance*")+ SUMIFS('APPENDIX 4 ii'!$B6:$K6,'APPENDIX 4 ii'!$B$5:$K$5,"*reinsurance*")+ SUMIFS('APPENDIX 4 iii'!$B6:$K6,'APPENDIX 4 iii'!$B$5:$K$5,"*reinsurance*") -> 1000000 | Q6: =N6+_xlfn.XLOOKUP($B6,'APPENDIX 5 iv'!$B:$B,'APPENDIX 5 iv'!P:P,0,0)+_xlfn.XLOOKUP($B6,'APPENDIX 6'!$B:$B,'APPENDIX 6'!I:I,0,0) -> 50105680 | R6: =O6+_xlfn.XLOOKUP($B6,'APPENDIX 5 iv'!$B:$B,'APPENDIX 5 iv'!Q:Q,0,0)+_xlfn.XLOOKUP($B6,'APPENDIX 6'!$B:$B,'APPENDIX 6'!J:J,0,0) -> 19101531 | S6: =SUM(Q6:R6) -> 69207211
B7: Share Premium_x000D_ | C7: 1160475.7 | D7: 0 | E7: 3768621.6 | F7: 30260 | G7: 0 | H7: 0 | I7: 0 | J7: 7755424.9 | N7: =SUMIFS('APPENDIX 4 iii'!$B7:$L7,'APPENDIX 4 iii'!$B$5:$L$5,"*total*")-O7 -> 7755424.9 | O7: =SUMIFS('APPENDIX 4 i'!$B7:$K7,'APPENDIX 4 i'!$B$5:$K$5,"*reinsurance*")+ SUMIFS('APPENDIX 4 ii'!$B7:$K7,'APPENDIX 4 ii'!$B$5:$K$5,"*reinsurance*")+ SUMIFS('APPENDIX 4 iii'!$B7:$K7,'APPENDIX 4 iii'!$B$5:$K$5,"*reinsurance*") -> 0 | Q7: =N7+_xlfn.XLOOKUP($B7,'APPENDIX 5 iv'!$B:$B,'APPENDIX 5 iv'!P:P,0,0)+_xlfn.XLOOKUP($B7,'APPENDIX 6'!$B:$B,'APPENDIX 6'!I:I,0,0) -> 12016882 | R7: =O7+_xlfn.XLOOKUP($B7,'APPENDIX 5 iv'!$B:$B,'APPENDIX 5 iv'!Q:Q,0,0)+_xlfn.XLOOKUP($B7,'APPENDIX 6'!$B:$B,'APPENDIX 6'!J:J,0,0) -> 10871.242 | S7: =SUM(Q7:R7) -> 12027754
B8: Revaluation Reserves | C8: 0 | D8: 0 | E8: 0 | F8: 0 | G8: 0 | H8: 0 | I8: 0 | J8: 408860.27 | N8: =SUMIFS('APPENDIX 4 iii'!$B8:$L8,'APPENDIX 4 iii'!$B$5:$L$5,"*total*")-O8 -> 408860.27 | O8: =SUMIFS('APPENDIX 4 i'!$B8:$K8,'APPENDIX 4 i'!$B$5:$K$5,"*reinsurance*")+ SUMIFS('APPENDIX 4 ii'!$B8:$K8,'APPENDIX 4 ii'!$B$5:$K$5,"*reinsurance*")+ SUMIFS('APPENDIX 4 iii'!$B8:$K8,'APPENDIX 4 iii'!$B$5:$K$5,"*reinsurance*") -> 0 | Q8: =N8+_xlfn.XLOOKUP($B8,'APPENDIX 5 iv'!$B:$B,'APPENDIX 5 iv'!P:P,0,0)+_xlfn.XLOOKUP($B8,'APPENDIX 6'!$B:$B,'APPENDIX 6'!I:I,0,0) -> 2960333.5 | R8: =O8+_xlfn.XLOOKUP($B8,'APPENDIX 5 iv'!$B:$B,'APPENDIX 5 iv'!Q:Q,0,0)+_xlfn.XLOOKUP($B8,'APPENDIX 6'!$B:$B,'APPENDIX 6'!J:J,0,0) -> 237108.49 | S8: =SUM(Q8:R8) -> 3197442
B9: Statutory Reserves | C9: -298557.7 | D9: 312202.03 | E9: 0 | F9: 3344067.6 | G9: 0 | H9: 0 | I9: 0 | J9: 49229372 | N9: =SUMIFS('APPENDIX 4 iii'!$B9:$L9,'APPENDIX 4 iii'!$B$5:$L$5,"*total*")-O9 -> 49229372 | O9: =SUMIFS('APPENDIX 4 i'!$B9:$K9,'APPENDIX 4 i'!$B$5:$K$5,"*reinsurance*")+ SUMIFS('APPENDIX 4 ii'!$B9:$K9,'APPENDIX 4 ii'!$B$5:$K$5,"*reinsurance*")+ SUMIFS('APPENDIX 4 iii'!$B9:$K9,'APPENDIX 4 iii'!$B$5:$K$5,"*reinsurance*") -> 0 | Q9: =N9+_xlfn.XLOOKUP($B9,'APPENDIX 5 iv'!$B:$B,'APPENDIX 5 iv'!P:P,0,0)+_xlfn.XLOOKUP($B9,'APPENDIX 6'!$B:$B,'APPENDIX 6'!I:I,0,0) -> 49229372 | R9: =O9+_xlfn.XLOOKUP($B9,'APPENDIX 5 iv'!$B:$B,'APPENDIX 5 iv'!Q:Q,0,0)+_xlfn.XLOOKUP($B9,'APPENDIX 6'!$B:$B,'APPENDIX 6'!J:J,0,0) -> 0 | S9: =SUM(Q9:R9) -> 49229372
B10: Other Equity | C10: 0 | D10: 0 | E10: 0 | F10: 0 | G10: 0 | H10: 0 | I10: 0 | J10: 6436101.3 | N10: =SUMIFS('APPENDIX 4 iii'!$B10:$L10,'APPENDIX 4 iii'!$B$5:$L$5,"*total*")-O10 -> 6436101.3 | O10: =SUMIFS('APPENDIX 4 i'!$B10:$K10,'APPENDIX 4 i'!$B$5:$K$5,"*reinsurance*")+ SUMIFS('APPENDIX 4 ii'!$B10:$K10,'APPENDIX 4 ii'!$B$5:$K$5,"*reinsurance*")+ SUMIFS('APPENDIX 4 iii'!$B10:$K10,'APPENDIX 4 iii'!$B$5:$K$5,"*reinsurance*") -> 0 | Q10: =N10+_xlfn.XLOOKUP($B10,'APPENDIX 5 iv'!$B:$B,'APPENDIX 5 iv'!P:P,0,0)+_xlfn.XLOOKUP($B10,'APPENDIX 6'!$B:$B,'APPENDIX 6'!I:I,0,0) -> 11981909 | R10: =O10+_xlfn.XLOOKUP($B10,'APPENDIX 5 iv'!$B:$B,'APPENDIX 5 iv'!Q:Q,0,0)+_xlfn.XLOOKUP($B10,'APPENDIX 6'!$B:$B,'APPENDIX 6'!J:J,0,0) -> 1314112.1 | S10: =SUM(Q10:R10) -> 13296021
B11: Retained Earnings | C11: 118180.75 | D11: 257545.71 | E11: -3516609.7 | F11: 235067.35 | G11: 363638.96 | H11: 0 | I11: 0 | J11: 25472088 | N11: =SUMIFS('APPENDIX 4 iii'!$B11:$L11,'APPENDIX 4 iii'!$B$5:$L$5,"*total*")-O11 -> 13261593 | O11: =SUMIFS('APPENDIX 4 i'!$B11:$K11,'APPENDIX 4 i'!$B$5:$K$5,"*reinsurance*")+ SUMIFS('APPENDIX 4 ii'!$B11:$K11,'APPENDIX 4 ii'!$B$5:$K$5,"*reinsurance*")+ SUMIFS('APPENDIX 4 iii'!$B11:$K11,'APPENDIX 4 iii'!$B$5:$K$5,"*reinsurance*") -> 12210495 | Q11: =N11+_xlfn.XLOOKUP($B11,'APPENDIX 5 iv'!$B:$B,'APPENDIX 5 iv'!P:P,0,0)+_xlfn.XLOOKUP($B11,'APPENDIX 6'!$B:$B,'APPENDIX 6'!I:I,0,0) -> 58827892 | R11: =O11+_xlfn.XLOOKUP($B11,'APPENDIX 5 iv'!$B:$B,'APPENDIX 5 iv'!Q:Q,0,0)+_xlfn.XLOOKUP($B11,'APPENDIX 6'!$B:$B,'APPENDIX 6'!J:J,0,0) -> 49218054 | S11: =SUM(Q11:R11) -> 1.0804595e+08
B12: Other Reserves | C12: 27533.634 | D12: 0 | E12: 0 | F12: 0 | G12: 0 | H12: 0 | I12: 0 | J12: 8180327.1 | N12: =SUMIFS('APPENDIX 4 iii'!$B12:$L12,'APPENDIX 4 iii'!$B$5:$L$5,"*total*")-O12 -> 8180327.1 | O12: =SUMIFS('APPENDIX 4 i'!$B12:$K12,'APPENDIX 4 i'!$B$5:$K$5,"*reinsurance*")+ SUMIFS('APPENDIX 4 ii'!$B12:$K12,'APPENDIX 4 ii'!$B$5:$K$5,"*reinsurance*")+ SUMIFS('APPENDIX 4 iii'!$B12:$K12,'APPENDIX 4 iii'!$B$5:$K$5,"*reinsurance*") -> 0 | Q12: =N12+_xlfn.XLOOKUP($B12,'APPENDIX 5 iv'!$B:$B,'APPENDIX 5 iv'!P:P,0,0)+_xlfn.XLOOKUP($B12,'APPENDIX 6'!$B:$B,'APPENDIX 6'!I:I,0,0) -> 10749663 | R12: =O12+_xlfn.XLOOKUP($B12,'APPENDIX 5 iv'!$B:$B,'APPENDIX 5 iv'!Q:Q,0,0)+_xlfn.XLOOKUP($B12,'APPENDIX 6'!$B:$B,'APPENDIX 6'!J:J,0,0) -> 1593975.7 | S12: =SUM(Q12:R12) -> 12343639
B13: Total Equity_x000D_ | C13: 3954299.7 | D13: 1169747.7 | E13: 677709.98 | F13: 4452533.5 | G13: 763638.96 | H13: 0 | I13: 0 | J13: 1.1362184e+08 | N13: =SUMIFS('APPENDIX 4 iii'!$B13:$L13,'APPENDIX 4 iii'!$B$5:$L$5,"*total*")-O13 -> 1.0041134e+08 | O13: =SUMIFS('APPENDIX 4 i'!$B13:$K13,'APPENDIX 4 i'!$B$5:$K$5,"*reinsurance*")+ SUMIFS('APPENDIX 4 ii'!$B13:$K13,'APPENDIX 4 ii'!$B$5:$K$5,"*reinsurance*")+ SUMIFS('APPENDIX 4 iii'!$B13:$K13,'APPENDIX 4 iii'!$B$5:$K$5,"*reinsurance*") -> 13210495 | Q13: =N13+_xlfn.XLOOKUP($B13,'APPENDIX 5 iv'!$B:$B,'APPENDIX 5 iv'!P:P,0,0)+_xlfn.XLOOKUP($B13,'APPENDIX 6'!$B:$B,'APPENDIX 6'!I:I,0,0) -> 1.9587173e+08 | R13: =O13+_xlfn.XLOOKUP($B13,'APPENDIX 5 iv'!$B:$B,'APPENDIX 5 iv'!Q:Q,0,0)+_xlfn.XLOOKUP($B13,'APPENDIX 6'!$B:$B,'APPENDIX 6'!J:J,0,0) -> 71475653 | S13: =SUM(Q13:R13) -> 2.6734739e+08
B14: Investment Contract Liabilites | C14: 674175.28 | D14: 0 | E14: 0 | F14: 0 | G14: 0 | H14: 0 | I14: 0 | J14: 73548957 | N14: =SUMIFS('APPENDIX 4 iii'!$B14:$L14,'APPENDIX 4 iii'!$B$5:$L$5,"*total*")-O14 -> 73548957 | O14: =SUMIFS('APPENDIX 4 i'!$B14:$K14,'APPENDIX 4 i'!$B$5:$K$5,"*reinsurance*")+ SUMIFS('APPENDIX 4 ii'!$B14:$K14,'APPENDIX 4 ii'!$B$5:$K$5,"*reinsurance*")+ SUMIFS('APPENDIX 4 iii'!$B14:$K14,'APPENDIX 4 iii'!$B$5:$K$5,"*reinsurance*") -> 0 | Q14: =N14+_xlfn.XLOOKUP($B14,'APPENDIX 5 iv'!$B:$B,'APPENDIX 5 iv'!P:P,0,0)+_xlfn.XLOOKUP($B14,'APPENDIX 6'!$B:$B,'APPENDIX 6'!I:I,0,0) -> 73548957 | R14: =O14+_xlfn.XLOOKUP($B14,'APPENDIX 5 iv'!$B:$B,'APPENDIX 5 iv'!Q:Q,0,0)+_xlfn.XLOOKUP($B14,'APPENDIX 6'!$B:$B,'APPENDIX 6'!J:J,0,0) -> 0 | S14: =SUM(Q14:R14) -> 73548957
B15: Insurance Contract Liabilites | C15: 25409747 | D15: 20860906 | E15: 6669080 | F15: 33112743 | G15: 122394.48 | H15: 0 | I15: 0 | J15: 9.3079876e+08 | N15: =SUMIFS('APPENDIX 4 iii'!$B15:$L15,'APPENDIX 4 iii'!$B$5:$L$5,"*total*")-O15 -> 9.2740801e+08 | O15: =SUMIFS('APPENDIX 4 i'!$B15:$K15,'APPENDIX 4 i'!$B$5:$K$5,"*reinsurance*")+ SUMIFS('APPENDIX 4 ii'!$B15:$K15,'APPENDIX 4 ii'!$B$5:$K$5,"*reinsurance*")+ SUMIFS('APPENDIX 4 iii'!$B15:$K15,'APPENDIX 4 iii'!$B$5:$K$5,"*reinsurance*") -> 3390743.4 | Q15: =N15+_xlfn.XLOOKUP($B15,'APPENDIX 5 iv'!$B:$B,'APPENDIX 5 iv'!P:P,0,0)+_xlfn.XLOOKUP($B15,'APPENDIX 6'!$B:$B,'APPENDIX 6'!I:I,0,0) -> 1.144899e+09 | R15: =O15+_xlfn.XLOOKUP($B15,'APPENDIX 5 iv'!$B:$B,'APPENDIX 5 iv'!Q:Q,0,0)+_xlfn.XLOOKUP($B15,'APPENDIX 6'!$B:$B,'APPENDIX 6'!J:J,0,0) -> 35965653 | S15: =SUM(Q15:R15) -> 1.1808647e+09
B16: Reinsurance Contract Liabilites | C16: 0 | D16: 0 | E16: 0 | F16: 0 | G16: 0 | H16: 0 | I16: 0 | J16: 162103.91 | N16: =SUMIFS('APPENDIX 4 iii'!$B16:$L16,'APPENDIX 4 iii'!$B$5:$L$5,"*total*")-O16 -> 81150.389 | O16: =SUMIFS('APPENDIX 4 i'!$B16:$K16,'APPENDIX 4 i'!$B$5:$K$5,"*reinsurance*")+ SUMIFS('APPENDIX 4 ii'!$B16:$K16,'APPENDIX 4 ii'!$B$5:$K$5,"*reinsurance*")+ SUMIFS('APPENDIX 4 iii'!$B16:$K16,'APPENDIX 4 iii'!$B$5:$K$5,"*reinsurance*") -> 80953.52 | Q16: =N16+_xlfn.XLOOKUP($B16,'APPENDIX 5 iv'!$B:$B,'APPENDIX 5 iv'!P:P,0,0)+_xlfn.XLOOKUP($B16,'APPENDIX 6'!$B:$B,'APPENDIX 6'!I:I,0,0) -> 4415482.7 | R16: =O16+_xlfn.XLOOKUP($B16,'APPENDIX 5 iv'!$B:$B,'APPENDIX 5 iv'!Q:Q,0,0)+_xlfn.XLOOKUP($B16,'APPENDIX 6'!$B:$B,'APPENDIX 6'!J:J,0,0) -> 1473334.1 | S16: =SUM(Q16:R16) -> 5888816.7
B17: Long-Term Liabilites | C17: 0 | D17: 0 | E17: 0 | F17: 0 | G17: 0 | H17: 0 | I17: 0 | J17: 0 | N17: =SUMIFS('APPENDIX 4 iii'!$B17:$L17,'APPENDIX 4 iii'!$B$5:$L$5,"*total*")-O17 -> 0 | O17: =SUMIFS('APPENDIX 4 i'!$B17:$K17,'APPENDIX 4 i'!$B$5:$K$5,"*reinsurance*")+ SUMIFS('APPENDIX 4 ii'!$B17:$K17,'APPENDIX 4 ii'!$B$5:$K$5,"*reinsurance*")+ SUMIFS('APPENDIX 4 iii'!$B17:$K17,'APPENDIX 4 iii'!$B$5:$K$5,"*reinsurance*") -> 0 | Q17: =N17+_xlfn.XLOOKUP($B17,'APPENDIX 5 iv'!$B:$B,'APPENDIX 5 iv'!P:P,0,0)+_xlfn.XLOOKUP($B17,'APPENDIX 6'!$B:$B,'APPENDIX 6'!I:I,0,0) -> 438424.9 | R17: =O17+_xlfn.XLOOKUP($B17,'APPENDIX 5 iv'!$B:$B,'APPENDIX 5 iv'!Q:Q,0,0)+_xlfn.XLOOKUP($B17,'APPENDIX 6'!$B:$B,'APPENDIX 6'!J:J,0,0) -> 0 | S17: =SUM(Q17:R17) -> 438424.9
... B45: Total Assets | C45: 31784005 | D45: 22598964 | E45: 7823446.6 | F45: 39969835 | G45: 894716.47 | H45: 0 | I45: 0 | J45: 1.1647085e+09 | N45: =SUMIFS('APPENDIX 4 iii'!$B45:$L45,'APPENDIX 4 iii'!$B$5:$L$5,"*total*")-O45 -> 1.1474045e+09 | O45: =SUMIFS('APPENDIX 4 i'!$B45:$K45,'APPENDIX 4 i'!$B$5:$K$5,"*reinsurance*")+ SUMIFS('APPENDIX 4 ii'!$B45:$K45,'APPENDIX 4 ii'!$B$5:$K$5,"*reinsurance*")+ SUMIFS('APPENDIX 4 iii'!$B45:$K45,'APPENDIX 4 iii'!$B$5:$K$5,"*reinsurance*") -> 17304016 | Q45: =N45+_xlfn.XLOOKUP($B45,'APPENDIX 5 iv'!$B:$B,'APPENDIX 5 iv'!P:P,0,0)+_xlfn.XLOOKUP($B45,'APPENDIX 6'!$B:$B,'APPENDIX 6'!I:I,0,0) -> 1.4926807e+09 | R45: =O45+_xlfn.XLOOKUP($B45,'APPENDIX 5 iv'!$B:$B,'APPENDIX 5 iv'!Q:Q,0,0)+_xlfn.XLOOKUP($B45,'APPENDIX 6'!$B:$B,'APPENDIX 6'!J:J,0,0) -> 1.1500946e+08 | S45: =SUM(Q45:R45) -> 1.6076901e+09
B46: Amounts in Thousand Shillings
N49: =N45-N42-N41-N43-N44-N40-N25-N22-N23 -> 1.0955451e+09 | O49: =O45-O42-O41-O43-O44-O40-O25-O22-O23 -> 15563642 | Q49: =Q45-Q42-Q41-Q43-Q44-Q40-Q25-Q22-Q23 -> 1.2997507e+09 | R49: =R45-R42-R41-R43-R44-R40-R25-R22-R23 -> 87961845 | S49: =S45-S42-S41-S43-S44-S40-S25-S22-S23 -> 1.3877126e+09
N50: Life | P50: General | R50: Micro | S50: Industry
N51: Insurers | O51: Reinsurers | P51: Insurers | Q51: Reinsurers | R51: Microinsurers | S51: Insurers | T51: Reinsurers | U51: Total
M52: Equity | N52: =N13 -> 1.0041134e+08 | O52: =O13 -> 13210495 | P52: ='APPENDIX 5 iv'!P12 -> 94965539 | Q52: ='APPENDIX 5 iv'!Q12 -> 58265158 | R52: ='APPENDIX 6'!I12 -> 494851.35 | S52: =Q13 -> 1.9587173e+08 | T52: =R13 -> 71475653 | U52: =S13 -> 2.6734739e+08 | V52: =IF(AND(SUM(N52:R52)=SUM(S52:T52),SUM(S52:T52)=U52),"Ok","Check") -> Ok
M53: Assets | N53: =N45 -> 1.1474045e+09 | O53: =O45 -> 17304016 | P53: ='APPENDIX 5 iv'!P43 -> 3.436757e+08 | Q53: ='APPENDIX 5 iv'!Q43 -> 97705442 | R53: ='APPENDIX 6'!I43 -> 1600509.8 | S53: =Q45 -> 1.4926807e+09 | T53: =R45 -> 1.1500946e+08 | U53: =S45 -> 1.6076901e+09 | V53: =IF(AND(SUM(N53:R53)=SUM(S53:T53),SUM(S53:T53)=U53),"Ok","Check") -> Ok
M54: Investments | N54: =SUM(N24,N26:N39) -> 1.0955451e+09 | O54: =SUM(O24,O26:O39) -> 15563642 | P54: =SUM('APPENDIX 5 iv'!P22,'APPENDIX 5 iv'!P24:P37) -> 2.0591962e+08 | Q54: =SUM('APPENDIX 5 iv'!Q22,'APPENDIX 5 iv'!Q24:Q37) -> 69650543 | R54: =SUM('APPENDIX 6'!I22,'APPENDIX 6'!I24:I37) -> 1033640.7 | S54: =SUM(Q24,Q26:Q39) -> 1.3024984e+09 | T54: =SUM(R24,R26:R39) -> 85214185 | U54: =SUM(S24,S26:S39) -> 1.3877126e+09 | V54: =IF(AND(SUM(N54:R54)=SUM(S54:T54),SUM(S54:T54)=U54),"Ok","Check") -> Ok

Sheet APPENDIX 5 i
B4: =_xlfn.CONCAT('Table of Contents'!B14,": ",'Table of Contents'!C14) -> APPENDIX 5 i: SUMMARY OF GENERAL INSURANCE BUSINESS BALANCE SHEETS AS AT 31.03.2026
B5: COMPANY | C5: AAR INSURANCE KENYA | D5: AFRICAN MERCHANT ASSURANCE | E5: APA INSURANCE LIMITED | F5: BRITAM GENERAL INSURANCE | G5: BUPA GLOBAL INSURANCE | H5: CANNON GENERAL INSURANCE | I5: CIC GENERAL INSURANCE COMPANY | J5: CONTINENTAL REINSURANCE | K5: DEFINITE ASSURANCE COMPANY | L5: DIRECTLINE ASSURANCE COMPANY
B6: Share Capital | C6: 1017626.6 | D6: 987386 | E6: 1250000 | F6: 2668000 | G6: 1086683.1 | H6: 453960.46 | I6: 1700000 | J6: 1500000 | K6: 0 | L6: 300000
B7: Share Premium | C7: 460523 | D7: 0 | E7: 0 | F7: 0 | G7: 0 | H7: 583039.52 | I7: 0 | J7: 0 | K7: 0 | L7: 0
B8: Revaluation Reserve | C8: 0 | D8: 30240.538 | E8: 0 | F8: 0 | G8: 0 | H8: 74345 | I8: 0 | J8: 0 | K8: 0 | L8: 0
B9: Other Equity | C9: 0 | D9: 0 | E9: 1165168.2 | F9: 0 | G9: 0 | H9: -86582 | I9: 349723.34 | J9: 0 | K9: 0 | L9: 0
B10: Retained Earnings | C10: 1374944.7 | D10: 270683.15 | E10: 5211241 | F10: 5795611.3 | G10: 306.865 | H10: -303595.12 | I10: 4395349.1 | J10: 2237763.7 | K10: 0 | L10: -2787343.5
B11: Other Reserves | C11: 0 | D11: 0 | E11: 0 | F11: 0 | G11: 0 | H11: 0 | I11: 0 | J11: -87345.33 | K11: 0 | L11: 0
B12: Total Equity_x000D_ | C12: 2853094.3 | D12: 1288309.7 | E12: 7626409.2 | F12: 8463611.3 | G12: 1086990 | H12: 721167.86 | I12: 6445072.5 | J12: 3650418.3 | K12: 0 | L12: -2487343.5
B13: Insurance Contract Liabilites | C13: 6301226.5 | D13: 3469223.4 | E13: 17111456 | F13: 15867776 | G13: 4482583 | H13: 2714863.7 | I13: 16195843 | J13: 6444699.4 | K13: 0 | L13: 9172659
B14: Reinsurance Contract Liabilites | C14: 0 | D14: 18.841367 | E14: 0 | F14: 30824.157 | G14: 0 | H14: 0 | I14: 0 | J14: 0 | K14: 0 | L14: 0
B15: Long-Term Liabilites | C15: 0 | D15: 0 | E15: 0 | F15: 0 | G15: 0 | H15: 0 | I15: 0 | J15: 0 | K15: 0 | L15: 0
B16: Deferred tax liability | C16: 0 | D16: 0 | E16: 0 | F16: 0 | G16: 0 | H16: 122344.66 | I16: 0 | J16: 51587.241 | K16: 0 | L16: 0
B17: Short-Term Liabilites | C17: 355113.84 | D17: 229204.96 | E17: 1530094.7 | F17: 1006130.1 | G17: 19235.17 | H17: 517354.41 | I17: 704623.18 | J17: 202872.7 | K17: 0 | L17: 330235.69
... B43: Total Assets | C43: 10003161 | D43: 5044946.9 | E43: 26423610 | F43: 26076585 | G43: 5863041.2 | H43: 4091056.5 | I43: 23430840 | J43: 10566962 | K43: 0 | L43: 7110021.4
B44: Amounts in Thousand Shillings | K44: Continued next page

Sheet APPENDIX 5 ii
B3: Continued from previous page
B4: =_xlfn.CONCAT('Table of Contents'!B15,": ",'Table of Contents'!C15) -> APPENDIX 5 ii: SUMMARY OF GENERAL INSURANCE BUSINESS BALANCE SHEETS AS AT 31.03.2026
B5: COMPANY | C5: EAST AFRICA REINSURANCE | D5: EQUITY GENERAL INSURANCE LIMITED | E5: EQUITY HEALTH INSURANCE LIMITED | F5: FIDELITY SHIELD INSURANCE | G5: FIRST ASSURANCE COMPANY | H5: GA INSURANCE COMPANY | I5: GEMINIA INSURANCE COMPANY | J5: GHANA REINSURANCE COMPANY | K5: ICEA LION GENERAL INSURANCE | L5: INTRA-AFRICA ASSURANCE
B6: Share Capital | C6: 1000000 | D6: 600000 | E6: 600000 | F6: 600000 | G6: 810000 | H6: 1500000 | I6: 1006250 | J6: 1000000 | K6: 1000000 | L6: 800000
B7: Share Premium | C7: 0 | D7: 0 | E7: 0 | F7: 0 | G7: 512138.51 | H7: 0 | I7: 0 | J7: 10871.242 | K7: 0 | L7: 0
B8: Revaluation Reserve | C8: 199204.18 | D8: 0 | E8: 0 | F8: 100140.56 | G8: 339178 | H8: 911178.74 | I8: 68492.66 | J8: 0 | K8: 66982.18 | L8: 342209.34
B9: Other Equity | C9: 0 | D9: 0 | E9: 0 | F9: 0 | G9: 71118.815 | H9: -750000 | I9: 21065.59 | J9: 0 | K9: 600000 | L9: 25000
B10: Retained Earnings | C10: 5106113.5 | D10: 239118.57 | E10: 41657.304 | F10: 738893.11 | G10: 222027.58 | H10: 8154107.4 | I10: 281064.84 | J10: 1390983.3 | K10: 7440347.5 | L10: 249103.63
B11: Other Reserves | C11: 0 | D11: 0 | E11: 0 | F11: 0 | G11: -16454.886 | H11: 950137 | I11: 0 | J11: 0 | K11: 0 | L11: 0
B12: Total Equity_x000D_ | C12: 6305317.6 | D12: 839118.57 | E12: 641657.3 | F12: 1439033.7 | G12: 1938008 | H12: 10765423 | I12: 1376873.1 | J12: 2401854.5 | K12: 9107329.7 | L12: 1416313
B13: Insurance Contract Liabilites | C13: 3385215.3 | D13: 862861.12 | E13: 1063463.3 | F13: 5796497.2 | G13: 5853555.4 | H13: 18634608 | I13: 6168932 | J13: 3316502 | K13: 7942529.7 | L13: 3033919.4
B14: Reinsurance Contract Liabilites | C14: 161180.33 | D14: 0 | E14: 0 | F14: 0 | G14: 0 | H14: 3128598.5 | I14: 0 | J14: 0 | K14: 432249.85 | L14: 8725.0624
B15: Long-Term Liabilites | C15: 0 | D15: 200000 | E15: 200000 | F15: 0 | G15: 0 | H15: 0 | I15: 0 | J15: 0 | K15: 0 | L15: 0
B16: Deferred tax liability | C16: 0 | D16: 0 | E16: 0 | F16: 11133.526 | G16: 0 | H16: 121943.95 | I16: 0 | J16: 0 | K16: 532885.94 | L16: 0
B17: Short-Term Liabilites | C17: 916987.56 | D17: 400523.72 | E17: 179915.67 | F17: 203287.09 | G17: 451158.82 | H17: 495050.39 | I17: 104132.81 | J17: 8570.936 | K17: 957361.02 | L17: 65400.603
... B43: Total Assets | C43: 10865238 | D43: 2364573.7 | E43: 2090023.7 | F43: 7459785.3 | G43: 8472972.7 | H43: 33468273 | I43: 7709620 | J43: 5796263.7 | K43: 19311463 | L43: 4598354.2
B44: Amounts in Thousand Shillings | K44: Continued next page

Sheet APPENDIX 5 iii
B3: Continued from previous page
B4: =_xlfn.CONCAT('Table of Contents'!B16,": ",'Table of Contents'!C16) -> APPENDIX 5 iii: SUMMARY OF GENERAL INSURANCE BUSINESS BALANCE SHEETS AS AT 31.03.2026
B5: COMPANY | C5: JUBILEE HEALTH INSURANCE | D5: KENINDIA ASSURANCE COMPANY | E5: KENYA ORIENT INSURANCE | F5: KENYA REINSURANCE CORPORATION | G5: MADISON INSURANCE COMPANY | H5: MAYFAIR INSURANCE COMPANY | I5: MUA INSURANCE COMPANY | J5: NCBA INSURANCE COMPANY | K5: OCCIDENTAL INSURANCE COMPANY | L5: OLD MUTUAL GENERAL INSURANCE | M5: PACIS INSURANCE COMPANY
B6: Share Capital | C6: 2763720 | D6: 600000 | E6: 810721.06 | F6: 13498981 | G6: 605000 | H6: 1500000 | I6: 600000 | J6: 600000 | K6: 895831 | L6: 1000000 | M6: 688553.91
B7: Share Premium | C7: 0 | D7: 1198.295 | E7: 0 | F7: 0 | G7: 0 | H7: 0 | I7: 0 | J7: 0 | K7: 0 | L7: 0 | M7: 5712
B8: Revaluation Reserve | C8: 54390.06 | D8: 456853 | E8: 10029.498 | F8: 37904.31 | G8: 0 | H8: -152930.36 | I8: 0 | J8: 0 | K8: 0 | L8: 0 | M8: 0
B9: Other Equity | C9: 0 | D9: 592976.33 | E9: 1672217.3 | F9: 1314112.1 | G9: 0 | H9: 244574 | I9: 1220213 | J9: 170013.69 | K9: 100378.9 | L9: 0 | M9: 0
B10: Retained Earnings | C10: 2442585.9 | D10: 2795919.9 | E10: -3949216.7 | F10: 25965243 | G10: 657475.84 | H10: 3851254.1 | I10: -2197953 | J10: 1640591.4 | K10: -437720.33 | L10: 5590792.6 | M10: 318901.32
B11: Other Reserves | C11: 0 | D11: 0 | E11: 0 | F11: 1681321 | G11: 0 | H11: 557046.93 | I11: 17823.603 | J11: 0 | K11: 0 | L11: 0 | M11: 29527.889
B12: Total Equity_x000D_ | C12: 5260696 | D12: 4446947.5 | E12: -1456248.9 | F12: 42497561 | G12: 1262475.8 | H12: 5999944.6 | I12: -359916.43 | J12: 2410605.1 | K12: 558489.57 | L12: 6590792.6 | M12: 1042695.1
B13: Insurance Contract Liabilites | C13: 8308280.6 | D13: 7083695.2 | E13: 2992167.2 | F13: 14468912 | G13: 8062992.9 | H13: 12261133 | I13: 2633864.8 | J13: 3020020.1 | K13: 2238469.5 | L13: 15323176 | M13: 3560958.5
B14: Reinsurance Contract Liabilites | C14: 0 | D14: 0 | E14: 0 | F14: 1231200.2 | G14: 0 | H14: 0 | I14: 0 | J14: 153957.83 | K14: 0 | L14: 0 | M14: 0
B15: Long-Term Liabilites | C15: 0 | D15: 0 | E15: 0 | F15: 0 | G15: 0 | H15: 0 | I15: 0 | J15: 0 | K15: 0 | L15: 0 | M15: 0
B16: Deferred tax liability | C16: 0 | D16: 0 | E16: 0 | F16: 1702582.3 | G16: 0 | H16: 101209.47 | I16: 0 | J16: 0 | K16: 0 | L16: 23488.854 | M16: 48694.997
B17: Short-Term Liabilites | C17: -37660.347 | D17: 181828.88 | E17: 606554.07 | F17: 827628.45 | G17: 58250.546 | H17: 3339313.8 | I17: 508455.82 | J17: 414847.11 | K17: 654118.55 | L17: 2817678.2 | M17: 224035.79
... B43: Total Assets | C43: 14528021 | D43: 11739902 | E43: 2216217.8 | F43: 61090313 | G43: 9605090.1 | H43: 21903271 | I43: 2837945.6 | J43: 6193713 | K43: 3513659.8 | L43: 26166330 | M43: 4951318.4
B44: Amounts in Thousand Shillings | L44: Continued next page

Sheet APPENDIX  5 iv
B3: Continued from previous page
B4: =_xlfn.CONCAT('Table of Contents'!B17,": ",'Table of Contents'!C17) -> APPENDIX 5 iv: SUMMARY OF GENERAL INSURANCE BUSINESS BALANCE SHEETS AS AT 31.03.2026
B5: COMPANY | C5: PIONEER INSURANCE COMPANY | D5: SANLAM ALLIANZ GENERAL INSURANCE | E5: STAR DISCOVER INSURANCE | F5: TAKAFUL INSURANCE OF AFRICA | G5: TAUSI ASSURANCE COMPANY | H5: THE HERITAGE INSURANCE COMPANY | I5: THE KENYAN ALLIANCE INSURANCE | J5: THE MONARCH INSURANCE | K5: WAICA REINSURANCE KENYA LIMITED | L5: TOTAL | P5: Insurers | Q5: Reinsurers
B6: Share Capital | C6: 700000 | D6: 3907103 | E6: 675000 | F6: 1239704.3 | G6: 600000 | H6: 1000000 | I6: 0 | J6: 0 | K6: 1102550 | L6: 52667071 | P6: =SUMIFS('APPENDIX 5 iv'!$B6:$O6,'APPENDIX 5 iv'!$B$5:$O$5,"*total*")-Q6 -> 34565539 | Q6: =SUMIFS('APPENDIX 5 i'!$B6:$O6,'APPENDIX 5 i'!$B$5:$O$5,"*reinsurance*")+ SUMIFS('APPENDIX 5 ii'!$B6:$O6,'APPENDIX 5 ii'!$B$5:$O$5,"*reinsurance*")+ SUMIFS('APPENDIX 5 iii'!$B6:$O6,'APPENDIX 5 iii'!$B$5:$O$5,"*reinsurance*")+ SUMIFS('APPENDIX 5 iv'!$B6:$O6,'APPENDIX 5 iv'!$B$5:$O$5,"*reinsurance*") -> 18101531
B7: Share Premium_x000D_ | C7: 0 | D7: 2552745 | E7: 0 | F7: 146101 | G7: 0 | H7: 0 | I7: 0 | J7: 0 | K7: 0 | L7: 4272328.6 | P7: =SUMIFS('APPENDIX 5 iv'!$B7:$O7,'APPENDIX 5 iv'!$B$5:$O$5,"*total*")-Q7 -> 4261457.3 | Q7: =SUMIFS('APPENDIX 5 i'!$B7:$O7,'APPENDIX 5 i'!$B$5:$O$5,"*reinsurance*")+ SUMIFS('APPENDIX 5 ii'!$B7:$O7,'APPENDIX 5 ii'!$B$5:$O$5,"*reinsurance*")+ SUMIFS('APPENDIX 5 iii'!$B7:$O7,'APPENDIX 5 iii'!$B$5:$O$5,"*reinsurance*")+ SUMIFS('APPENDIX 5 iv'!$B7:$O7,'APPENDIX 5 iv'!$B$5:$O$5,"*reinsurance*") -> 10871.242
B8: Revaluation Reserves | C8: 0 | D8: 0 | E8: 16000 | F8: 25539.216 | G8: 208824.79 | H8: 0 | I8: 0 | J8: 0 | K8: 0 | L8: 2788581.7 | P8: =SUMIFS('APPENDIX 5 iv'!$B8:$O8,'APPENDIX 5 iv'!$B$5:$O$5,"*total*")-Q8 -> 2551473.2 | Q8: =SUMIFS('APPENDIX 5 i'!$B8:$O8,'APPENDIX 5 i'!$B$5:$O$5,"*reinsurance*")+ SUMIFS('APPENDIX 5 ii'!$B8:$O8,'APPENDIX 5 ii'!$B$5:$O$5,"*reinsurance*")+ SUMIFS('APPENDIX 5 iii'!$B8:$O8,'APPENDIX 5 iii'!$B$5:$O$5,"*reinsurance*")+ SUMIFS('APPENDIX 5 iv'!$B8:$O8,'APPENDIX 5 iv'!$B$5:$O$5,"*reinsurance*") -> 237108.49
B9: Other Equity | C9: 60200 | D9: 0 | E9: 0 | F9: 0 | G9: 89740.165 | H9: 0 | I9: 0 | J9: 0 | K9: 0 | L9: 6859919.4 | P9: =SUMIFS('APPENDIX 5 iv'!$B9:$O9,'APPENDIX 5 iv'!$B$5:$O$5,"*total*")-Q9 -> 5545807.3 | Q9: =SUMIFS('APPENDIX 5 i'!$B9:$O9,'APPENDIX 5 i'!$B$5:$O$5,"*reinsurance*")+ SUMIFS('APPENDIX 5 ii'!$B9:$O9,'APPENDIX 5 ii'!$B$5:$O$5,"*reinsurance*")+ SUMIFS('APPENDIX 5 iii'!$B9:$O9,'APPENDIX 5 iii'!$B$5:$O$5,"*reinsurance*")+ SUMIFS('APPENDIX 5 iv'!$B9:$O9,'APPENDIX 5 iv'!$B$5:$O$5,"*reinsurance*") -> 1314112.1
B10: Retained Earnings | C10: 602217.91 | D10: -3227847.6 | E10: -11579.211 | F10: -477725.49 | G10: 2081032.8 | H10: 4469678.2 | I10: 0 | J10: 0 | K10: 2307456.5 | L10: 82479484 | P10: =SUMIFS('APPENDIX 5 iv'!$B10:$O10,'APPENDIX 5 iv'!$B$5:$O$5,"*total*")-Q10 -> 45471925 | Q10: =SUMIFS('APPENDIX 5 i'!$B10:$O10,'APPENDIX 5 i'!$B$5:$O$5,"*reinsurance*")+ SUMIFS('APPENDIX 5 ii'!$B10:$O10,'APPENDIX 5 ii'!$B$5:$O$5,"*reinsurance*")+ SUMIFS('APPENDIX 5 iii'!$B10:$O10,'APPENDIX 5 iii'!$B$5:$O$5,"*reinsurance*")+ SUMIFS('APPENDIX 5 iv'!$B10:$O10,'APPENDIX 5 iv'!$B$5:$O$5,"*reinsurance*") -> 37007559
B11: Other Reserves | C11: 1031184.4 | D11: 71.376174 | E11: 0 | F11: 0 | G11: 0 | H11: 0 | I11: 0 | J11: 0 | K11: 0 | L11: 4163312 | P11: =SUMIFS('APPENDIX 5 iv'!$B11:$O11,'APPENDIX 5 iv'!$B$5:$O$5,"*total*")-Q11 -> 2569336.4 | Q11: =SUMIFS('APPENDIX 5 i'!$B11:$O11,'APPENDIX 5 i'!$B$5:$O$5,"*reinsurance*")+ SUMIFS('APPENDIX 5 ii'!$B11:$O11,'APPENDIX 5 ii'!$B$5:$O$5,"*reinsurance*")+ SUMIFS('APPENDIX 5 iii'!$B11:$O11,'APPENDIX 5 iii'!$B$5:$O$5,"*reinsurance*")+ SUMIFS('APPENDIX 5 iv'!$B11:$O11,'APPENDIX 5 iv'!$B$5:$O$5,"*reinsurance*") -> 1593975.7
B12: Total Equity_x000D_ | C12: 2393602.3 | D12: 3232071.8 | E12: 679420.79 | F12: 933618.99 | G12: 2979597.7 | H12: 5469678.2 | I12: 0 | J12: 0 | K12: 3410006.5 | L12: 1.532307e+08 | P12: =SUMIFS('APPENDIX 5 iv'!$B12:$O12,'APPENDIX 5 iv'!$B$5:$O$5,"*total*")-Q12 -> 94965539 | Q12: =SUMIFS('APPENDIX 5 i'!$B12:$O12,'APPENDIX 5 i'!$B$5:$O$5,"*reinsurance*")+ SUMIFS('APPENDIX 5 ii'!$B12:$O12,'APPENDIX 5 ii'!$B$5:$O$5,"*reinsurance*")+ SUMIFS('APPENDIX 5 iii'!$B12:$O12,'APPENDIX 5 iii'!$B$5:$O$5,"*reinsurance*")+ SUMIFS('APPENDIX 5 iv'!$B12:$O12,'APPENDIX 5 iv'!$B$5:$O$5,"*reinsurance*") -> 58265158
B13: Insurance Contract Liabilites | C13: 2382681.8 | D13: 10832690 | E13: 1332180.6 | F13: 1383080.9 | G13: 2498156.5 | H13: 8083284.6 | I13: 0 | J13: 0 | K13: 4959580.9 | L13: 2.4924374e+08 | P13: =SUMIFS('APPENDIX 5 iv'!$B13:$O13,'APPENDIX 5 iv'!$B$5:$O$5,"*total*")-Q13 -> 2.1666883e+08 | Q13: =SUMIFS('APPENDIX 5 i'!$B13:$O13,'APPENDIX 5 i'!$B$5:$O$5,"*reinsurance*")+ SUMIFS('APPENDIX 5 ii'!$B13:$O13,'APPENDIX 5 ii'!$B$5:$O$5,"*reinsurance*")+ SUMIFS('APPENDIX 5 iii'!$B13:$O13,'APPENDIX 5 iii'!$B$5:$O$5,"*reinsurance*")+ SUMIFS('APPENDIX 5 iv'!$B13:$O13,'APPENDIX 5 iv'!$B$5:$O$5,"*reinsurance*") -> 32574910
B14: Reinsurance Contract Liabilites | C14: 0 | D14: 547078.41 | E14: 0 | F14: 27691.879 | G14: 0 | H14: 0 | I14: 0 | J14: 0 | K14: 0 | L14: 5721525 | P14: =SUMIFS('APPENDIX 5 iv'!$B14:$O14,'APPENDIX 5 iv'!$B$5:$O$5,"*total*")-Q14 -> 4329144.5 | Q14: =SUMIFS('APPENDIX 5 i'!$B14:$O14,'APPENDIX 5 i'!$B$5:$O$5,"*reinsurance*")+ SUMIFS('APPENDIX 5 ii'!$B14:$O14,'APPENDIX 5 ii'!$B$5:$O$5,"*reinsurance*")+ SUMIFS('APPENDIX 5 iii'!$B14:$O14,'APPENDIX 5 iii'!$B$5:$O$5,"*reinsurance*")+ SUMIFS('APPENDIX 5 iv'!$B14:$O14,'APPENDIX 5 iv'!$B$5:$O$5,"*reinsurance*") -> 1392380.5
B15: Long-Term Liabilites | C15: 0 | D15: 0 | E15: 34950.782 | F15: 0 | G15: 0 | H15: 0 | I15: 0 | J15: 0 | K15: 0 | L15: 434950.78 | P15: =SUMIFS('APPENDIX 5 iv'!$B15:$O15,'APPENDIX 5 iv'!$B$5:$O$5,"*total*")-Q15 -> 434950.78 | Q15: =SUMIFS('APPENDIX 5 i'!$B15:$O15,'APPENDIX 5 i'!$B$5:$O$5,"*reinsurance*")+ SUMIFS('APPENDIX 5 ii'!$B15:$O15,'APPENDIX 5 ii'!$B$5:$O$5,"*reinsurance*")+ SUMIFS('APPENDIX 5 iii'!$B15:$O15,'APPENDIX 5 iii'!$B$5:$O$5,"*reinsurance*")+ SUMIFS('APPENDIX 5 iv'!$B15:$O15,'APPENDIX 5 iv'!$B$5:$O$5,"*reinsurance*") -> 0
B16: Deferred tax liability | C16: 0 | D16: 0 | E16: 756.59033 | F16: 16921.2 | G16: 93228.071 | H16: 38586.533 | I16: 0 | J16: 0 | K16: 0 | L16: 2865363.3 | P16: =SUMIFS('APPENDIX 5 iv'!$B16:$O16,'APPENDIX 5 iv'!$B$5:$O$5,"*total*")-Q16 -> 1111193.8 | Q16: =SUMIFS('APPENDIX 5 i'!$B16:$O16,'APPENDIX 5 i'!$B$5:$O$5,"*reinsurance*")+ SUMIFS('APPENDIX 5 ii'!$B16:$O16,'APPENDIX 5 ii'!$B$5:$O$5,"*reinsurance*")+ SUMIFS('APPENDIX 5 iii'!$B16:$O16,'APPENDIX 5 iii'!$B$5:$O$5,"*reinsurance*")+ SUMIFS('APPENDIX 5 iv'!$B16:$O16,'APPENDIX 5 iv'!$B$5:$O$5,"*reinsurance*") -> 1754169.5
B17: Short-Term Liabilites | C17: 641451.46 | D17: 1170188.7 | E17: 104998.56 | F17: 24178.283 | G17: 108806.34 | H17: 705453.83 | I17: 0 | J17: 0 | K17: 998936.41 | L17: 22026318 | P17: =SUMIFS('APPENDIX 5 iv'!$B17:$O17,'APPENDIX 5 iv'!$B$5:$O$5,"*total*")-Q17 -> 19071322 | Q17: =SUMIFS('APPENDIX 5 i'!$B17:$O17,'APPENDIX 5 i'!$B$5:$O$5,"*reinsurance*")+ SUMIFS('APPENDIX 5 ii'!$B17:$O17,'APPENDIX 5 ii'!$B$5:$O$5,"*reinsurance*")+ SUMIFS('APPENDIX 5 iii'!$B17:$O17,'APPENDIX 5 iii'!$B$5:$O$5,"*reinsurance*")+ SUMIFS('APPENDIX 5 iv'!$B17:$O17,'APPENDIX 5 iv'!$B$5:$O$5,"*reinsurance*") -> 2954996.1
... B23: Fixed Assets | C23: 26786.43 | D23: 61303.437 | E23: 11371.666 | F23: 23565.157 | G23: 33340.841 | H23: 85337.985 | I23: 0 | J23: 0 | K23: 26786.54 | L23: 1868006.5 | P23: =SUMIFS('APPENDIX 5 iv'!$B23:$O23,'APPENDIX 5 iv'!$B$5:$O$5,"*total*")-Q23 -> 1734359.1 | Q23: =SUMIFS('APPENDIX 5 i'!$B23:$O23,'APPENDIX 5 i'!$B$5:$O$5,"*reinsurance*")+ SUMIFS('APPENDIX 5 ii'!$B23:$O23,'APPENDIX 5 ii'!$B$5:$O$5,"*reinsurance*")+ SUMIFS('APPENDIX 5 iii'!$B23:$O23,'APPENDIX 5 iii'!$B$5:$O$5,"*reinsurance*")+ SUMIFS('APPENDIX 5 iv'!$B23:$O23,'APPENDIX 5 iv'!$B$5:$O$5,"*reinsurance*") -> 133647.36
B24: Government Securites | C24: 1330242.6 | D24: 7895603.3 | E24: 875928.69 | F24: 20606 | G24: 2791156.8 | H24: 7749375.4 | I24: 0 | J24: 0 | K24: 1606148.3 | L24: 1.4994521e+08 | P24: =SUMIFS('APPENDIX 5 iv'!$B24:$O24,'APPENDIX 5 iv'!$B$5:$O$5,"*total*")-Q24 -> 1.2433392e+08 | Q24: =SUMIFS('APPENDIX 5 i'!$B25:$O25,'APPENDIX 5 i'!$B$5:$O$5,"*reinsurance*")+ SUMIFS('APPENDIX 5 ii'!$B24:$O24,'APPENDIX 5 ii'!$B$5:$O$5,"*reinsurance*")+ SUMIFS('APPENDIX 5 iii'!$B24:$O24,'APPENDIX 5 iii'!$B$5:$O$5,"*reinsurance*")+ SUMIFS('APPENDIX 5 iv'!$B24:$O24,'APPENDIX 5 iv'!$B$5:$O$5,"*reinsurance*") -> 25611288
